Workbook

Sheet CurrentPor-Equ Factor Movements
C1: LH = 10 | G1: LH = 20 | H1: LH = 40 | I1: LH = 60 | J1: LH = 20 | K1: Standard deviation of factors
A2: DATE | C2: 1Y_Treasury | D2: 2Y_Treasury | E2: MSFT price | F2: Intel price | G2: Credit spread: sovereign (investment grade, or IG) | H2: Credit spread: sovereign (high yield, or HY) | I2: Credit Spread: Corporate(HY) | J2: Carbon Credits | K2: 1Y_Treasury | L2: 2Y_Treasury | M2: MSFT price | N2: Intel price | O2: Credit spread: sovereign (investment grade, or IG) | P2: Credit spread: sovereign (high yield, or HY) | Q2: Credit Spread: Corporate(HY) | R2: Carbon Credits
A3: 45474 | B3: 45474 | C3: 4.2673967 | D3: 4.5673967 | E3: 521.43896 | F3: 36.962945 | G3: 0.51 | H3: 0.58622522 | I3: 0.69637381 | J3: 21.480999 | K3: =_xlfn.STDEV.P(C3:C263) -> 2.6645353e-15 | L3: =_xlfn.STDEV.P(D3:D263) -> 6.2172489e-15 | M3: =_xlfn.STDEV.P(E3:E263) -> 2.9558578e-12 | N3: =_xlfn.STDEV.P(F3:F263) -> 0 | O3: =_xlfn.STDEV.P(G3:G263) -> 0.060694822 | P3: =_xlfn.STDEV.P(H3:H263) -> 0.052996577 | Q3: =_xlfn.STDEV.P(I3:I263) -> 0.0059420423 | R3: =_xlfn.STDEV.P(J3:J263) -> 6.750156e-14
A4: 45475 | B4: 45475 | C4: 4.2673967 | D4: 4.5673967 | E4: 521.43896 | F4: 36.962945 | G4: 0.51 | H4: 0.66683919 | I4: 0.70908799 | J4: 21.480999 | K4: Standard deviation/Average%
A5: 45476 | B5: 45476 | C5: 4.2673967 | D5: 4.5673967 | E5: 521.43896 | F5: 36.962945 | G5: 0.51 | H5: 0.5738683 | I5: 0.70174466 | J5: 21.480999 | K5: =_xlfn.STDEV.P(C3:C263)/AVERAGE(C3:C263) -> 6.2439362e-16 | L5: =_xlfn.STDEV.P(D3:D263)/AVERAGE(D3:D263) -> 1.3612238e-15 | M5: =_xlfn.STDEV.P(E3:E263)/AVERAGE(E3:E263) -> 5.6686555e-15 | N5: =_xlfn.STDEV.P(F3:F263)/AVERAGE(F3:F263) -> 0 | O5: =_xlfn.STDEV.P(G3:G263)/AVERAGE(G3:G263) -> 0.15633269 | P5: =_xlfn.STDEV.P(H3:H263)/AVERAGE(H3:H263) -> 0.088635041 | Q5: =_xlfn.STDEV.P(I3:I263)/AVERAGE(I3:I263) -> 0.0084803547 | R5: =_xlfn.STDEV.P(J3:J263)/AVERAGE(J3:J263) -> 3.1423846e-15
A6: 45477 | B6: 45477 | C6: 4.2673967 | D6: 4.5673967 | E6: 521.43896 | F6: 36.962945 | G6: 0.51 | H6: 0.55415584 | I6: 0.68446686 | J6: 21.480999
A7: 45478 | B7: 45478 | C7: 4.2673967 | D7: 4.5673967 | E7: 521.43896 | F7: 36.962945 | G7: 0.5 | H7: 0.70278175 | I7: 0.70703017 | J7: 21.480999
A8: 45481 | B8: 45481 | C8: 4.2673967 | D8: 4.5673967 | E8: 521.43896 | F8: 36.962945 | G8: 0.52 | H8: 0.69285184 | I8: 0.70188085 | J8: 21.480999
A9: 45482 | B9: 45482 | C9: 4.2673967 | D9: 4.5673967 | E9: 521.43896 | F9: 36.962945 | G9: 0.52 | H9: 0.62109307 | I9: 0.69910659 | J9: 21.480999
A10: 45483 | B10: 45483 | C10: 4.2673967 | D10: 4.5673967 | E10: 521.43896 | F10: 36.962945 | G10: 0.51 | H10: 0.62999665 | I10: 0.70233 | J10: 21.480999
A11: 45484 | B11: 45484 | C11: 4.2673967 | D11: 4.5673967 | E11: 521.43896 | F11: 36.962945 | G11: 0.51 | H11: 0.6105303 | I11: 0.7157203 | J11: 21.480999
A12: 45485 | B12: 45485 | C12: 4.2673967 | D12: 4.5673967 | E12: 521.43896 | F12: 36.962945 | G12: 0.51 | H12: 0.62792874 | I12: 0.69935472 | J12: 21.480999
A13: 45488 | B13: 45488 | C13: 4.2673967 | D13: 4.5673967 | E13: 521.43896 | F13: 36.962945 | G13: 0.48 | H13: 0.68700411 | I13: 0.70432056 | J13: 21.480999
A14: 45489 | B14: 45489 | C14: 4.2673967 | D14: 4.5673967 | E14: 521.43896 | F14: 36.962945 | G14: 0.5 | H14: 0.54610546 | I14: 0.70274327 | J14: 21.480999
A15: 45490 | B15: 45490 | C15: 4.2673967 | D15: 4.5673967 | E15: 521.43896 | F15: 36.962945 | G15: 0.5 | H15: 0.562373 | I15: 0.69713657 | J15: 21.480999
A16: 45491 | B16: 45491 | C16: 4.2673967 | D16: 4.5673967 | E16: 521.43896 | F16: 36.962945 | G16: 0.49 | H16: 0.61849849 | I16: 0.68759396 | J16: 21.480999
A17: 45492 | B17: 45492 | C17: 4.2673967 | D17: 4.5673967 | E17: 521.43896 | F17: 36.962945 | G17: 0.5 | H17: 0.54908808 | I17: 0.70006206 | J17: 21.480999
... A263: 45838 | B263: 45838 | C263: 4.2673967 | D263: 4.5673967 | E263: 521.43896 | F263: 36.962945 | G263: 0.24184791 | H263: 0.57001071 | I263: 0.7082136 | J263: 21.480999

Sheet CurrentPor-LH=10 unchanged
C1: LH = 10 | G1: LH = 20 | H1: LH = 40 | I1: LH = 60 | J1: LH = 20 | K1: Standard deviation of factors
A2: DATE | C2: 1Y_Treasury | D2: 2Y_Treasury | E2: MSFT price | F2: Intel price | G2: Credit spread: sovereign (investment grade, or IG) | H2: Credit spread: sovereign (high yield, or HY) | I2: Credit Spread: Corporate(HY) | J2: Carbon Credits | K2: 1Y_Treasury | L2: 2Y_Treasury | M2: MSFT price | N2: Intel price | O2: Credit spread: sovereign (investment grade, or IG) | P2: Credit spread: sovereign (high yield, or HY) | Q2: Credit Spread: Corporate(HY) | R2: Carbon Credits
A3: 45474 | B3: 45474 | C3: 4.2673967 | D3: 4.5673967 | E3: 521.43896 | F3: 36.962945 | G3: 0.51 | H3: 0.58622522 | I3: 0.69637381 | J3: 21.480999 | K3: =_xlfn.STDEV.P(C3:C263) -> 2.6645353e-15 | L3: =_xlfn.STDEV.P(D3:D263) -> 6.2172489e-15 | M3: =_xlfn.STDEV.P(E3:E263) -> 2.9558578e-12 | N3: =_xlfn.STDEV.P(F3:F263) -> 0 | O3: =_xlfn.STDEV.P(G3:G263) -> 0.060694822 | P3: =_xlfn.STDEV.P(H3:H263) -> 0.052996577 | Q3: =_xlfn.STDEV.P(I3:I263) -> 0.0059420423 | R3: =_xlfn.STDEV.P(J3:J263) -> 6.750156e-14
A4: 45475 | B4: 45475 | C4: 4.2673967 | D4: 4.5673967 | E4: 521.43896 | F4: 36.962945 | G4: 0.51 | H4: 0.66683919 | I4: 0.70908799 | J4: 21.480999 | K4: Standard deviation/Average%
A5: 45476 | B5: 45476 | C5: 4.2673967 | D5: 4.5673967 | E5: 521.43896 | F5: 36.962945 | G5: 0.51 | H5: 0.5738683 | I5: 0.70174466 | J5: 21.480999 | K5: =_xlfn.STDEV.P(C3:C263)/AVERAGE(C3:C263) -> 6.2439362e-16 | L5: =_xlfn.STDEV.P(D3:D263)/AVERAGE(D3:D263) -> 1.3612238e-15 | M5: =_xlfn.STDEV.P(E3:E263)/AVERAGE(E3:E263) -> 5.6686555e-15 | N5: =_xlfn.STDEV.P(F3:F263)/AVERAGE(F3:F263) -> 0 | O5: =_xlfn.STDEV.P(G3:G263)/AVERAGE(G3:G263) -> 0.15633269 | P5: =_xlfn.STDEV.P(H3:H263)/AVERAGE(H3:H263) -> 0.088635041 | Q5: =_xlfn.STDEV.P(I3:I263)/AVERAGE(I3:I263) -> 0.0084803547 | R5: =_xlfn.STDEV.P(J3:J263)/AVERAGE(J3:J263) -> 3.1423846e-15
A6: 45477 | B6: 45477 | C6: 4.2673967 | D6: 4.5673967 | E6: 521.43896 | F6: 36.962945 | G6: 0.51 | H6: 0.55415584 | I6: 0.68446686 | J6: 21.480999
A7: 45478 | B7: 45478 | C7: 4.2673967 | D7: 4.5673967 | E7: 521.43896 | F7: 36.962945 | G7: 0.5 | H7: 0.70278175 | I7: 0.70703017 | J7: 21.480999
A8: 45481 | B8: 45481 | C8: 4.2673967 | D8: 4.5673967 | E8: 521.43896 | F8: 36.962945 | G8: 0.52 | H8: 0.69285184 | I8: 0.70188085 | J8: 21.480999
A9: 45482 | B9: 45482 | C9: 4.2673967 | D9: 4.5673967 | E9: 521.43896 | F9: 36.962945 | G9: 0.52 | H9: 0.62109307 | I9: 0.69910659 | J9: 21.480999
A10: 45483 | B10: 45483 | C10: 4.2673967 | D10: 4.5673967 | E10: 521.43896 | F10: 36.962945 | G10: 0.51 | H10: 0.62999665 | I10: 0.70233 | J10: 21.480999
A11: 45484 | B11: 45484 | C11: 4.2673967 | D11: 4.5673967 | E11: 521.43896 | F11: 36.962945 | G11: 0.51 | H11: 0.6105303 | I11: 0.7157203 | J11: 21.480999
A12: 45485 | B12: 45485 | C12: 4.2673967 | D12: 4.5673967 | E12: 521.43896 | F12: 36.962945 | G12: 0.51 | H12: 0.62792874 | I12: 0.69935472 | J12: 21.480999
A13: 45488 | B13: 45488 | C13: 4.2673967 | D13: 4.5673967 | E13: 521.43896 | F13: 36.962945 | G13: 0.48 | H13: 0.68700411 | I13: 0.70432056 | J13: 21.480999
A14: 45489 | B14: 45489 | C14: 4.2673967 | D14: 4.5673967 | E14: 521.43896 | F14: 36.962945 | G14: 0.5 | H14: 0.54610546 | I14: 0.70274327 | J14: 21.480999
A15: 45490 | B15: 45490 | C15: 4.2673967 | D15: 4.5673967 | E15: 521.43896 | F15: 36.962945 | G15: 0.5 | H15: 0.562373 | I15: 0.69713657 | J15: 21.480999
A16: 45491 | B16: 45491 | C16: 4.2673967 | D16: 4.5673967 | E16: 521.43896 | F16: 36.962945 | G16: 0.49 | H16: 0.61849849 | I16: 0.68759396 | J16: 21.480999
A17: 45492 | B17: 45492 | C17: 4.2673967 | D17: 4.5673967 | E17: 521.43896 | F17: 36.962945 | G17: 0.5 | H17: 0.54908808 | I17: 0.70006206 | J17: 21.480999
... A263: 45838 | B263: 45838 | C263: 4.2673967 | D263: 4.5673967 | E263: 521.43896 | F263: 36.962945 | G263: 0.24184791 | H263: 0.57001071 | I263: 0.7082136 | J263: 21.480999

Sheet CurrentPor-LH=20 unchanged
C1: LH = 10 | G1: LH = 20 | H1: LH = 40 | I1: LH = 60 | J1: LH = 20 | K1: Standard deviation of factors
A2: DATE | C2: 1Y_Treasury | D2: 2Y_Treasury | E2: MSFT price | F2: Intel price | G2: Credit spread: sovereign (investment grade, or IG) | H2: Credit spread: sovereign (high yield, or HY) | I2: Credit Spread: Corporate(HY) | J2: Carbon Credits | K2: 1Y_Treasury | L2: 2Y_Treasury | M2: MSFT price | N2: Intel price | O2: Credit spread: sovereign (investment grade, or IG) | P2: Credit spread: sovereign (high yield, or HY) | Q2: Credit Spread: Corporate(HY) | R2: Carbon Credits
A3: 45474 | B3: 45474 | C3: 4.2673967 | D3: 4.5673967 | E3: 521.43896 | F3: 36.962945 | G3: 0.51 | H3: 0.58622522 | I3: 0.69637381 | J3: 21.480999 | K3: =_xlfn.STDEV.P(C3:C263) -> 2.6645353e-15 | L3: =_xlfn.STDEV.P(D3:D263) -> 6.2172489e-15 | M3: =_xlfn.STDEV.P(E3:E263) -> 2.9558578e-12 | N3: =_xlfn.STDEV.P(F3:F263) -> 0 | O3: =_xlfn.STDEV.P(G3:G263) -> 1.7763568e-15 | P3: =_xlfn.STDEV.P(H3:H263) -> 0.052996577 | Q3: =_xlfn.STDEV.P(I3:I263) -> 0.0059420423 | R3: =_xlfn.STDEV.P(J3:J263) -> 6.750156e-14
A4: 45475 | B4: 45475 | C4: 4.2673967 | D4: 4.5673967 | E4: 521.43896 | F4: 36.962945 | G4: 0.51 | H4: 0.66683919 | I4: 0.70908799 | J4: 21.480999 | K4: Standard deviation/Average%
A5: 45476 | B5: 45476 | C5: 4.2673967 | D5: 4.5673967 | E5: 521.43896 | F5: 36.962945 | G5: 0.51 | H5: 0.5738683 | I5: 0.70174466 | J5: 21.480999 | K5: =_xlfn.STDEV.P(C3:C263)/AVERAGE(C3:C263) -> 6.2439362e-16 | L5: =_xlfn.STDEV.P(D3:D263)/AVERAGE(D3:D263) -> 1.3612238e-15 | M5: =_xlfn.STDEV.P(E3:E263)/AVERAGE(E3:E263) -> 5.6686555e-15 | N5: =_xlfn.STDEV.P(F3:F263)/AVERAGE(F3:F263) -> 0 | O5: =_xlfn.STDEV.P(G3:G263)/AVERAGE(G3:G263) -> 3.4830526e-15 | P5: =_xlfn.STDEV.P(H3:H263)/AVERAGE(H3:H263) -> 0.088635041 | Q5: =_xlfn.STDEV.P(I3:I263)/AVERAGE(I3:I263) -> 0.0084803547 | R5: =_xlfn.STDEV.P(J3:J263)/AVERAGE(J3:J263) -> 3.1423846e-15
A6: 45477 | B6: 45477 | C6: 4.2673967 | D6: 4.5673967 | E6: 521.43896 | F6: 36.962945 | G6: 0.51 | H6: 0.55415584 | I6: 0.68446686 | J6: 21.480999
A7: 45478 | B7: 45478 | C7: 4.2673967 | D7: 4.5673967 | E7: 521.43896 | F7: 36.962945 | G7: 0.51 | H7: 0.70278175 | I7: 0.70703017 | J7: 21.480999
A8: 45481 | B8: 45481 | C8: 4.2673967 | D8: 4.5673967 | E8: 521.43896 | F8: 36.962945 | G8: 0.51 | H8: 0.69285184 | I8: 0.70188085 | J8: 21.480999
A9: 45482 | B9: 45482 | C9: 4.2673967 | D9: 4.5673967 | E9: 521.43896 | F9: 36.962945 | G9: 0.51 | H9: 0.62109307 | I9: 0.69910659 | J9: 21.480999
A10: 45483 | B10: 45483 | C10: 4.2673967 | D10: 4.5673967 | E10: 521.43896 | F10: 36.962945 | G10: 0.51 | H10: 0.62999665 | I10: 0.70233 | J10: 21.480999
A11: 45484 | B11: 45484 | C11: 4.2673967 | D11: 4.5673967 | E11: 521.43896 | F11: 36.962945 | G11: 0.51 | H11: 0.6105303 | I11: 0.7157203 | J11: 21.480999
A12: 45485 | B12: 45485 | C12: 4.2673967 | D12: 4.5673967 | E12: 521.43896 | F12: 36.962945 | G12: 0.51 | H12: 0.62792874 | I12: 0.69935472 | J12: 21.480999
A13: 45488 | B13: 45488 | C13: 4.2673967 | D13: 4.5673967 | E13: 521.43896 | F13: 36.962945 | G13: 0.51 | H13: 0.68700411 | I13: 0.70432056 | J13: 21.480999
A14: 45489 | B14: 45489 | C14: 4.2673967 | D14: 4.5673967 | E14: 521.43896 | F14: 36.962945 | G14: 0.51 | H14: 0.54610546 | I14: 0.70274327 | J14: 21.480999
A15: 45490 | B15: 45490 | C15: 4.2673967 | D15: 4.5673967 | E15: 521.43896 | F15: 36.962945 | G15: 0.51 | H15: 0.562373 | I15: 0.69713657 | J15: 21.480999
A16: 45491 | B16: 45491 | C16: 4.2673967 | D16: 4.5673967 | E16: 521.43896 | F16: 36.962945 | G16: 0.51 | H16: 0.61849849 | I16: 0.68759396 | J16: 21.480999
A17: 45492 | B17: 45492 | C17: 4.2673967 | D17: 4.5673967 | E17: 521.43896 | F17: 36.962945 | G17: 0.51 | H17: 0.54908808 | I17: 0.70006206 | J17: 21.480999
... A263: 45838 | B263: 45838 | C263: 4.2673967 | D263: 4.5673967 | E263: 521.43896 | F263: 36.962945 | G263: 0.51 | H263: 0.57001071 | I263: 0.7082136 | J263: 21.480999

Sheet CurrentPor-LH=40 unchanged
C1: LH = 10 | G1: LH = 20 | H1: LH = 40 | I1: LH = 60 | J1: LH = 20 | K1: Standard deviation of factors
A2: DATE | C2: 1Y_Treasury | D2: 2Y_Treasury | E2: MSFT price | F2: Intel price | G2: Credit spread: sovereign (investment grade, or IG) | H2: Credit spread: sovereign (high yield, or HY) | I2: Credit Spread: Corporate(HY) | J2: Carbon Credits | K2: 1Y_Treasury | L2: 2Y_Treasury | M2: MSFT price | N2: Intel price | O2: Credit spread: sovereign (investment grade, or IG) | P2: Credit spread: sovereign (high yield, or HY) | Q2: Credit Spread: Corporate(HY) | R2: Carbon Credits
A3: 45474 | B3: 45474 | C3: 4.2673967 | D3: 4.5673967 | E3: 521.43896 | F3: 36.962945 | G3: 0.51 | H3: 0.58622522 | I3: 0.69637381 | J3: 21.480999 | K3: =_xlfn.STDEV.P(C3:C263) -> 2.6645353e-15 | L3: =_xlfn.STDEV.P(D3:D263) -> 6.2172489e-15 | M3: =_xlfn.STDEV.P(E3:E263) -> 2.9558578e-12 | N3: =_xlfn.STDEV.P(F3:F263) -> 0 | O3: =_xlfn.STDEV.P(G3:G263) -> 1.7763568e-15 | P3: =_xlfn.STDEV.P(H3:H263) -> 1.8873791e-15 | Q3: =_xlfn.STDEV.P(I3:I263) -> 0.0059420423 | R3: =_xlfn.STDEV.P(J3:J263) -> 6.750156e-14
A4: 45475 | B4: 45475 | C4: 4.2673967 | D4: 4.5673967 | E4: 521.43896 | F4: 36.962945 | G4: 0.51 | H4: 0.58622522 | I4: 0.70908799 | J4: 21.480999 | K4: Standard deviation/Average%
A5: 45476 | B5: 45476 | C5: 4.2673967 | D5: 4.5673967 | E5: 521.43896 | F5: 36.962945 | G5: 0.51 | H5: 0.58622522 | I5: 0.70174466 | J5: 21.480999 | K5: =_xlfn.STDEV.P(C3:C263)/AVERAGE(C3:C263) -> 6.2439362e-16 | L5: =_xlfn.STDEV.P(D3:D263)/AVERAGE(D3:D263) -> 1.3612238e-15 | M5: =_xlfn.STDEV.P(E3:E263)/AVERAGE(E3:E263) -> 5.6686555e-15 | N5: =_xlfn.STDEV.P(F3:F263)/AVERAGE(F3:F263) -> 0 | O5: =_xlfn.STDEV.P(G3:G263)/AVERAGE(G3:G263) -> 3.4830526e-15 | P5: =_xlfn.STDEV.P(H3:H263)/AVERAGE(H3:H263) -> 3.2195461e-15 | Q5: =_xlfn.STDEV.P(I3:I263)/AVERAGE(I3:I263) -> 0.0084803547 | R5: =_xlfn.STDEV.P(J3:J263)/AVERAGE(J3:J263) -> 3.1423846e-15
A6: 45477 | B6: 45477 | C6: 4.2673967 | D6: 4.5673967 | E6: 521.43896 | F6: 36.962945 | G6: 0.51 | H6: 0.58622522 | I6: 0.68446686 | J6: 21.480999
A7: 45478 | B7: 45478 | C7: 4.2673967 | D7: 4.5673967 | E7: 521.43896 | F7: 36.962945 | G7: 0.51 | H7: 0.58622522 | I7: 0.70703017 | J7: 21.480999
A8: 45481 | B8: 45481 | C8: 4.2673967 | D8: 4.5673967 | E8: 521.43896 | F8: 36.962945 | G8: 0.51 | H8: 0.58622522 | I8: 0.70188085 | J8: 21.480999
A9: 45482 | B9: 45482 | C9: 4.2673967 | D9: 4.5673967 | E9: 521.43896 | F9: 36.962945 | G9: 0.51 | H9: 0.58622522 | I9: 0.69910659 | J9: 21.480999
A10: 45483 | B10: 45483 | C10: 4.2673967 | D10: 4.5673967 | E10: 521.43896 | F10: 36.962945 | G10: 0.51 | H10: 0.58622522 | I10: 0.70233 | J10: 21.480999
A11: 45484 | B11: 45484 | C11: 4.2673967 | D11: 4.5673967 | E11: 521.43896 | F11: 36.962945 | G11: 0.51 | H11: 0.58622522 | I11: 0.7157203 | J11: 21.480999
A12: 45485 | B12: 45485 | C12: 4.2673967 | D12: 4.5673967 | E12: 521.43896 | F12: 36.962945 | G12: 0.51 | H12: 0.58622522 | I12: 0.69935472 | J12: 21.480999
A13: 45488 | B13: 45488 | C13: 4.2673967 | D13: 4.5673967 | E13: 521.43896 | F13: 36.962945 | G13: 0.51 | H13: 0.58622522 | I13: 0.70432056 | J13: 21.480999
A14: 45489 | B14: 45489 | C14: 4.2673967 | D14: 4.5673967 | E14: 521.43896 | F14: 36.962945 | G14: 0.51 | H14: 0.58622522 | I14: 0.70274327 | J14: 21.480999
A15: 45490 | B15: 45490 | C15: 4.2673967 | D15: 4.5673967 | E15: 521.43896 | F15: 36.962945 | G15: 0.51 | H15: 0.58622522 | I15: 0.69713657 | J15: 21.480999
A16: 45491 | B16: 45491 | C16: 4.2673967 | D16: 4.5673967 | E16: 521.43896 | F16: 36.962945 | G16: 0.51 | H16: 0.58622522 | I16: 0.68759396 | J16: 21.480999
A17: 45492 | B17: 45492 | C17: 4.2673967 | D17: 4.5673967 | E17: 521.43896 | F17: 36.962945 | G17: 0.51 | H17: 0.58622522 | I17: 0.70006206 | J17: 21.480999
... A263: 45838 | B263: 45838 | C263: 4.2673967 | D263: 4.5673967 | E263: 521.43896 | F263: 36.962945 | G263: 0.51 | H263: 0.58622522 | I263: 0.7082136 | J263: 21.480999

Sheet CurrentPor-LH=60 unchanged
C1: LH = 10 | G1: LH = 20 | H1: LH = 40 | I1: LH = 60 | J1: LH = 20 | K1: Standard deviation of factors
A2: DATE | C2: 1Y_Treasury | D2: 2Y_Treasury | E2: MSFT price | F2: Intel price | G2: Credit spread: sovereign (investment grade, or IG) | H2: Credit spread: sovereign (high yield, or HY) | I2: Credit Spread: Corporate(HY) | J2: Carbon Credits | K2: 1Y_Treasury | L2: 2Y_Treasury | M2: MSFT price | N2: Intel price | O2: Credit spread: sovereign (investment grade, or IG) | P2: Credit spread: sovereign (high yield, or HY) | Q2: Credit Spread: Corporate(HY) | R2: Carbon Credits
A3: 45474 | B3: 45474 | C3: 4.2673967 | D3: 4.5673967 | E3: 521.43896 | F3: 36.962945 | G3: 0.51 | H3: 0.58622522 | I3: 0.69637381 | J3: 21.480999 | K3: =_xlfn.STDEV.P(C3:C263) -> 2.6645353e-15 | L3: =_xlfn.STDEV.P(D3:D263) -> 6.2172489e-15 | M3: =_xlfn.STDEV.P(E3:E263) -> 2.9558578e-12 | N3: =_xlfn.STDEV.P(F3:F263) -> 0 | O3: =_xlfn.STDEV.P(G3:G263) -> 1.7763568e-15 | P3: =_xlfn.STDEV.P(H3:H263) -> 1.8873791e-15 | Q3: =_xlfn.STDEV.P(I3:I263) -> 3.663736e-15 | R3: =_xlfn.STDEV.P(J3:J263) -> 6.750156e-14
A4: 45475 | B4: 45475 | C4: 4.2673967 | D4: 4.5673967 | E4: 521.43896 | F4: 36.962945 | G4: 0.51 | H4: 0.58622522 | I4: 0.69637381 | J4: 21.480999 | K4: Standard deviation/Average%
A5: 45476 | B5: 45476 | C5: 4.2673967 | D5: 4.5673967 | E5: 521.43896 | F5: 36.962945 | G5: 0.51 | H5: 0.58622522 | I5: 0.69637381 | J5: 21.480999 | K5: =_xlfn.STDEV.P(C3:C263)/AVERAGE(C3:C263) -> 6.2439362e-16 | L5: =_xlfn.STDEV.P(D3:D263)/AVERAGE(D3:D263) -> 1.3612238e-15 | M5: =_xlfn.STDEV.P(E3:E263)/AVERAGE(E3:E263) -> 5.6686555e-15 | N5: =_xlfn.STDEV.P(F3:F263)/AVERAGE(F3:F263) -> 0 | O5: =_xlfn.STDEV.P(G3:G263)/AVERAGE(G3:G263) -> 3.4830526e-15 | P5: =_xlfn.STDEV.P(H3:H263)/AVERAGE(H3:H263) -> 3.2195461e-15 | Q5: =_xlfn.STDEV.P(I3:I263)/AVERAGE(I3:I263) -> 5.2611628e-15 | R5: =_xlfn.STDEV.P(J3:J263)/AVERAGE(J3:J263) -> 3.1423846e-15
A6: 45477 | B6: 45477 | C6: 4.2673967 | D6: 4.5673967 | E6: 521.43896 | F6: 36.962945 | G6: 0.51 | H6: 0.58622522 | I6: 0.69637381 | J6: 21.480999
A7: 45478 | B7: 45478 | C7: 4.2673967 | D7: 4.5673967 | E7: 521.43896 | F7: 36.962945 | G7: 0.51 | H7: 0.58622522 | I7: 0.69637381 | J7: 21.480999
A8: 45481 | B8: 45481 | C8: 4.2673967 | D8: 4.5673967 | E8: 521.43896 | F8: 36.962945 | G8: 0.51 | H8: 0.58622522 | I8: 0.69637381 | J8: 21.480999
A9: 45482 | B9: 45482 | C9: 4.2673967 | D9: 4.5673967 | E9: 521.43896 | F9: 36.962945 | G9: 0.51 | H9: 0.58622522 | I9: 0.69637381 | J9: 21.480999
A10: 45483 | B10: 45483 | C10: 4.2673967 | D10: 4.5673967 | E10: 521.43896 | F10: 36.962945 | G10: 0.51 | H10: 0.58622522 | I10: 0.69637381 | J10: 21.480999
A11: 45484 | B11: 45484 | C11: 4.2673967 | D11: 4.5673967 | E11: 521.43896 | F11: 36.962945 | G11: 0.51 | H11: 0.58622522 | I11: 0.69637381 | J11: 21.480999
A12: 45485 | B12: 45485 | C12: 4.2673967 | D12: 4.5673967 | E12: 521.43896 | F12: 36.962945 | G12: 0.51 | H12: 0.58622522 | I12: 0.69637381 | J12: 21.480999
A13: 45488 | B13: 45488 | C13: 4.2673967 | D13: 4.5673967 | E13: 521.43896 | F13: 36.962945 | G13: 0.51 | H13: 0.58622522 | I13: 0.69637381 | J13: 21.480999
A14: 45489 | B14: 45489 | C14: 4.2673967 | D14: 4.5673967 | E14: 521.43896 | F14: 36.962945 | G14: 0.51 | H14: 0.58622522 | I14: 0.69637381 | J14: 21.480999
A15: 45490 | B15: 45490 | C15: 4.2673967 | D15: 4.5673967 | E15: 521.43896 | F15: 36.962945 | G15: 0.51 | H15: 0.58622522 | I15: 0.69637381 | J15: 21.480999
A16: 45491 | B16: 45491 | C16: 4.2673967 | D16: 4.5673967 | E16: 521.43896 | F16: 36.962945 | G16: 0.51 | H16: 0.58622522 | I16: 0.69637381 | J16: 21.480999
A17: 45492 | B17: 45492 | C17: 4.2673967 | D17: 4.5673967 | E17: 521.43896 | F17: 36.962945 | G17: 0.51 | H17: 0.58622522 | I17: 0.69637381 | J17: 21.480999
... A263: 45838 | B263: 45838 | C263: 4.2673967 | D263: 4.5673967 | E263: 521.43896 | F263: 36.962945 | G263: 0.51 | H263: 0.58622522 | I263: 0.69637381 | J263: 21.480999

Sheet Portfolio
A1: Holding | B1: Quantity | C1: Coupon | D1: Notional | E1: Price | F1: Total | J1: T | N1: LH | O1: ES | P1: Absolute ES | Q1: Calculated value
A2: Treasury bonds | B2: 100 | C2: 3 | D2: 100 | F2: =B2*D2 -> 10000 | J2: 10 | M2: EST(P) | O2: ='ES, Equity factor movement'!L3 -> -32.825414 | P2: =ABS(O2) -> 32.825414 | Q2: =P2*P2 -> 1077.5078
A3: Sovereign Bonds HY | B3: 100 | C3: 3 | D3: 100 | F3: =B3*D3 -> 10000 | M3: EST(P,2) | N3: 20 | O3: ='ES, Credit LH=10Unchanged'!L3 -> -32.825414 | P3: =ABS(O3) -> 32.825414 | Q3: =POWER(P3*SQRT(10/10),2) -> 1077.5078
A4: Sovereign Bonds IG | B4: 100 | C4: 3 | D4: 100 | F4: =B4*D4 -> 10000 | M4: EST(P,3) | N4: 40 | O4: ='ES, Credit LH=20Unchanged'!L3 -> -30.607706 | P4: =ABS(O4) -> 30.607706 | Q4: =POWER(P4*SQRT(20/10),2) -> 1873.6634
A5: MSFT stocks | B5: 100 | E5: 500 | F5: =B5*E5 -> 50000 | M5: EST(P,4) | N5: 60 | O5: ='ES, Credit LH=40Unchanged'!L3 -> -3.1479407 | P5: =ABS(O5) -> 3.1479407 | Q5: =POWER(P5*SQRT(20/10),2) -> 19.819062
A6: Intel Stock | B6: 100 | E6: 36 | F6: =B6*E6 -> 3600 | P6: ESF,C | Q6: =SQRT(SUM(Q2:Q2)) -> 32.825414
A7: Carbon credits | B7: 100 | E7: 20 | F7: =B7*E7 -> 2000
A8: Credit Spread Corporate HY | B8: 100 | C8: 3 | D8: 100 | F8: =B8*D8 -> 10000
F9: =SUM(F2:F8) -> 95600

Sheet ES, Equity factor movement
B1: LH=10 | C1: LH=10, 20 | D1: LH=10, 40 | E1: LH=10, 60 | F1: LH=10 | G1: LH=10 | H1: LH=20
B2: Treasury Bonds IG valuation | C2: Credit spread: Sovereign Bonds IG valuation | D2: Credit spread: sovereign (high yield, or HY) | E2: Credit Spread:Corporate HY | F2: MSFT | G2: Intel | H2: carbon credits | I2: Portfolio value | J2: 10 day PnL | K2: VaR | L2: ES, Q(pi,1)
A3: 45474 | B3: =(3/(1+('CurrentPor-Equ Factor Movements'!C3)/100)+103/POWER(1+('CurrentPor-Equ Factor Movements'!D3)/100,2))*100 -> 9707.5858 | C3: =(3/(1+('CurrentPor-Equ Factor Movements'!C3+'CurrentPor-Equ Factor Movements'!G3)/100)+103/POWER(1+('CurrentPor-Equ Factor Movements'!D3+'CurrentPor-Equ Factor Movements'!G3)/100,2))*100 -> 9614.9674 | D3: =(3/(1+('CurrentPor-Equ Factor Movements'!C3+'CurrentPor-Equ Factor Movements'!H3)/100)+103/POWER(1+('CurrentPor-Equ Factor Movements'!D3+'CurrentPor-Equ Factor Movements'!H3)/100,2))*100 -> 9601.2396 | E3: =(3/(1+('CurrentPor-Equ Factor Movements'!C3+'CurrentPor-Equ Factor Movements'!I3)/100)+103/POWER(1+('CurrentPor-Equ Factor Movements'!D3+'CurrentPor-Equ Factor Movements'!I3)/100,2))*100 -> 9581.4547 | F3: =Portfolio!B$5*'CurrentPor-Equ Factor Movements'!E3 -> 52143.896 | G3: =Portfolio!B$6*'CurrentPor-Equ Factor Movements'!F3 -> 3696.2945 | H3: =Portfolio!B$7*'CurrentPor-Equ Factor Movements'!J3 -> 2148.0999 | I3: =SUM(B3:H3) -> 96493.537 | K3: =_xlfn.PERCENTILE.INC(J13:J263, 0.025) -> -30.682238 | L3: =AVERAGEIF(J13:J263, "<="&K3,J13:J263) -> -32.825414
A4: 45475 | B4: =(3/(1+('CurrentPor-Equ Factor Movements'!C4)/100)+103/POWER(1+('CurrentPor-Equ Factor Movements'!D4)/100,2))*100 -> 9707.5858 | C4: =(3/(1+('CurrentPor-Equ Factor Movements'!C4+'CurrentPor-Equ Factor Movements'!G4)/100)+103/POWER(1+('CurrentPor-Equ Factor Movements'!D4+'CurrentPor-Equ Factor Movements'!G4)/100,2))*100 -> 9614.9674 | D4: =(3/(1+('CurrentPor-Equ Factor Movements'!C4+'CurrentPor-Equ Factor Movements'!H4)/100)+103/POWER(1+('CurrentPor-Equ Factor Movements'!D4+'CurrentPor-Equ Factor Movements'!H4)/100,2))*100 -> 9586.7536 | E4: =(3/(1+('CurrentPor-Equ Factor Movements'!C4+'CurrentPor-Equ Factor Movements'!I4)/100)+103/POWER(1+('CurrentPor-Equ Factor Movements'!D4+'CurrentPor-Equ Factor Movements'!I4)/100,2))*100 -> 9579.175 | F4: =Portfolio!B$5*'CurrentPor-Equ Factor Movements'!E4 -> 52143.896 | G4: =Portfolio!B$6*'CurrentPor-Equ Factor Movements'!F4 -> 3696.2945 | H4: =Portfolio!B$7*'CurrentPor-Equ Factor Movements'!J4 -> 2148.0999 | I4: =SUM(B4:H4) -> 96476.772
A5: 45476 | B5: =(3/(1+('CurrentPor-Equ Factor Movements'!C5)/100)+103/POWER(1+('CurrentPor-Equ Factor Movements'!D5)/100,2))*100 -> 9707.5858 | C5: =(3/(1+('CurrentPor-Equ Factor Movements'!C5+'CurrentPor-Equ Factor Movements'!G5)/100)+103/POWER(1+('CurrentPor-Equ Factor Movements'!D5+'CurrentPor-Equ Factor Movements'!G5)/100,2))*100 -> 9614.9674 | D5: =(3/(1+('CurrentPor-Equ Factor Movements'!C5+'CurrentPor-Equ Factor Movements'!H5)/100)+103/POWER(1+('CurrentPor-Equ Factor Movements'!D5+'CurrentPor-Equ Factor Movements'!H5)/100,2))*100 -> 9603.463 | E5: =(3/(1+('CurrentPor-Equ Factor Movements'!C5+'CurrentPor-Equ Factor Movements'!I5)/100)+103/POWER(1+('CurrentPor-Equ Factor Movements'!D5+'CurrentPor-Equ Factor Movements'!I5)/100,2))*100 -> 9580.4916 | F5: =Portfolio!B$5*'CurrentPor-Equ Factor Movements'!E5 -> 52143.896 | G5: =Portfolio!B$6*'CurrentPor-Equ Factor Movements'!F5 -> 3696.2945 | H5: =Portfolio!B$7*'CurrentPor-Equ Factor Movements'!J5 -> 2148.0999 | I5: =SUM(B5:H5) -> 96494.798
A6: 45477 | B6: =(3/(1+('CurrentPor-Equ Factor Movements'!C6)/100)+103/POWER(1+('CurrentPor-Equ Factor Movements'!D6)/100,2))*100 -> 9707.5858 | C6: =(3/(1+('CurrentPor-Equ Factor Movements'!C6+'CurrentPor-Equ Factor Movements'!G6)/100)+103/POWER(1+('CurrentPor-Equ Factor Movements'!D6+'CurrentPor-Equ Factor Movements'!G6)/100,2))*100 -> 9614.9674 | D6: =(3/(1+('CurrentPor-Equ Factor Movements'!C6+'CurrentPor-Equ Factor Movements'!H6)/100)+103/POWER(1+('CurrentPor-Equ Factor Movements'!D6+'CurrentPor-Equ Factor Movements'!H6)/100,2))*100 -> 9607.0115 | E6: =(3/(1+('CurrentPor-Equ Factor Movements'!C6+'CurrentPor-Equ Factor Movements'!I6)/100)+103/POWER(1+('CurrentPor-Equ Factor Movements'!D6+'CurrentPor-Equ Factor Movements'!I6)/100,2))*100 -> 9583.5905 | F6: =Portfolio!B$5*'CurrentPor-Equ Factor Movements'!E6 -> 52143.896 | G6: =Portfolio!B$6*'CurrentPor-Equ Factor Movements'!F6 -> 3696.2945 | H6: =Portfolio!B$7*'CurrentPor-Equ Factor Movements'!J6 -> 2148.0999 | I6: =SUM(B6:H6) -> 96501.445
A7: 45478 | B7: =(3/(1+('CurrentPor-Equ Factor Movements'!C7)/100)+103/POWER(1+('CurrentPor-Equ Factor Movements'!D7)/100,2))*100 -> 9707.5858 | C7: =(3/(1+('CurrentPor-Equ Factor Movements'!C7+'CurrentPor-Equ Factor Movements'!G7)/100)+103/POWER(1+('CurrentPor-Equ Factor Movements'!D7+'CurrentPor-Equ Factor Movements'!G7)/100,2))*100 -> 9616.7705 | D7: =(3/(1+('CurrentPor-Equ Factor Movements'!C7+'CurrentPor-Equ Factor Movements'!H7)/100)+103/POWER(1+('CurrentPor-Equ Factor Movements'!D7+'CurrentPor-Equ Factor Movements'!H7)/100,2))*100 -> 9580.3056 | E7: =(3/(1+('CurrentPor-Equ Factor Movements'!C7+'CurrentPor-Equ Factor Movements'!I7)/100)+103/POWER(1+('CurrentPor-Equ Factor Movements'!D7+'CurrentPor-Equ Factor Movements'!I7)/100,2))*100 -> 9579.5439 | F7: =Portfolio!B$5*'CurrentPor-Equ Factor Movements'!E7 -> 52143.896 | G7: =Portfolio!B$6*'CurrentPor-Equ Factor Movements'!F7 -> 3696.2945 | H7: =Portfolio!B$7*'CurrentPor-Equ Factor Movements'!J7 -> 2148.0999 | I7: =SUM(B7:H7) -> 96472.496
A8: 45481 | B8: =(3/(1+('CurrentPor-Equ Factor Movements'!C8)/100)+103/POWER(1+('CurrentPor-Equ Factor Movements'!D8)/100,2))*100 -> 9707.5858 | C8: =(3/(1+('CurrentPor-Equ Factor Movements'!C8+'CurrentPor-Equ Factor Movements'!G8)/100)+103/POWER(1+('CurrentPor-Equ Factor Movements'!D8+'CurrentPor-Equ Factor Movements'!G8)/100,2))*100 -> 9613.1647 | D8: =(3/(1+('CurrentPor-Equ Factor Movements'!C8+'CurrentPor-Equ Factor Movements'!H8)/100)+103/POWER(1+('CurrentPor-Equ Factor Movements'!D8+'CurrentPor-Equ Factor Movements'!H8)/100,2))*100 -> 9582.0864 | E8: =(3/(1+('CurrentPor-Equ Factor Movements'!C8+'CurrentPor-Equ Factor Movements'!I8)/100)+103/POWER(1+('CurrentPor-Equ Factor Movements'!D8+'CurrentPor-Equ Factor Movements'!I8)/100,2))*100 -> 9580.4672 | F8: =Portfolio!B$5*'CurrentPor-Equ Factor Movements'!E8 -> 52143.896 | G8: =Portfolio!B$6*'CurrentPor-Equ Factor Movements'!F8 -> 3696.2945 | H8: =Portfolio!B$7*'CurrentPor-Equ Factor Movements'!J8 -> 2148.0999 | I8: =SUM(B8:H8) -> 96471.594
A9: 45482 | B9: =(3/(1+('CurrentPor-Equ Factor Movements'!C9)/100)+103/POWER(1+('CurrentPor-Equ Factor Movements'!D9)/100,2))*100 -> 9707.5858 | C9: =(3/(1+('CurrentPor-Equ Factor Movements'!C9+'CurrentPor-Equ Factor Movements'!G9)/100)+103/POWER(1+('CurrentPor-Equ Factor Movements'!D9+'CurrentPor-Equ Factor Movements'!G9)/100,2))*100 -> 9613.1647 | D9: =(3/(1+('CurrentPor-Equ Factor Movements'!C9+'CurrentPor-Equ Factor Movements'!H9)/100)+103/POWER(1+('CurrentPor-Equ Factor Movements'!D9+'CurrentPor-Equ Factor Movements'!H9)/100,2))*100 -> 9594.9699 | E9: =(3/(1+('CurrentPor-Equ Factor Movements'!C9+'CurrentPor-Equ Factor Movements'!I9)/100)+103/POWER(1+('CurrentPor-Equ Factor Movements'!D9+'CurrentPor-Equ Factor Movements'!I9)/100,2))*100 -> 9580.9646 | F9: =Portfolio!B$5*'CurrentPor-Equ Factor Movements'!E9 -> 52143.896 | G9: =Portfolio!B$6*'CurrentPor-Equ Factor Movements'!F9 -> 3696.2945 | H9: =Portfolio!B$7*'CurrentPor-Equ Factor Movements'!J9 -> 2148.0999 | I9: =SUM(B9:H9) -> 96484.975
A10: 45483 | B10: =(3/(1+('CurrentPor-Equ Factor Movements'!C10)/100)+103/POWER(1+('CurrentPor-Equ Factor Movements'!D10)/100,2))*100 -> 9707.5858 | C10: =(3/(1+('CurrentPor-Equ Factor Movements'!C10+'CurrentPor-Equ Factor Movements'!G10)/100)+103/POWER(1+('CurrentPor-Equ Factor Movements'!D10+'CurrentPor-Equ Factor Movements'!G10)/100,2))*100 -> 9614.9674 | D10: =(3/(1+('CurrentPor-Equ Factor Movements'!C10+'CurrentPor-Equ Factor Movements'!H10)/100)+103/POWER(1+('CurrentPor-Equ Factor Movements'!D10+'CurrentPor-Equ Factor Movements'!H10)/100,2))*100 -> 9593.3699 | E10: =(3/(1+('CurrentPor-Equ Factor Movements'!C10+'CurrentPor-Equ Factor Movements'!I10)/100)+103/POWER(1+('CurrentPor-Equ Factor Movements'!D10+'CurrentPor-Equ Factor Movements'!I10)/100,2))*100 -> 9580.3866 | F10: =Portfolio!B$5*'CurrentPor-Equ Factor Movements'!E10 -> 52143.896 | G10: =Portfolio!B$6*'CurrentPor-Equ Factor Movements'!F10 -> 3696.2945 | H10: =Portfolio!B$7*'CurrentPor-Equ Factor Movements'!J10 -> 2148.0999 | I10: =SUM(B10:H10) -> 96484.6
A11: 45484 | B11: =(3/(1+('CurrentPor-Equ Factor Movements'!C11)/100)+103/POWER(1+('CurrentPor-Equ Factor Movements'!D11)/100,2))*100 -> 9707.5858 | C11: =(3/(1+('CurrentPor-Equ Factor Movements'!C11+'CurrentPor-Equ Factor Movements'!G11)/100)+103/POWER(1+('CurrentPor-Equ Factor Movements'!D11+'CurrentPor-Equ Factor Movements'!G11)/100,2))*100 -> 9614.9674 | D11: =(3/(1+('CurrentPor-Equ Factor Movements'!C11+'CurrentPor-Equ Factor Movements'!H11)/100)+103/POWER(1+('CurrentPor-Equ Factor Movements'!D11+'CurrentPor-Equ Factor Movements'!H11)/100,2))*100 -> 9596.8686 | E11: =(3/(1+('CurrentPor-Equ Factor Movements'!C11+'CurrentPor-Equ Factor Movements'!I11)/100)+103/POWER(1+('CurrentPor-Equ Factor Movements'!D11+'CurrentPor-Equ Factor Movements'!I11)/100,2))*100 -> 9577.9861 | F11: =Portfolio!B$5*'CurrentPor-Equ Factor Movements'!E11 -> 52143.896 | G11: =Portfolio!B$6*'CurrentPor-Equ Factor Movements'!F11 -> 3696.2945 | H11: =Portfolio!B$7*'CurrentPor-Equ Factor Movements'!J11 -> 2148.0999 | I11: =SUM(B11:H11) -> 96485.698
A12: 45485 | B12: =(3/(1+('CurrentPor-Equ Factor Movements'!C12)/100)+103/POWER(1+('CurrentPor-Equ Factor Movements'!D12)/100,2))*100 -> 9707.5858 | C12: =(3/(1+('CurrentPor-Equ Factor Movements'!C12+'CurrentPor-Equ Factor Movements'!G12)/100)+103/POWER(1+('CurrentPor-Equ Factor Movements'!D12+'CurrentPor-Equ Factor Movements'!G12)/100,2))*100 -> 9614.9674 | D12: =(3/(1+('CurrentPor-Equ Factor Movements'!C12+'CurrentPor-Equ Factor Movements'!H12)/100)+103/POWER(1+('CurrentPor-Equ Factor Movements'!D12+'CurrentPor-Equ Factor Movements'!H12)/100,2))*100 -> 9593.7415 | E12: =(3/(1+('CurrentPor-Equ Factor Movements'!C12+'CurrentPor-Equ Factor Movements'!I12)/100)+103/POWER(1+('CurrentPor-Equ Factor Movements'!D12+'CurrentPor-Equ Factor Movements'!I12)/100,2))*100 -> 9580.9201 | F12: =Portfolio!B$5*'CurrentPor-Equ Factor Movements'!E12 -> 52143.896 | G12: =Portfolio!B$6*'CurrentPor-Equ Factor Movements'!F12 -> 3696.2945 | H12: =Portfolio!B$7*'CurrentPor-Equ Factor Movements'!J12 -> 2148.0999 | I12: =SUM(B12:H12) -> 96485.505
A13: 45488 | B13: =(3/(1+('CurrentPor-Equ Factor Movements'!C13)/100)+103/POWER(1+('CurrentPor-Equ Factor Movements'!D13)/100,2))*100 -> 9707.5858 | C13: =(3/(1+('CurrentPor-Equ Factor Movements'!C13+'CurrentPor-Equ Factor Movements'!G13)/100)+103/POWER(1+('CurrentPor-Equ Factor Movements'!D13+'CurrentPor-Equ Factor Movements'!G13)/100,2))*100 -> 9620.3784 | D13: =(3/(1+('CurrentPor-Equ Factor Movements'!C13+'CurrentPor-Equ Factor Movements'!H13)/100)+103/POWER(1+('CurrentPor-Equ Factor Movements'!D13+'CurrentPor-Equ Factor Movements'!H13)/100,2))*100 -> 9583.1353 | E13: =(3/(1+('CurrentPor-Equ Factor Movements'!C13+'CurrentPor-Equ Factor Movements'!I13)/100)+103/POWER(1+('CurrentPor-Equ Factor Movements'!D13+'CurrentPor-Equ Factor Movements'!I13)/100,2))*100 -> 9580.0297 | F13: =Portfolio!B$5*'CurrentPor-Equ Factor Movements'!E13 -> 52143.896 | G13: =Portfolio!B$6*'CurrentPor-Equ Factor Movements'!F13 -> 3696.2945 | H13: =Portfolio!B$7*'CurrentPor-Equ Factor Movements'!J13 -> 2148.0999 | I13: =SUM(B13:H13) -> 96479.419 | J13: =I13-I3 -> -14.118258
A14: 45489 | B14: =(3/(1+('CurrentPor-Equ Factor Movements'!C14)/100)+103/POWER(1+('CurrentPor-Equ Factor Movements'!D14)/100,2))*100 -> 9707.5858 | C14: =(3/(1+('CurrentPor-Equ Factor Movements'!C14+'CurrentPor-Equ Factor Movements'!G14)/100)+103/POWER(1+('CurrentPor-Equ Factor Movements'!D14+'CurrentPor-Equ Factor Movements'!G14)/100,2))*100 -> 9616.7705 | D14: =(3/(1+('CurrentPor-Equ Factor Movements'!C14+'CurrentPor-Equ Factor Movements'!H14)/100)+103/POWER(1+('CurrentPor-Equ Factor Movements'!D14+'CurrentPor-Equ Factor Movements'!H14)/100,2))*100 -> 9608.4612 | E14: =(3/(1+('CurrentPor-Equ Factor Movements'!C14+'CurrentPor-Equ Factor Movements'!I14)/100)+103/POWER(1+('CurrentPor-Equ Factor Movements'!D14+'CurrentPor-Equ Factor Movements'!I14)/100,2))*100 -> 9580.3125 | F14: =Portfolio!B$5*'CurrentPor-Equ Factor Movements'!E14 -> 52143.896 | G14: =Portfolio!B$6*'CurrentPor-Equ Factor Movements'!F14 -> 3696.2945 | H14: =Portfolio!B$7*'CurrentPor-Equ Factor Movements'!J14 -> 2148.0999 | I14: =SUM(B14:H14) -> 96501.42 | J14: =I14-I4 -> 24.648296
A15: 45490 | B15: =(3/(1+('CurrentPor-Equ Factor Movements'!C15)/100)+103/POWER(1+('CurrentPor-Equ Factor Movements'!D15)/100,2))*100 -> 9707.5858 | C15: =(3/(1+('CurrentPor-Equ Factor Movements'!C15+'CurrentPor-Equ Factor Movements'!G15)/100)+103/POWER(1+('CurrentPor-Equ Factor Movements'!D15+'CurrentPor-Equ Factor Movements'!G15)/100,2))*100 -> 9616.7705 | D15: =(3/(1+('CurrentPor-Equ Factor Movements'!C15+'CurrentPor-Equ Factor Movements'!H15)/100)+103/POWER(1+('CurrentPor-Equ Factor Movements'!D15+'CurrentPor-Equ Factor Movements'!H15)/100,2))*100 -> 9605.532 | E15: =(3/(1+('CurrentPor-Equ Factor Movements'!C15+'CurrentPor-Equ Factor Movements'!I15)/100)+103/POWER(1+('CurrentPor-Equ Factor Movements'!D15+'CurrentPor-Equ Factor Movements'!I15)/100,2))*100 -> 9581.3179 | F15: =Portfolio!B$5*'CurrentPor-Equ Factor Movements'!E15 -> 52143.896 | G15: =Portfolio!B$6*'CurrentPor-Equ Factor Movements'!F15 -> 3696.2945 | H15: =Portfolio!B$7*'CurrentPor-Equ Factor Movements'!J15 -> 2148.0999 | I15: =SUM(B15:H15) -> 96499.496 | J15: =I15-I5 -> 4.6985703
A16: 45491 | B16: =(3/(1+('CurrentPor-Equ Factor Movements'!C16)/100)+103/POWER(1+('CurrentPor-Equ Factor Movements'!D16)/100,2))*100 -> 9707.5858 | C16: =(3/(1+('CurrentPor-Equ Factor Movements'!C16+'CurrentPor-Equ Factor Movements'!G16)/100)+103/POWER(1+('CurrentPor-Equ Factor Movements'!D16+'CurrentPor-Equ Factor Movements'!G16)/100,2))*100 -> 9618.5742 | D16: =(3/(1+('CurrentPor-Equ Factor Movements'!C16+'CurrentPor-Equ Factor Movements'!H16)/100)+103/POWER(1+('CurrentPor-Equ Factor Movements'!D16+'CurrentPor-Equ Factor Movements'!H16)/100,2))*100 -> 9595.4362 | E16: =(3/(1+('CurrentPor-Equ Factor Movements'!C16+'CurrentPor-Equ Factor Movements'!I16)/100)+103/POWER(1+('CurrentPor-Equ Factor Movements'!D16+'CurrentPor-Equ Factor Movements'!I16)/100,2))*100 -> 9583.0295 | F16: =Portfolio!B$5*'CurrentPor-Equ Factor Movements'!E16 -> 52143.896 | G16: =Portfolio!B$6*'CurrentPor-Equ Factor Movements'!F16 -> 3696.2945 | H16: =Portfolio!B$7*'CurrentPor-Equ Factor Movements'!J16 -> 2148.0999 | I16: =SUM(B16:H16) -> 96492.916 | J16: =I16-I6 -> -8.5293862
A17: 45492 | B17: =(3/(1+('CurrentPor-Equ Factor Movements'!C17)/100)+103/POWER(1+('CurrentPor-Equ Factor Movements'!D17)/100,2))*100 -> 9707.5858 | C17: =(3/(1+('CurrentPor-Equ Factor Movements'!C17+'CurrentPor-Equ Factor Movements'!G17)/100)+103/POWER(1+('CurrentPor-Equ Factor Movements'!D17+'CurrentPor-Equ Factor Movements'!G17)/100,2))*100 -> 9616.7705 | D17: =(3/(1+('CurrentPor-Equ Factor Movements'!C17+'CurrentPor-Equ Factor Movements'!H17)/100)+103/POWER(1+('CurrentPor-Equ Factor Movements'!D17+'CurrentPor-Equ Factor Movements'!H17)/100,2))*100 -> 9607.9241 | E17: =(3/(1+('CurrentPor-Equ Factor Movements'!C17+'CurrentPor-Equ Factor Movements'!I17)/100)+103/POWER(1+('CurrentPor-Equ Factor Movements'!D17+'CurrentPor-Equ Factor Movements'!I17)/100,2))*100 -> 9580.7933 | F17: =Portfolio!B$5*'CurrentPor-Equ Factor Movements'!E17 -> 52143.896 | G17: =Portfolio!B$6*'CurrentPor-Equ Factor Movements'!F17 -> 3696.2945 | H17: =Portfolio!B$7*'CurrentPor-Equ Factor Movements'!J17 -> 2148.0999 | I17: =SUM(B17:H17) -> 96501.364 | J17: =I17-I7 -> 28.867847
A18: 45495 | B18: =(3/(1+('CurrentPor-Equ Factor Movements'!C18)/100)+103/POWER(1+('CurrentPor-Equ Factor Movements'!D18)/100,2))*100 -> 9707.5858 | C18: =(3/(1+('CurrentPor-Equ Factor Movements'!C18+'CurrentPor-Equ Factor Movements'!G18)/100)+103/POWER(1+('CurrentPor-Equ Factor Movements'!D18+'CurrentPor-Equ Factor Movements'!G18)/100,2))*100 -> 9616.7705 | D18: =(3/(1+('CurrentPor-Equ Factor Movements'!C18+'CurrentPor-Equ Factor Movements'!H18)/100)+103/POWER(1+('CurrentPor-Equ Factor Movements'!D18+'CurrentPor-Equ Factor Movements'!H18)/100,2))*100 -> 9603.7417 | E18: =(3/(1+('CurrentPor-Equ Factor Movements'!C18+'CurrentPor-Equ Factor Movements'!I18)/100)+103/POWER(1+('CurrentPor-Equ Factor Movements'!D18+'CurrentPor-Equ Factor Movements'!I18)/100,2))*100 -> 9580.8468 | F18: =Portfolio!B$5*'CurrentPor-Equ Factor Movements'!E18 -> 52143.896 | G18: =Portfolio!B$6*'CurrentPor-Equ Factor Movements'!F18 -> 3696.2945 | H18: =Portfolio!B$7*'CurrentPor-Equ Factor Movements'!J18 -> 2148.0999 | I18: =SUM(B18:H18) -> 96497.235 | J18: =I18-I8 -> 25.640769
A19: 45496 | B19: =(3/(1+('CurrentPor-Equ Factor Movements'!C19)/100)+103/POWER(1+('CurrentPor-Equ Factor Movements'!D19)/100,2))*100 -> 9707.5858 | C19: =(3/(1+('CurrentPor-Equ Factor Movements'!C19+'CurrentPor-Equ Factor Movements'!G19)/100)+103/POWER(1+('CurrentPor-Equ Factor Movements'!D19+'CurrentPor-Equ Factor Movements'!G19)/100,2))*100 -> 9616.7705 | D19: =(3/(1+('CurrentPor-Equ Factor Movements'!C19+'CurrentPor-Equ Factor Movements'!H19)/100)+103/POWER(1+('CurrentPor-Equ Factor Movements'!D19+'CurrentPor-Equ Factor Movements'!H19)/100,2))*100 -> 9590.1448 | E19: =(3/(1+('CurrentPor-Equ Factor Movements'!C19+'CurrentPor-Equ Factor Movements'!I19)/100)+103/POWER(1+('CurrentPor-Equ Factor Movements'!D19+'CurrentPor-Equ Factor Movements'!I19)/100,2))*100 -> 9581.9982 | F19: =Portfolio!B$5*'CurrentPor-Equ Factor Movements'!E19 -> 52143.896 | G19: =Portfolio!B$6*'CurrentPor-Equ Factor Movements'!F19 -> 3696.2945 | H19: =Portfolio!B$7*'CurrentPor-Equ Factor Movements'!J19 -> 2148.0999 | I19: =SUM(B19:H19) -> 96484.789 | J19: =I19-I9 -> -0.18570152
A20: 45497 | B20: =(3/(1+('CurrentPor-Equ Factor Movements'!C20)/100)+103/POWER(1+('CurrentPor-Equ Factor Movements'!D20)/100,2))*100 -> 9707.5858 | C20: =(3/(1+('CurrentPor-Equ Factor Movements'!C20+'CurrentPor-Equ Factor Movements'!G20)/100)+103/POWER(1+('CurrentPor-Equ Factor Movements'!D20+'CurrentPor-Equ Factor Movements'!G20)/100,2))*100 -> 9616.7705 | D20: =(3/(1+('CurrentPor-Equ Factor Movements'!C20+'CurrentPor-Equ Factor Movements'!H20)/100)+103/POWER(1+('CurrentPor-Equ Factor Movements'!D20+'CurrentPor-Equ Factor Movements'!H20)/100,2))*100 -> 9590.0804 | E20: =(3/(1+('CurrentPor-Equ Factor Movements'!C20+'CurrentPor-Equ Factor Movements'!I20)/100)+103/POWER(1+('CurrentPor-Equ Factor Movements'!D20+'CurrentPor-Equ Factor Movements'!I20)/100,2))*100 -> 9580.9065 | F20: =Portfolio!B$5*'CurrentPor-Equ Factor Movements'!E20 -> 52143.896 | G20: =Portfolio!B$6*'CurrentPor-Equ Factor Movements'!F20 -> 3696.2945 | H20: =Portfolio!B$7*'CurrentPor-Equ Factor Movements'!J20 -> 2148.0999 | I20: =SUM(B20:H20) -> 96483.633 | J20: =I20-I10 -> -0.96654744
A21: 45498 | B21: =(3/(1+('CurrentPor-Equ Factor Movements'!C21)/100)+103/POWER(1+('CurrentPor-Equ Factor Movements'!D21)/100,2))*100 -> 9707.5858 | C21: =(3/(1+('CurrentPor-Equ Factor Movements'!C21+'CurrentPor-Equ Factor Movements'!G21)/100)+103/POWER(1+('CurrentPor-Equ Factor Movements'!D21+'CurrentPor-Equ Factor Movements'!G21)/100,2))*100 -> 9614.9674 | D21: =(3/(1+('CurrentPor-Equ Factor Movements'!C21+'CurrentPor-Equ Factor Movements'!H21)/100)+103/POWER(1+('CurrentPor-Equ Factor Movements'!D21+'CurrentPor-Equ Factor Movements'!H21)/100,2))*100 -> 9601.3477 | E21: =(3/(1+('CurrentPor-Equ Factor Movements'!C21+'CurrentPor-Equ Factor Movements'!I21)/100)+103/POWER(1+('CurrentPor-Equ Factor Movements'!D21+'CurrentPor-Equ Factor Movements'!I21)/100,2))*100 -> 9582.6411 | F21: =Portfolio!B$5*'CurrentPor-Equ Factor Movements'!E21 -> 52143.896 | G21: =Portfolio!B$6*'CurrentPor-Equ Factor Movements'!F21 -> 3696.2945 | H21: =Portfolio!B$7*'CurrentPor-Equ Factor Movements'!J21 -> 2148.0999 | I21: =SUM(B21:H21) -> 96494.832 | J21: =I21-I11 -> 9.1341899
A22: 45499 | B22: =(3/(1+('CurrentPor-Equ Factor Movements'!C22)/100)+103/POWER(1+('CurrentPor-Equ Factor Movements'!D22)/100,2))*100 -> 9707.5858 | C22: =(3/(1+('CurrentPor-Equ Factor Movements'!C22+'CurrentPor-Equ Factor Movements'!G22)/100)+103/POWER(1+('CurrentPor-Equ Factor Movements'!D22+'CurrentPor-Equ Factor Movements'!G22)/100,2))*100 -> 9616.7705 | D22: =(3/(1+('CurrentPor-Equ Factor Movements'!C22+'CurrentPor-Equ Factor Movements'!H22)/100)+103/POWER(1+('CurrentPor-Equ Factor Movements'!D22+'CurrentPor-Equ Factor Movements'!H22)/100,2))*100 -> 9591.6422 | E22: =(3/(1+('CurrentPor-Equ Factor Movements'!C22+'CurrentPor-Equ Factor Movements'!I22)/100)+103/POWER(1+('CurrentPor-Equ Factor Movements'!D22+'CurrentPor-Equ Factor Movements'!I22)/100,2))*100 -> 9581.4673 | F22: =Portfolio!B$5*'CurrentPor-Equ Factor Movements'!E22 -> 52143.896 | G22: =Portfolio!B$6*'CurrentPor-Equ Factor Movements'!F22 -> 3696.2945 | H22: =Portfolio!B$7*'CurrentPor-Equ Factor Movements'!J22 -> 2148.0999 | I22: =SUM(B22:H22) -> 96485.756 | J22: =I22-I12 -> 0.25100895
A23: 45502 | B23: =(3/(1+('CurrentPor-Equ Factor Movements'!C23)/100)+103/POWER(1+('CurrentPor-Equ Factor Movements'!D23)/100,2))*100 -> 9707.5858 | C23: =(3/(1+('CurrentPor-Equ Factor Movements'!C23+'CurrentPor-Equ Factor Movements'!G23)/100)+103/POWER(1+('CurrentPor-Equ Factor Movements'!D23+'CurrentPor-Equ Factor Movements'!G23)/100,2))*100 -> 9622.1831 | D23: =(3/(1+('CurrentPor-Equ Factor Movements'!C23+'CurrentPor-Equ Factor Movements'!H23)/100)+103/POWER(1+('CurrentPor-Equ Factor Movements'!D23+'CurrentPor-Equ Factor Movements'!H23)/100,2))*100 -> 9612.9614 | E23: =(3/(1+('CurrentPor-Equ Factor Movements'!C23+'CurrentPor-Equ Factor Movements'!I23)/100)+103/POWER(1+('CurrentPor-Equ Factor Movements'!D23+'CurrentPor-Equ Factor Movements'!I23)/100,2))*100 -> 9580.3092 | F23: =Portfolio!B$5*'CurrentPor-Equ Factor Movements'!E23 -> 52143.896 | G23: =Portfolio!B$6*'CurrentPor-Equ Factor Movements'!F23 -> 3696.2945 | H23: =Portfolio!B$7*'CurrentPor-Equ Factor Movements'!J23 -> 2148.0999 | I23: =SUM(B23:H23) -> 96511.329 | J23: =I23-I13 -> 31.910298
A24: 45503 | B24: =(3/(1+('CurrentPor-Equ Factor Movements'!C24)/100)+103/POWER(1+('CurrentPor-Equ Factor Movements'!D24)/100,2))*100 -> 9707.5858 | C24: =(3/(1+('CurrentPor-Equ Factor Movements'!C24+'CurrentPor-Equ Factor Movements'!G24)/100)+103/POWER(1+('CurrentPor-Equ Factor Movements'!D24+'CurrentPor-Equ Factor Movements'!G24)/100,2))*100 -> 9622.1831 | D24: =(3/(1+('CurrentPor-Equ Factor Movements'!C24+'CurrentPor-Equ Factor Movements'!H24)/100)+103/POWER(1+('CurrentPor-Equ Factor Movements'!D24+'CurrentPor-Equ Factor Movements'!H24)/100,2))*100 -> 9604.3101 | E24: =(3/(1+('CurrentPor-Equ Factor Movements'!C24+'CurrentPor-Equ Factor Movements'!I24)/100)+103/POWER(1+('CurrentPor-Equ Factor Movements'!D24+'CurrentPor-Equ Factor Movements'!I24)/100,2))*100 -> 9580.4201 | F24: =Portfolio!B$5*'CurrentPor-Equ Factor Movements'!E24 -> 52143.896 | G24: =Portfolio!B$6*'CurrentPor-Equ Factor Movements'!F24 -> 3696.2945 | H24: =Portfolio!B$7*'CurrentPor-Equ Factor Movements'!J24 -> 2148.0999 | I24: =SUM(B24:H24) -> 96502.789 | J24: =I24-I14 -> 1.3689954
... A263: 45838 | B263: =(3/(1+('CurrentPor-Equ Factor Movements'!C263)/100)+103/POWER(1+('CurrentPor-Equ Factor Movements'!D263)/100,2))*100 -> 9707.5858 | C263: =(3/(1+('CurrentPor-Equ Factor Movements'!C263+'CurrentPor-Equ Factor Movements'!G263)/100)+103/POWER(1+('CurrentPor-Equ Factor Movements'!D263+'CurrentPor-Equ Factor Movements'!G263)/100,2))*100 -> 9663.4973 | D263: =(3/(1+('CurrentPor-Equ Factor Movements'!C263+'CurrentPor-Equ Factor Movements'!H263)/100)+103/POWER(1+('CurrentPor-Equ Factor Movements'!D263+'CurrentPor-Equ Factor Movements'!H263)/100,2))*100 -> 9604.1572 | E263: =(3/(1+('CurrentPor-Equ Factor Movements'!C263+'CurrentPor-Equ Factor Movements'!I263)/100)+103/POWER(1+('CurrentPor-Equ Factor Movements'!D263+'CurrentPor-Equ Factor Movements'!I263)/100,2))*100 -> 9579.3317 | F263: =Portfolio!B$5*'CurrentPor-Equ Factor Movements'!E263 -> 52143.896 | G263: =Portfolio!B$6*'CurrentPor-Equ Factor Movements'!F263 -> 3696.2945 | H263: =Portfolio!B$7*'CurrentPor-Equ Factor Movements'!J263 -> 2148.0999 | I263: =SUM(B263:H263) -> 96542.862 | J263: =I263-I253 -> 34.003815

Sheet ES, Credit LH=10Unchanged
B1: LH=10 | C1: LH=10, 20 | D1: LH=10, 40 | E1: LH=10, 60 | F1: LH=10 | G1: LH=10 | H1: LH=20
B2: Treasury Bonds IG valuation | C2: Credit spread: Sovereign Bonds IG valuation | D2: Credit spread: sovereign (high yield, or HY) | E2: Credit Spread:Corporate HY | F2: MSFT | G2: Intel | H2: carbon credits | I2: Portfolio value | J2: 10 day PnL | K2: VaR | L2: ES, Q(pi,1)
A3: 45474 | B3: =(3/(1+('CurrentPor-LH=10 unchanged'!C3)/100)+103/POWER(1+('CurrentPor-LH=10 unchanged'!D3)/100,2))*100 -> 9707.5858 | C3: =(3/(1+('CurrentPor-LH=10 unchanged'!C3+'CurrentPor-LH=10 unchanged'!G3)/100)+103/POWER(1+('CurrentPor-LH=10 unchanged'!D3+'CurrentPor-LH=10 unchanged'!G3)/100,2))*100 -> 9614.9674 | D3: =(3/(1+('CurrentPor-LH=10 unchanged'!C3+'CurrentPor-LH=10 unchanged'!H3)/100)+103/POWER(1+('CurrentPor-LH=10 unchanged'!D3+'CurrentPor-LH=10 unchanged'!H3)/100,2))*100 -> 9601.2396 | E3: =(3/(1+('CurrentPor-LH=10 unchanged'!C3+'CurrentPor-LH=10 unchanged'!I3)/100)+103/POWER(1+('CurrentPor-LH=10 unchanged'!D3+'CurrentPor-LH=10 unchanged'!I3)/100,2))*100 -> 9581.4547 | F3: =Portfolio!B$5*'CurrentPor-LH=10 unchanged'!E3 -> 52143.896 | G3: =Portfolio!B$6*'CurrentPor-LH=10 unchanged'!F3 -> 3696.2945 | H3: =Portfolio!B$7*'CurrentPor-LH=10 unchanged'!J3 -> 2148.0999 | I3: =SUM(B3:H3) -> 96493.537 | K3: =_xlfn.PERCENTILE.INC(J13:J263, 0.025) -> -30.682238 | L3: =AVERAGEIF(J13:J263, "<="&K3,J13:J263) -> -32.825414
A4: 45475 | B4: =(3/(1+('CurrentPor-LH=10 unchanged'!C4)/100)+103/POWER(1+('CurrentPor-LH=10 unchanged'!D4)/100,2))*100 -> 9707.5858 | C4: =(3/(1+('CurrentPor-LH=10 unchanged'!C4+'CurrentPor-LH=10 unchanged'!G4)/100)+103/POWER(1+('CurrentPor-LH=10 unchanged'!D4+'CurrentPor-LH=10 unchanged'!G4)/100,2))*100 -> 9614.9674 | D4: =(3/(1+('CurrentPor-LH=10 unchanged'!C4+'CurrentPor-LH=10 unchanged'!H4)/100)+103/POWER(1+('CurrentPor-LH=10 unchanged'!D4+'CurrentPor-LH=10 unchanged'!H4)/100,2))*100 -> 9586.7536 | E4: =(3/(1+('CurrentPor-LH=10 unchanged'!C4+'CurrentPor-LH=10 unchanged'!I4)/100)+103/POWER(1+('CurrentPor-LH=10 unchanged'!D4+'CurrentPor-LH=10 unchanged'!I4)/100,2))*100 -> 9579.175 | F4: =Portfolio!B$5*'CurrentPor-LH=10 unchanged'!E4 -> 52143.896 | G4: =Portfolio!B$6*'CurrentPor-LH=10 unchanged'!F4 -> 3696.2945 | H4: =Portfolio!B$7*'CurrentPor-LH=10 unchanged'!J4 -> 2148.0999 | I4: =SUM(B4:H4) -> 96476.772
A5: 45476 | B5: =(3/(1+('CurrentPor-LH=10 unchanged'!C5)/100)+103/POWER(1+('CurrentPor-LH=10 unchanged'!D5)/100,2))*100 -> 9707.5858 | C5: =(3/(1+('CurrentPor-LH=10 unchanged'!C5+'CurrentPor-LH=10 unchanged'!G5)/100)+103/POWER(1+('CurrentPor-LH=10 unchanged'!D5+'CurrentPor-LH=10 unchanged'!G5)/100,2))*100 -> 9614.9674 | D5: =(3/(1+('CurrentPor-LH=10 unchanged'!C5+'CurrentPor-LH=10 unchanged'!H5)/100)+103/POWER(1+('CurrentPor-LH=10 unchanged'!D5+'CurrentPor-LH=10 unchanged'!H5)/100,2))*100 -> 9603.463 | E5: =(3/(1+('CurrentPor-LH=10 unchanged'!C5+'CurrentPor-LH=10 unchanged'!I5)/100)+103/POWER(1+('CurrentPor-LH=10 unchanged'!D5+'CurrentPor-LH=10 unchanged'!I5)/100,2))*100 -> 9580.4916 | F5: =Portfolio!B$5*'CurrentPor-LH=10 unchanged'!E5 -> 52143.896 | G5: =Portfolio!B$6*'CurrentPor-LH=10 unchanged'!F5 -> 3696.2945 | H5: =Portfolio!B$7*'CurrentPor-LH=10 unchanged'!J5 -> 2148.0999 | I5: =SUM(B5:H5) -> 96494.798
A6: 45477 | B6: =(3/(1+('CurrentPor-LH=10 unchanged'!C6)/100)+103/POWER(1+('CurrentPor-LH=10 unchanged'!D6)/100,2))*100 -> 9707.5858 | C6: =(3/(1+('CurrentPor-LH=10 unchanged'!C6+'CurrentPor-LH=10 unchanged'!G6)/100)+103/POWER(1+('CurrentPor-LH=10 unchanged'!D6+'CurrentPor-LH=10 unchanged'!G6)/100,2))*100 -> 9614.9674 | D6: =(3/(1+('CurrentPor-LH=10 unchanged'!C6+'CurrentPor-LH=10 unchanged'!H6)/100)+103/POWER(1+('CurrentPor-LH=10 unchanged'!D6+'CurrentPor-LH=10 unchanged'!H6)/100,2))*100 -> 9607.0115 | E6: =(3/(1+('CurrentPor-LH=10 unchanged'!C6+'CurrentPor-LH=10 unchanged'!I6)/100)+103/POWER(1+('CurrentPor-LH=10 unchanged'!D6+'CurrentPor-LH=10 unchanged'!I6)/100,2))*100 -> 9583.5905 | F6: =Portfolio!B$5*'CurrentPor-LH=10 unchanged'!E6 -> 52143.896 | G6: =Portfolio!B$6*'CurrentPor-LH=10 unchanged'!F6 -> 3696.2945 | H6: =Portfolio!B$7*'CurrentPor-LH=10 unchanged'!J6 -> 2148.0999 | I6: =SUM(B6:H6) -> 96501.445
A7: 45478 | B7: =(3/(1+('CurrentPor-LH=10 unchanged'!C7)/100)+103/POWER(1+('CurrentPor-LH=10 unchanged'!D7)/100,2))*100 -> 9707.5858 | C7: =(3/(1+('CurrentPor-LH=10 unchanged'!C7+'CurrentPor-LH=10 unchanged'!G7)/100)+103/POWER(1+('CurrentPor-LH=10 unchanged'!D7+'CurrentPor-LH=10 unchanged'!G7)/100,2))*100 -> 9616.7705 | D7: =(3/(1+('CurrentPor-LH=10 unchanged'!C7+'CurrentPor-LH=10 unchanged'!H7)/100)+103/POWER(1+('CurrentPor-LH=10 unchanged'!D7+'CurrentPor-LH=10 unchanged'!H7)/100,2))*100 -> 9580.3056 | E7: =(3/(1+('CurrentPor-LH=10 unchanged'!C7+'CurrentPor-LH=10 unchanged'!I7)/100)+103/POWER(1+('CurrentPor-LH=10 unchanged'!D7+'CurrentPor-LH=10 unchanged'!I7)/100,2))*100 -> 9579.5439 | F7: =Portfolio!B$5*'CurrentPor-LH=10 unchanged'!E7 -> 52143.896 | G7: =Portfolio!B$6*'CurrentPor-LH=10 unchanged'!F7 -> 3696.2945 | H7: =Portfolio!B$7*'CurrentPor-LH=10 unchanged'!J7 -> 2148.0999 | I7: =SUM(B7:H7) -> 96472.496
A8: 45481 | B8: =(3/(1+('CurrentPor-LH=10 unchanged'!C8)/100)+103/POWER(1+('CurrentPor-LH=10 unchanged'!D8)/100,2))*100 -> 9707.5858 | C8: =(3/(1+('CurrentPor-LH=10 unchanged'!C8+'CurrentPor-LH=10 unchanged'!G8)/100)+103/POWER(1+('CurrentPor-LH=10 unchanged'!D8+'CurrentPor-LH=10 unchanged'!G8)/100,2))*100 -> 9613.1647 | D8: =(3/(1+('CurrentPor-LH=10 unchanged'!C8+'CurrentPor-LH=10 unchanged'!H8)/100)+103/POWER(1+('CurrentPor-LH=10 unchanged'!D8+'CurrentPor-LH=10 unchanged'!H8)/100,2))*100 -> 9582.0864 | E8: =(3/(1+('CurrentPor-LH=10 unchanged'!C8+'CurrentPor-LH=10 unchanged'!I8)/100)+103/POWER(1+('CurrentPor-LH=10 unchanged'!D8+'CurrentPor-LH=10 unchanged'!I8)/100,2))*100 -> 9580.4672 | F8: =Portfolio!B$5*'CurrentPor-LH=10 unchanged'!E8 -> 52143.896 | G8: =Portfolio!B$6*'CurrentPor-LH=10 unchanged'!F8 -> 3696.2945 | H8: =Portfolio!B$7*'CurrentPor-LH=10 unchanged'!J8 -> 2148.0999 | I8: =SUM(B8:H8) -> 96471.594
A9: 45482 | B9: =(3/(1+('CurrentPor-LH=10 unchanged'!C9)/100)+103/POWER(1+('CurrentPor-LH=10 unchanged'!D9)/100,2))*100 -> 9707.5858 | C9: =(3/(1+('CurrentPor-LH=10 unchanged'!C9+'CurrentPor-LH=10 unchanged'!G9)/100)+103/POWER(1+('CurrentPor-LH=10 unchanged'!D9+'CurrentPor-LH=10 unchanged'!G9)/100,2))*100 -> 9613.1647 | D9: =(3/(1+('CurrentPor-LH=10 unchanged'!C9+'CurrentPor-LH=10 unchanged'!H9)/100)+103/POWER(1+('CurrentPor-LH=10 unchanged'!D9+'CurrentPor-LH=10 unchanged'!H9)/100,2))*100 -> 9594.9699 | E9: =(3/(1+('CurrentPor-LH=10 unchanged'!C9+'CurrentPor-LH=10 unchanged'!I9)/100)+103/POWER(1+('CurrentPor-LH=10 unchanged'!D9+'CurrentPor-LH=10 unchanged'!I9)/100,2))*100 -> 9580.9646 | F9: =Portfolio!B$5*'CurrentPor-LH=10 unchanged'!E9 -> 52143.896 | G9: =Portfolio!B$6*'CurrentPor-LH=10 unchanged'!F9 -> 3696.2945 | H9: =Portfolio!B$7*'CurrentPor-LH=10 unchanged'!J9 -> 2148.0999 | I9: =SUM(B9:H9) -> 96484.975
A10: 45483 | B10: =(3/(1+('CurrentPor-LH=10 unchanged'!C10)/100)+103/POWER(1+('CurrentPor-LH=10 unchanged'!D10)/100,2))*100 -> 9707.5858 | C10: =(3/(1+('CurrentPor-LH=10 unchanged'!C10+'CurrentPor-LH=10 unchanged'!G10)/100)+103/POWER(1+('CurrentPor-LH=10 unchanged'!D10+'CurrentPor-LH=10 unchanged'!G10)/100,2))*100 -> 9614.9674 | D10: =(3/(1+('CurrentPor-LH=10 unchanged'!C10+'CurrentPor-LH=10 unchanged'!H10)/100)+103/POWER(1+('CurrentPor-LH=10 unchanged'!D10+'CurrentPor-LH=10 unchanged'!H10)/100,2))*100 -> 9593.3699 | E10: =(3/(1+('CurrentPor-LH=10 unchanged'!C10+'CurrentPor-LH=10 unchanged'!I10)/100)+103/POWER(1+('CurrentPor-LH=10 unchanged'!D10+'CurrentPor-LH=10 unchanged'!I10)/100,2))*100 -> 9580.3866 | F10: =Portfolio!B$5*'CurrentPor-LH=10 unchanged'!E10 -> 52143.896 | G10: =Portfolio!B$6*'CurrentPor-LH=10 unchanged'!F10 -> 3696.2945 | H10: =Portfolio!B$7*'CurrentPor-LH=10 unchanged'!J10 -> 2148.0999 | I10: =SUM(B10:H10) -> 96484.6
A11: 45484 | B11: =(3/(1+('CurrentPor-LH=10 unchanged'!C11)/100)+103/POWER(1+('CurrentPor-LH=10 unchanged'!D11)/100,2))*100 -> 9707.5858 | C11: =(3/(1+('CurrentPor-LH=10 unchanged'!C11+'CurrentPor-LH=10 unchanged'!G11)/100)+103/POWER(1+('CurrentPor-LH=10 unchanged'!D11+'CurrentPor-LH=10 unchanged'!G11)/100,2))*100 -> 9614.9674 | D11: =(3/(1+('CurrentPor-LH=10 unchanged'!C11+'CurrentPor-LH=10 unchanged'!H11)/100)+103/POWER(1+('CurrentPor-LH=10 unchanged'!D11+'CurrentPor-LH=10 unchanged'!H11)/100,2))*100 -> 9596.8686 | E11: =(3/(1+('CurrentPor-LH=10 unchanged'!C11+'CurrentPor-LH=10 unchanged'!I11)/100)+103/POWER(1+('CurrentPor-LH=10 unchanged'!D11+'CurrentPor-LH=10 unchanged'!I11)/100,2))*100 -> 9577.9861 | F11: =Portfolio!B$5*'CurrentPor-LH=10 unchanged'!E11 -> 52143.896 | G11: =Portfolio!B$6*'CurrentPor-LH=10 unchanged'!F11 -> 3696.2945 | H11: =Portfolio!B$7*'CurrentPor-LH=10 unchanged'!J11 -> 2148.0999 | I11: =SUM(B11:H11) -> 96485.698
A12: 45485 | B12: =(3/(1+('CurrentPor-LH=10 unchanged'!C12)/100)+103/POWER(1+('CurrentPor-LH=10 unchanged'!D12)/100,2))*100 -> 9707.5858 | C12: =(3/(1+('CurrentPor-LH=10 unchanged'!C12+'CurrentPor-LH=10 unchanged'!G12)/100)+103/POWER(1+('CurrentPor-LH=10 unchanged'!D12+'CurrentPor-LH=10 unchanged'!G12)/100,2))*100 -> 9614.9674 | D12: =(3/(1+('CurrentPor-LH=10 unchanged'!C12+'CurrentPor-LH=10 unchanged'!H12)/100)+103/POWER(1+('CurrentPor-LH=10 unchanged'!D12+'CurrentPor-LH=10 unchanged'!H12)/100,2))*100 -> 9593.7415 | E12: =(3/(1+('CurrentPor-LH=10 unchanged'!C12+'CurrentPor-LH=10 unchanged'!I12)/100)+103/POWER(1+('CurrentPor-LH=10 unchanged'!D12+'CurrentPor-LH=10 unchanged'!I12)/100,2))*100 -> 9580.9201 | F12: =Portfolio!B$5*'CurrentPor-LH=10 unchanged'!E12 -> 52143.896 | G12: =Portfolio!B$6*'CurrentPor-LH=10 unchanged'!F12 -> 3696.2945 | H12: =Portfolio!B$7*'CurrentPor-LH=10 unchanged'!J12 -> 2148.0999 | I12: =SUM(B12:H12) -> 96485.505
A13: 45488 | B13: =(3/(1+('CurrentPor-LH=10 unchanged'!C13)/100)+103/POWER(1+('CurrentPor-LH=10 unchanged'!D13)/100,2))*100 -> 9707.5858 | C13: =(3/(1+('CurrentPor-LH=10 unchanged'!C13+'CurrentPor-LH=10 unchanged'!G13)/100)+103/POWER(1+('CurrentPor-LH=10 unchanged'!D13+'CurrentPor-LH=10 unchanged'!G13)/100,2))*100 -> 9620.3784 | D13: =(3/(1+('CurrentPor-LH=10 unchanged'!C13+'CurrentPor-LH=10 unchanged'!H13)/100)+103/POWER(1+('CurrentPor-LH=10 unchanged'!D13+'CurrentPor-LH=10 unchanged'!H13)/100,2))*100 -> 9583.1353 | E13: =(3/(1+('CurrentPor-LH=10 unchanged'!C13+'CurrentPor-LH=10 unchanged'!I13)/100)+103/POWER(1+('CurrentPor-LH=10 unchanged'!D13+'CurrentPor-LH=10 unchanged'!I13)/100,2))*100 -> 9580.0297 | F13: =Portfolio!B$5*'CurrentPor-LH=10 unchanged'!E13 -> 52143.896 | G13: =Portfolio!B$6*'CurrentPor-LH=10 unchanged'!F13 -> 3696.2945 | H13: =Portfolio!B$7*'CurrentPor-LH=10 unchanged'!J13 -> 2148.0999 | I13: =SUM(B13:H13) -> 96479.419 | J13: =I13-I3 -> -14.118258
A14: 45489 | B14: =(3/(1+('CurrentPor-LH=10 unchanged'!C14)/100)+103/POWER(1+('CurrentPor-LH=10 unchanged'!D14)/100,2))*100 -> 9707.5858 | C14: =(3/(1+('CurrentPor-LH=10 unchanged'!C14+'CurrentPor-LH=10 unchanged'!G14)/100)+103/POWER(1+('CurrentPor-LH=10 unchanged'!D14+'CurrentPor-LH=10 unchanged'!G14)/100,2))*100 -> 9616.7705 | D14: =(3/(1+('CurrentPor-LH=10 unchanged'!C14+'CurrentPor-LH=10 unchanged'!H14)/100)+103/POWER(1+('CurrentPor-LH=10 unchanged'!D14+'CurrentPor-LH=10 unchanged'!H14)/100,2))*100 -> 9608.4612 | E14: =(3/(1+('CurrentPor-LH=10 unchanged'!C14+'CurrentPor-LH=10 unchanged'!I14)/100)+103/POWER(1+('CurrentPor-LH=10 unchanged'!D14+'CurrentPor-LH=10 unchanged'!I14)/100,2))*100 -> 9580.3125 | F14: =Portfolio!B$5*'CurrentPor-LH=10 unchanged'!E14 -> 52143.896 | G14: =Portfolio!B$6*'CurrentPor-LH=10 unchanged'!F14 -> 3696.2945 | H14: =Portfolio!B$7*'CurrentPor-LH=10 unchanged'!J14 -> 2148.0999 | I14: =SUM(B14:H14) -> 96501.42 | J14: =I14-I4 -> 24.648296
A15: 45490 | B15: =(3/(1+('CurrentPor-LH=10 unchanged'!C15)/100)+103/POWER(1+('CurrentPor-LH=10 unchanged'!D15)/100,2))*100 -> 9707.5858 | C15: =(3/(1+('CurrentPor-LH=10 unchanged'!C15+'CurrentPor-LH=10 unchanged'!G15)/100)+103/POWER(1+('CurrentPor-LH=10 unchanged'!D15+'CurrentPor-LH=10 unchanged'!G15)/100,2))*100 -> 9616.7705 | D15: =(3/(1+('CurrentPor-LH=10 unchanged'!C15+'CurrentPor-LH=10 unchanged'!H15)/100)+103/POWER(1+('CurrentPor-LH=10 unchanged'!D15+'CurrentPor-LH=10 unchanged'!H15)/100,2))*100 -> 9605.532 | E15: =(3/(1+('CurrentPor-LH=10 unchanged'!C15+'CurrentPor-LH=10 unchanged'!I15)/100)+103/POWER(1+('CurrentPor-LH=10 unchanged'!D15+'CurrentPor-LH=10 unchanged'!I15)/100,2))*100 -> 9581.3179 | F15: =Portfolio!B$5*'CurrentPor-LH=10 unchanged'!E15 -> 52143.896 | G15: =Portfolio!B$6*'CurrentPor-LH=10 unchanged'!F15 -> 3696.2945 | H15: =Portfolio!B$7*'CurrentPor-LH=10 unchanged'!J15 -> 2148.0999 | I15: =SUM(B15:H15) -> 96499.496 | J15: =I15-I5 -> 4.6985703
A16: 45491 | B16: =(3/(1+('CurrentPor-LH=10 unchanged'!C16)/100)+103/POWER(1+('CurrentPor-LH=10 unchanged'!D16)/100,2))*100 -> 9707.5858 | C16: =(3/(1+('CurrentPor-LH=10 unchanged'!C16+'CurrentPor-LH=10 unchanged'!G16)/100)+103/POWER(1+('CurrentPor-LH=10 unchanged'!D16+'CurrentPor-LH=10 unchanged'!G16)/100,2))*100 -> 9618.5742 | D16: =(3/(1+('CurrentPor-LH=10 unchanged'!C16+'CurrentPor-LH=10 unchanged'!H16)/100)+103/POWER(1+('CurrentPor-LH=10 unchanged'!D16+'CurrentPor-LH=10 unchanged'!H16)/100,2))*100 -> 9595.4362 | E16: =(3/(1+('CurrentPor-LH=10 unchanged'!C16+'CurrentPor-LH=10 unchanged'!I16)/100)+103/POWER(1+('CurrentPor-LH=10 unchanged'!D16+'CurrentPor-LH=10 unchanged'!I16)/100,2))*100 -> 9583.0295 | F16: =Portfolio!B$5*'CurrentPor-LH=10 unchanged'!E16 -> 52143.896 | G16: =Portfolio!B$6*'CurrentPor-LH=10 unchanged'!F16 -> 3696.2945 | H16: =Portfolio!B$7*'CurrentPor-LH=10 unchanged'!J16 -> 2148.0999 | I16: =SUM(B16:H16) -> 96492.916 | J16: =I16-I6 -> -8.5293862
