Workbook
Name AsOf: '60_calculator'!$B$3
Name RowA_low: '20_regulatory_buckets'!$J$6:$J$14
Name RowB_low: '20_regulatory_buckets'!$K$6:$K$11
Name RowC_low: '20_regulatory_buckets'!$L$6:$L$10
Name RowD_low: '20_regulatory_buckets'!$M$6:$M$10

Sheet 00_README
A1: FRTB RFET — Bucketing Approach Reference & Live Calculator
A2: BCBS MAR31.12–31.26 — bucketing, the RFET and modellability | Generic / self-contained | reference sheets · worked examples · live calculator
A4: Purpose | B4: A 13-sheet reference and course on MAR31 risk-factor modellability: why real prices gate capital (05), the bucketing machinery (10–30), the own-vs-regulatory election and its guardrail (40–45), worked special cases (50), the quantified systematic/idio and proxy splits (55), the seven data principles (57), a LIVE calculator with verdicts (60–70), and verbatim citations (90).
A5: What the RFET is | B5: The Risk Factor Eligibility Test (MAR31.12). A necessary condition for a risk factor to be MODELLABLE (and so allowed in the Expected Shortfall capital model, MAR33). A factor that fails the RFET is a Non-Modellable Risk Factor (NMRF) and attracts a separate, punitive stressed capital add-on.
A6: Why bucketing exists | B6: Most risk factors are POINTS on a curve / surface / cube (e.g. the 5Y point of a swap curve; the 1Y-expiry / 0.50-delta point of a vol surface). Real trades rarely land exactly on a point, so MAR31.16 lets banks group observations into BUCKETS and count any trade inside a bucket toward the factor (MAR31.17). Without bucketing almost nothing would pass.
A7: Dimensional geometry | B7: Curve = 1-D (one axis, e.g. tenor). Surface = 2-D (e.g. expiry x strike). Cube = 3-D (e.g. swaption: underlying tenor x expiry x strike). 'delta' (δ) on the strike axis = the probability the option finishes in-the-money.
A8: Two bucketing approaches (MAR31.16) | B8: (1) OWN buckets — bank-defined; MUST be one risk factor per bucket, non-overlapping, and the buckets must CORRESPOND to the RTPL risk factors used for the PLA test — the requirement sits in the BODY of 31.16(1)(a); footnote 5 explains its rationale (same buckets/segmentation for PLA & RFET; granularity helps PLA but strains sourcing real prices per bucket). (2) REGULATORY buckets — the fixed standard grid (Table 1, rows A/B/C/D).
A9: The PLA linkage (why this matters) | B9: MAR31.16(1)(a) hard-wires the bucketing grid to RTPL. So the bucketing choice is simultaneously a MODELLABILITY decision (RFET) and a PnL-ATTRIBUTION decision (PLA, MAR32). Widening buckets eases the RFET but coarsens RTPL -> RTPL drifts from HPL -> the desk can fail PLA and lose IMA. Finding a grid that passes BOTH gates is the core design judgement.
A10: Authoritative source | B10: BCBS MAR31 'Internal models approach: model requirements' (in-force 01 Jan 2023). No regulatory constant in this workbook is invented — every boundary and threshold is transcribed from MAR31. See '90_citations'.
A11: Sheet guide | B11: REFERENCE — 10_decision_map · 20_regulatory_buckets · 30_instrument_coverage · 90_citations | NARRATIVE — 05_why_real_prices · 40_own_vs_regulatory · 45_guardrail | WORKED EXAMPLES — 50_special_cases · 55_systematic_proxy_nmrf · 57_seven_principles | LIVE — 60_calculator → 70_rfet_results
A12: How to use the calculator | B12: Go to 60_calculator. Each row = one real-price observation. Fill the WHITE input cells (date, class, flags, dimension values, real-price criterion). The GREY cells derive automatically (row, bucket index, risk-factor key). Then read 70_rfet_results for the pass/fail and modellable/NMRF verdict per risk factor.
A13: Working vocabulary | B13: prints = real-price observations (trades / committed quotes, 31.12) · pillar = an evidenced curve point kept as a risk factor · drought = the longest observation gap incl. window edges (70) · election = the per-object own-vs-regulatory choice (40) · register = the policy appendix recording every election (40) · no-man's-land = tenor space where no model factor lives (40, route 4) · free lunch = a wide self-defined bucket over fine RTPL — forbidden (45) · the rent = the seven ongoing data principles (57)
A14: Reading order | B14: LEARN: 05 → 10 → 20 → 30 → 40 → 45 → 50 → 55 → 57. USE: 60 → 70 (set the as-of date, paste observations, read verdicts). VERIFY: 90. The companion deck's five sessions follow the same arc.

Sheet 05_why_real_prices
A1: Why Real Prices? — the philosophy of the RFET, and the life of a price after the pass
A2: Why the framework fixates on price availability when an army of quants can generate a PnL series for anything (the moon swap included) — and why the prices are never thrown away after the pass. Anchors: 31.12–31.15, 31.22–31.23, 31.25–31.26 (Principles 3–4), 31.13 (quarterly/monthly), MAR33.16–33.17.
A4: 1 · Why price availability gates capital — a generated series is not evidence
A5: The circularity problem | B5: A PnL series produced by your own interpolator has volatility = your smoothing assumption and correlation = your interpolation weights. Feed it to ES and the ES measures the risk OF YOUR INTERPOLATOR — the model validates itself on data it manufactured. A real price is the only exogenous number in the loop, the only input able to prove the model wrong. (That is why 31.12 excludes the bank's own valuations and collateral reconciliations BY NAME: they are model output, not market evidence.)
A6: The smooth-series pathology | B6: Interpolated marks are smooth and over-correlated. XYZ 7Y CDS marked daily by 5Y–10Y interpolation shows low σ and ρ ≈ 1 with the 5Y → ES sees a calm, hedged book. On the twist day the real 7Y prints +8bp while the interpolated series moves +2.4bp: the generated-series machine would have capitalised about a THIRD of the real risk AND manufactured a diversification benefit that never existed. 2008's super-senior and correlation books were this pathology at scale — immaculate marked-to-model PnL, tiny VaR, no exit price. Principle 3 ('do not understate volatility… by inappropriate averaging or proxies') is its statutory memory.
A7: Coordinates ≠ dynamics | B7: Knowing that the point EXISTS — (3M, 4Y, ATM), or the moon swap — is not knowing its DYNAMICS. The RFET operationalises one question: does the market regularly emit independent information about this point (≥24 prints/yr, 90-day density)? A series without that anchor has a generator but no way to be wrong — and a capital model must be falsifiable by the market it claims to measure.
A8: What the rule does NOT do | B8: Failing the RFET does not ban the model. The NMRF stays in desk risk management, stays in RTPL (which is computed with ALL risk factors, NMRFs included), and its series drives the SES scenario construction. Price availability gates something narrower: THE CAPITAL CREDIT FOR THE MODEL'S STATISTICS. Modellable → evidenced vols/correlations earn full ES treatment (netting, diversification, 97.5% point-in-time). NMRF → stress-calibrated capital with severely restricted diversification (33.16–33.17). Unverifiable statistics are not allowed to REDUCE capital — that is the entire rule.
A9: The two gates | B9: If generated series earned full ES treatment, the incentive gradient points one way: series would be built smooth, mean-reverting and hedge-correlated, because that minimises capital. Backtesting and PLA cannot catch it — HPL is built from front-office MARKS, and for an illiquid point the marks come from the same interpolator: model vs model, everything green. PLA tests INTERNAL consistency (model vs marks); the RFET is the only gate in the framework testing EXTERNAL validity (marks vs market). Remove the second gate and the first one tests nothing.
A11: 2 · After the pass — the prices are never thrown away (GATE → POLICE → EVIDENCE; calibration is the only job they lose)
A12: GATE — rolling, not one-shot | B12: 31.13: the criteria must be met on a QUARTERLY basis and criterion (1) monitored MONTHLY, on a rolling 12-month window. Modellability is never 'established' — it is re-earned every quarter; a factor that goes quiet flips to NMRF the next quarter, capital consequences following automatically. (60_calculator / 70_rfet_results mimic exactly this production process via the As-of date.)
A13: POLICE — the mandated recon (Principle 4) | B13: 31.26(4), near-verbatim: 'the bank must periodically reconcile price data used in a risk model with front office and back office prices… risk model prices should be included in the comparison… comparisons of risk prices with REAL PRICE OBSERVATIONS' (FO/BO prices only where real prices are not widely available). Principle 3 adds: data sources must yield vols and correlations that are 'reasonable approximations of correlations among real price observations'. Enforcement: 31.23 — principles unmet ⇒ the supervisor pulls the factor from ES → NMRF, DESPITE the RFET pass. The RFET is the entry ticket; the principles are the rent.
A14: EVIDENCE — retrievable on demand | B14: 31.14: the vendor must provide evidence of the transaction or committed quote to supervisors ON REQUEST, and remain subject to an audit whose results are available to the supervisor; 31.15: documented price→risk-factor mapping policies. The modellability claim must be reproducible quarters later — the observation archive is part of the model's audit trail.
A15: CALIBRATE — the one job they lose | B15: 31.22: once a factor passes, the ES model may be CALIBRATED on different, richer data — vendor series, consensus marks — chosen for quality (31.23/31.25 still apply). Real prices GATE, POLICE and EVIDENCE; they need not be the calibration input. It is a division of labour, not a retirement.

Sheet 10_decision_map
A1: MAR31.16(2)(a)–(f) — Decision Map: which bucket row applies
A2: Given a risk factor's object type and axes, which standard rows (A/B/C/D) bucket each dimension.
A4: # | B4: Risk-factor type / object | C4: Object | D4: Dimension(s) | E4: Maturity/expiry row | F4: Strike row | G4: MAR31.16(2) ref
A5: a | B5: IR / FX / commodity — single maturity dimension (excl. vol) | C5: Curve | D5: maturity | E5: A | F5: — | G5: (a)
A6: b | B6: IR / FX / commodity — several maturity dimensions (excl. vol) | C6: Curve/Surface | D6: maturity (multi) | E6: B | F6: — | G6: (b)
A7: c | B7: Credit spread & equity — one or several maturity dims (excl. vol) | C7: Curve/Surface | D7: maturity | E7: C | F7: — | G7: (c)
A8: d | B8: Any object with a strike dimension | C8: Surface/Cube | D8: strike (delta) | E8: — | F8: D | G8: (d)
A9: e | B9: Implied vol (NON-swaption) — expiry & strike | C9: Surface | D9: expiry; strike | E9: C (expiry) | F9: D (strike) | G9: (e)
A10: f | B10: Implied vol — INTEREST-RATE SWAPTION — maturity, expiry, strike | C10: Cube | D10: underlying tenor; expiry; strike | E10: B (tenor) + C (expiry) | F10: D (strike) | G10: (f)
A12: Note: a swaption implied-vol point is a CUBE — three dimensions bucketed simultaneously (B × C × D). A non-swaption vol point is a SURFACE (C × D). A cash/linear instrument is a CURVE (one of A/B/C).
A14: Row A vs Row B — how to count maturity dimensions
A15: The choice is NOT about the instrument type (swap vs bond vs spot vs forward). It is about how many TIME/MATURITY axes are needed to locate ONE risk factor. Row A = a single time coordinate, factor(t), a point on a 1-D curve. Row B = two or more time coordinates at once, factor(t1, t2), a point on a time×time surface. 'Several maturity dimensions' typically means forward / forward-starting / tenor-by-tenor representations.
A16: Instrument / risk factor | C16: # time axes | D16: Example contract | F16: Row | G16: Locate by
A17: FX spot | C17: 0 | D17: EUR/USD spot rate | F17: — | G17: spot (no maturity)
A18: Vanilla IR swap (curve point) | C18: 1 | D18: 5Y EUR payer IRS vs 6M Euribor | F18: A | G18: one tenor (5Y)
A19: Bond (yield-curve point) | C19: 1 | D19: Bund 0.0% 2030 | F19: A | G19: one tenor
A20: FX outright forward | C20: 1 | D20: EUR/USD 1Y outright forward | F20: A | G20: one maturity
A21: Commodity future (single delivery) | C21: 1 | D21: NYMEX WTI Dec-26 future | F21: A | G21: one delivery date
A22: Constant-maturity swap (CMS) — tenor PINNED | C22: 1 | D22: EUR CMS: pay the 10Y swap rate, reset yearly for 5y | F22: A | G22: start only — 10Y tenor is constant -> categorical, not bucketed
A23: Forward-starting swap | C23: 2 | D23: EUR 2y-into-5y forward payer swap (starts in 2y, runs 5y) | F23: B | G23: start + tenor (book spans a range of BOTH)
A24: Forward-rate surface (model object) | C24: 2 | D24: grid of f(start, tenor) forward rates in the model | F24: B | G24: start + tenor
A25: Swaption underlying-maturity axis | C25: of 3 | D25: EUR 2y-into-10y payer swaption | F25: B | G25: expiry + u-tenor + strike
A27: Counting maturity dimensions = how many time axes the model keeps LIVE (varying across the book) for that risk factor. An axis held CONSTANT by the product is categorical, not bucketed, so it does NOT count. Hence a CMS (underlying tenor PINNED at 10Y) is single-dimension -> Row A, even though two times appear; only the start varies. By contrast a book of FORWARD-STARTING swaps spans a range of starts AND tenors, so both axes are live -> Row B. (Likewise a tenor-BASIS factor, 3M vs 6M Euribor, is one maturity axis + a categorical index pair -> Row A.) Caveat: MAR31.16(2)(b) names no instruments; this is the standard reading. The black-letter rule is purely single vs several LIVE time axes.

Sheet 20_regulatory_buckets
A1: MAR31.16(2) — Regulatory Bucketing Grid (Table 1)
A2: Standard buckets. Boundaries transcribed verbatim from MAR31 Table 1. t in years; δ = delta (prob. ITM).
A4: Row | B4: Dimension | C4: Typical application | D4: Bucket # | E4: Lower | F4: Upper (excl.) | G4: Band | I4: Lookup lists (used by the live calculator — do not edit)
A5: A | B5: Maturity — single maturity dimension | C5: IR, FX, commodity (excl. implied vol) | D5: 1 | E5: 0 | F5: 0.75 | G5: 0 ≤ t < 0.75 | J5: RowA_low | K5: RowB_low | L5: RowC_low | M5: RowD_low
D6: 2 | E6: 0.75 | F6: 1.5 | G6: 0.75 ≤ t < 1.5 | J6: 0 | K6: 0 | L6: 0 | M6: 0
D7: 3 | E7: 1.5 | F7: 4 | G7: 1.5 ≤ t < 4 | J7: 0.75 | K7: 0.75 | L7: 1.5 | M7: 0.05
D8: 4 | E8: 4 | F8: 7 | G8: 4 ≤ t < 7 | J8: 1.5 | K8: 4 | L8: 3.5 | M8: 0.3
D9: 5 | E9: 7 | F9: 12 | G9: 7 ≤ t < 12 | J9: 4 | K9: 10 | L9: 7.5 | M9: 0.7
D10: 6 | E10: 12 | F10: 18 | G10: 12 ≤ t < 18 | J10: 7 | K10: 18 | L10: 15 | M10: 0.95
D11: 7 | E11: 18 | F11: 25 | G11: 18 ≤ t < 25 | J11: 12 | K11: 30
D12: 8 | E12: 25 | F12: 35 | G12: 25 ≤ t < 35 | J12: 18
D13: 9 | E13: 35 | F13: ∞ | G13: 35 ≤ t < ∞ | J13: 25
J14: 35
A15: B | B15: Maturity — several maturity dimensions | C15: IR/FX/commodity; swaption underlying maturity axis | D15: 1 | E15: 0 | F15: 0.75 | G15: 0 ≤ t < 0.75
D16: 2 | E16: 0.75 | F16: 4 | G16: 0.75 ≤ t < 4
D17: 3 | E17: 4 | F17: 10 | G17: 4 ≤ t < 10
D18: 4 | E18: 10 | F18: 18 | G18: 10 ≤ t < 18
D19: 5 | E19: 18 | F19: 30 | G19: 18 ≤ t < 30
D20: 6 | E20: 30 | F20: ∞ | G20: 30 ≤ t < ∞
A22: C | B22: Maturity / expiry | C22: Credit spread & equity maturity; implied-vol expiry (incl. swaption expiry) | D22: 1 | E22: 0 | F22: 1.5 | G22: 0 ≤ t < 1.5
D23: 2 | E23: 1.5 | F23: 3.5 | G23: 1.5 ≤ t < 3.5
D24: 3 | E24: 3.5 | F24: 7.5 | G24: 3.5 ≤ t < 7.5
D25: 4 | E25: 7.5 | F25: 15 | G25: 7.5 ≤ t < 15
D26: 5 | E26: 15 | F26: ∞ | G26: 15 ≤ t < ∞
A28: D | B28: Strike — by delta (δ) | C28: Any strike dimension of an implied-vol object | D28: 1 | E28: 0 | F28: 0.05 | G28: 0 ≤ δ < 0.05
D29: 2 | E29: 0.05 | F29: 0.3 | G29: 0.05 ≤ δ < 0.3
D30: 3 | E30: 0.3 | F30: 0.7 | G30: 0.3 ≤ δ < 0.7
D31: 4 | E31: 0.7 | F31: 0.95 | G31: 0.7 ≤ δ < 0.95
D32: 5 | E32: 0.95 | F32: 1 | G32: 0.95 ≤ δ < 1
A34: Footnote 6 to 31.16(2)(d) — delta conventions: for options markets where alternative definitions of moneyness are standard (e.g. FX quoted as 25Δ risk reversals, equity as %-moneyness), banks SHALL convert the regulatory delta buckets to the market-standard convention using their own approved pricing models. Row D is defined on δ = probability of finishing in-the-money; a market quote only lands in a D-band after that conversion.

Sheet 30_instrument_coverage
A1: Holistic Instrument / Risk-Factor Coverage Matrix
A2: Every instrument family in MAR31.16 mapped to object type, axes, applicable rows and example risk-factor points.
A4: Risk class | B4: Example instrument | C4: Sample contract | D4: Object | E4: Axis → bucket row | F4: Example risk-factor point | G4: RFET counted via
A5: Interest rate | B5: Vanilla IR swap / bond | C5: 5Y EUR payer IRS, €100m, fixed vs 6M Euribor (or Bund 0.0% 2030) | D5: Curve | E5: maturity → A | F5: 5Y point of EUR swap curve | G5: trade counts if maturity ∈ 4–7y (A, bucket 4)
A6: Interest rate | B6: Forward-starting / tenor-by-tenor swap (several maturity dims) | C6: EUR 2Y-into-5Y forward-starting payer swap, €50m | D6: Surface | E6: maturity → B | F6: forward(start 2Y, tenor 5Y) point | G6: trade counts if start ∈ 0.75–4y AND tenor ∈ 4–10y (B×B cell)
A7: Interest rate | B7: Cap/floor implied vol (non-swaption) | C7: EUR 1Y cap, 3.0% strike on 3M Euribor | D7: Surface | E7: expiry → C ; strike → D | F7: 1Y expiry, δ0.50 caplet vol | G7: vol quote counts if expiry ∈ 0–1.5y AND δ ∈ 0.3–0.7 (C×D cell)
A8: Interest rate | B8: Swaption implied vol | C8: EUR 2Y-into-10Y ATM payer swaption | D8: Cube | E8: u-tenor → B ; expiry → C ; strike → D | F8: 10Y u-tenor, 2Y expiry, δ0.50 | G8: quote counts if u-tenor ∈ 10–18y AND expiry ∈ 1.5–3.5y AND δ ∈ 0.3–0.7 (B×C×D cell)
A9: FX | B9: FX forward / outright | C9: EUR/USD 1Y outright forward, €25m | D9: Curve | E9: maturity → A | F9: 1Y EURUSD forward point | G9: fwd counts if maturity ∈ 0.75–1.5y (A, bucket 2)
A10: FX | B10: FX option implied vol | C10: EUR/USD 3M 25Δ risk reversal | D10: Surface | E10: expiry → C ; strike → D | F10: 3M expiry, 25Δ (≈δ0.25) vol | G10: vol quote counts if expiry ∈ 0–1.5y AND δ ∈ 0.05–0.3 (C×D cell)
A11: Commodity | B11: Commodity future (single maturity) | C11: NYMEX WTI (CL) Dec-2026 future, 1,000 bbl | D11: Curve | E11: maturity → A | F11: 6M WTI future | G11: future counts if maturity ∈ 0–0.75y (A, bucket 1)
A12: Commodity | B12: Forward-starting commodity swap (several maturity dims) | C12: ICE Brent swap starting in 1y, 1y tenor | D12: Surface | E12: maturity → B | F12: forward(start 1y, tenor 1y) point | G12: trade counts if start ∈ 0.75–4y AND tenor ∈ 0.75–4y (B×B cell)
A13: Commodity | B13: Commodity option implied vol | C13: ICE Brent 1Y ATM option | D13: Surface | E13: expiry → C ; strike → D | F13: 1Y expiry, δ0.50 option vol | G13: vol quote counts if expiry ∈ 0–1.5y AND δ ∈ 0.3–0.7 (C×D cell)
A14: Credit spread | B14: Single-name / index CDS | C14: 5Y single-name CDS on ACME Corp, $10m (or iTraxx Europe 5Y) | D14: Curve | E14: maturity → C | F14: 7Y CDS spread point | G14: CDS counts if maturity ∈ 3.5–7.5y (C, bucket 3)
A15: Credit spread | B15: Systematic (sector/region) credit + maturity | C15: CDX IG 5Y index (sector spread curve point) | D15: Curve | E15: maturity → C (per 31.21) | F15: sector 5Y spread point | G15: index/name counts if maturity ∈ 3.5–7.5y (C, bucket 3; sharing attrs, 31.20)
... A18: Equity | B18: Systematic equity factor (market/sector) | C18: EuroStoxx 50 index future (sector beta factor) | D18: point/Curve | E18: spot (idio→NMRF); maturity → C | F18: sector beta factor | G18: index trades count for the systematic factor (sharing attrs, 31.20)
A20: How to read 'C×D' (a multi-dimensional bucket CELL)
A21: A curve point sits in ONE band on ONE axis -> a simple range like '4–7y'. A surface/cube point needs a band on EACH axis at once: 'C×D' means one band from row C (expiry/maturity) AND one band from row D (strike/δ). The risk factor's bucket is the INTERSECTION (a rectangle/box). A real-price quote counts toward that factor (MAR31.17) only if it falls inside ALL of the bands simultaneously. Example — cap vol '1Y expiry, δ0.50': expiry 1Y is in C-band 0–1.5y AND δ0.50 is in D-band 0.3–0.7, so the cell is [0–1.5y expiry] × [0.3–0.7 δ]. 'B×C×D' (swaption) is the same idea in 3 dimensions (a box: u-tenor band × expiry band × strike band). (Full 3-D walkthrough of the swaption cube — benchmark prints, wings, band boundaries — on 50_special_cases.)
A23: Exact-match (categorical) attributes — fixed BEFORE you bucket
A24: Bucketing (MAR31.16) only operates on CONTINUOUS coordinates (tenor, expiry, strike δ) where trades rarely hit a pillar exactly, so neighbours are pooled. CATEGORICAL attributes (currency, curve/index, issuer, …) are NOT bucketed — there is no 'nearby' between EUR and USD. They must match EXACTLY because they DEFINE which risk factor / which curve you are on. A USD 5Y swap rate is not a 'close point' to a EUR 5Y swap rate — it is a different risk factor. So every example in the table above implicitly assumes a single, fixed currency & underlying; you fix those first, THEN bucket along the axes. Regulatory hooks: prices must be 'representative of the risk factor' (31.13); systematic factors must 'share the same attributes' (31.20); proxies must suit 'region, quality and type' (Principle 7, 31.26).
A25: Risk class | B25: Must match EXACTLY (defines WHICH risk factor) | E25: Then BUCKET on (continuous axes)
A26: Interest rate | B26: currency; reference rate & curve (3M Euribor / 6M Euribor / OIS / IBOR) | E26: tenor (and forward start, for fwd-starting)
A27: FX | B27: currency pair | E27: maturity / expiry; δ (for options)
A28: Credit spread | B28: single-name reference entity OR credit index (e.g. iTraxx / CDX); seniority; currency; doc clause | E28: tenor
A29: Equity | B29: issuer / index; factor type (spot / repo / dividend) | E29: maturity; expiry; δ (for vol)
A30: Commodity | B30: commodity type & grade; delivery hub/location | E30: maturity; expiry; δ (for vol)
A32: Diagram — a bucket is the INTERSECTION of one band per axis (1-D band → 2-D rectangle → 3-D box)
A33: This geometry applies to BOTH bucketing approaches — it is inherent to the risk factor (31.16 chapeau) and, for OWN bucketing, forced by 31.16(1)(a) 'one risk factor per bucket' (a surface own-bucket must be bounded on EVERY axis). Only the fixed RANGES (Table 1 bands) and the (a)–(f) row assignments are regulatory-only; own bucketing keeps the same geometry and just draws its own edges.

Sheet 40_own_vs_regulatory
A1: MAR31.16(1) vs (2) — Own vs Regulatory Bucketing
A2: The two permitted approaches, their constraints, the per-object election, and the four routes for a thin tenor — in reading order: comparison → doctrine → election → anatomy → route 4 → documentation.
A4: Dimension | B4: OWN (31.16(1)) | C4: REGULATORY (31.16(2))
A5: Who defines buckets | B5: Bank (subject to constraints) | C5: BCBS fixed grid (Table 1)
A6: Risk factors per bucket | B6: EXACTLY ONE (31.16(1)(a)) | C6: MAY be SEVERAL — obs pool across all factors in the bucket (31.17)
A7: Bucket vs RTPL grid | B7: Bucket = one RTPL factor (fn 5) — the two are tied | C7: Bucket only COUNTS prices; RTPL keeps its own (finer) grid
A8: Pooling for thin tenors | B8: ACROSS TENOR SPACE only — the bucket may be drawn wide over UNCLAIMED tenors (route 4: 6Y prints feed the 7Y factor), but can never reach another FACTOR's prints (those sit in its own bucket; single count, 31.18). A thin factor with no nearby no-man's-land liquidity ⇒ NMRF | C8: ACROSS FACTORS too — a band may hold several factors and every print in it counts toward EACH (31.17): the thin 7Y borrows the 5Y pillar's own trades
A9: Effect on PLA | B9: Fine IF you keep RTPL fine (widening a bucket widens RTPL → PLA risk) | C9: None — RTPL stays fine, so PLA is unaffected
A10: Non-overlapping | B10: Required (31.16(1)(b)) | C10: Non-overlapping by construction
A11: Justification burden | B11: Must define & defend the scheme to supervisor | C11: Safe harbour — no scheme to defend
A12: Granularity / control | B12: Tune boundaries to your book & RTPL | C12: Fixed, one-size-fits-all
A13: Best for | B13: Fine control when tenors are liquid enough — or when spare liquidity sits in no-man's-land (route 4) | C13: Thin/illiquid tenors (legit pooling); fast compliance
A15: WHAT 31.16(1)(a) ACTUALLY FORBIDS: the 'free lunch' of a wide SELF-DEFINED bucket (pool trades → pass RFET) sitting over a FINE RTPL (pass PLA). Under the OWN approach each bucket must equal ONE RTPL factor, so you cannot pool ACROSS FACTORS via your own buckets — pooling across UNCLAIMED tenor space (route 4) remains open. If you want CROSS-FACTOR pooling, use the REGULATORY grid — BCBS controls the pooling width. KEY: an RFET bucket only COUNTS prices; it does NOT set RTPL. PLA fails when the RTPL GRID is coarse, not when an RFET bucket is wide.
A16: 31.17 POOLING: 'one risk factor per bucket' is an OWN-approach rule only. A REGULATORY bucket may contain several risk factors, and all real prices in it count toward EACH of them (31.17) — e.g. a 3.5–7.5y band lets a thin 7Y borrow the 5Y's trades to pass the RFET, WHILE RTPL keeps 5Y and 7Y separate. So regulatory pooling helps thin tenors WITHOUT any PLA cost — it is the legitimate route, not the higher-PLA-risk one. → Worked 31.17 example (the pooling subsidy vs the representativeness bill) on 50_special_cases.
A17: GEOMETRY IS SHARED, ONLY RANGES DIFFER: the curve/surface/cube structure (a band per axis → rectangle → box, see the diagram on 30_instrument_coverage) applies to BOTH approaches. It is inherent to the risk factor (31.16 chapeau) and, for OWN bucketing, FORCED by 31.16(1)(a): a surface own-bucket must be bounded on EVERY axis, else it would hold >1 risk factor. Only the fixed RANGES (Table 1 bands) and the (a)–(f) row assignments are regulatory-only; own bucketing keeps the same geometry and just draws its own edges. Own does NOT borrow structure from regulatory — the geometry is a property of the risk factor.
A18: FOOTNOTE 5 & THE INVARIANT TRADE-OFF: fn 5 ties own buckets to the RTPL segmentation for PLA and warns that finer granularity helps PLA but strains the RFET (fewer prices per bucket). That trade-off — granularity vs genuine data sufficiency — is INVARIANT; it does not vanish under the regulatory approach, it RELOCATES. Regulatory pooling relaxes the raw COUNT, but is capped by REPRESENTATIVENESS: a 3.6y trade may only count toward a fine 7Y factor if it is genuinely representative of it (31.17), and source accuracy matters (31.25). So the cost of pooling is a QUALITY/representativeness cost (and supervisor scrutiny of 'borrowed' modellability) — NOT a PLA cost. Regulatory is the norm for thin/illiquid books; own is chosen for control and the cleanest 'each factor on its own trades' defensibility.
A19: → See '45_guardrail' for the nomenclature, the SA floor (31.3) and ROUTES 1–3 for a thin tenor (worked as a Credit desk / 7Y CDS). ROUTE 4 — own-bucket capture of no-man's-land liquidity — is worked at the bottom of THIS sheet.
A20: ELECTION GRANULARITY: the own-vs-regulatory choice is made PER CURVE / SURFACE / CUBE — own on the liquid EUR swap curve and regulatory on a thin single-name CDS curve can coexist (EU codification: Art. 5(1), Delegated Regulation (EU) 2022/2060 — buckets are determined 'for each curve, surface or cube' using EITHER approach; the MAR31.16 chapeau is likewise object-level). NEVER two schemes within one object: buckets must partition the axis and each observation counts in a single bucket (31.18). Record the per-curve election in the 31.15 policy set. Note: 2022/2060 attaches 'consistently over time' to the SHIFTED-PERIOD election (Art. 1(2)/5(3)), not to this choice — but re-electing each quarter to whichever approach passes is gaming; treat an approach switch as a model change needing justification.
A22: Worked election — ONE book, MIXED approaches (per-object election; see the granularity note above)
A23: Curve / surface / cube | B23: Liquidity & model profile | C23: Election | D23: Why
A24: EUR swap curve (GIRR) | B24: all desk pillars liquid; RTPL fine (0.25y–30y) | C24: OWN | D24: each pillar = its own bucket = its own trades; cleanest 31.16(1)(a) evidence; no pooling needed
A25: ACME 5Y/7Y CDS curve | B25: 5Y ~40 trades/yr; 7Y ~12 | C25: REGULATORY (row C) | D25: the 3.5–7.5y band pools 5Y+7Y prints while RTPL keeps them separate → PLA safe (route 3, 45_guardrail)
A26: EUR swaption vol cube | B26: core expiry×tenor grid quoted daily; wings sparse | C26: REGULATORY (B×C×D) | D26: off-benchmark expiry×tenor points and near-ATM strikes borrow the daily benchmark prints that land in the same B×C×D box (31.17); deep strike wings sit in their own D-bands and typically stay NMRF — 3-D walkthrough on 50_special_cases
A27: EURUSD vol surface | B27: desk model = 3 params per expiry (ATM/RR/BF); pillar quotes liquid | C27: OWN | D27: own buckets drawn = the parameter factors (one per bucket); RFET passed on the calibration quotes (31.19); δ-convention conversion per fn6 — 31.19 walkthrough on 50_special_cases
A28: WTI futures curve | B28: front 6 contracts liquid; 12–18M months thin | C28: REGULATORY (row A) | D28: thin back months pool inside the 0.75–1.5y band; monthly RTPL pillars stay intact
A29: HUF swap curve (GIRR) | B29: only 2Y/5Y/10Y trade regularly; other tenors sporadic | C29: REGULATORY (row A) | D29: same product type as the EUR swap curve, OPPOSITE election — thin tenors pool inside the A-bands while the RTPL pillars stay intact (per-object granularity in action) — tenor-by-tenor anatomy below (rows 39–48)
A30: DEF Corp CDS curve | B30: index constituent; 5Y prints ~daily, full curve quoted | C30: OWN | D30: same product type as ACME, opposite election — every pillar passes on its OWN trades; no borrowed modellability to defend
A31: iTraxx Europe index curve (systematic factor) | B31: index trades daily across 3/5/7/10Y pillars | C31: OWN | D31: 31.21: even a systematic curve's maturity axis must be bucketed — liquid at every pillar, so own is free and clean
A32: USDTRY vol surface | B32: pillar quotes patchy beyond 1Y; wings rarely quoted | C32: REGULATORY (C×D) | D32: same product type as EURUSD, opposite election — sparse expiries/strikes accumulate within their C- and D-bands; the fn6 δ-conversion is accepted as the price of pooling
A33: SX5E index vol surface | B33: dense listed quotes across expiries & strikes | C33: OWN | D33: the listed market gives per-pillar evidence at every point the model keeps; no pooling needed
A34: MidCap AG single-name equity vol | B34: monthly listed prints; few strikes | C34: REGULATORY (C×D) | D34: sparse single-name options pool within bands; deep strike wings likely stay NMRF regardless (cube walkthrough logic, 50_special_cases)
A35: EURUSD xccy basis curve | B35: 5Y/10Y quoted daily; 15Y+ sporadic | C35: REGULATORY (row A) | D35: sporadic long-end prints accumulate WITH EACH OTHER inside the 12–18y / 18–25y bands; the liquid front passes on its own prints — a regulatory election costs the liquid points nothing
A37: THE REGISTER RULE — one election per OBJECT (= curve/surface/cube, i.e. product type × currency/underlying); ALL points on the object follow it; mixing ACROSS objects is the intended design (Art. 5(1), Delegated Regulation (EU) 2022/2060 — note the same-product, opposite-election pairs above), and mixing WITHIN one object has no payoff: under a regulatory election the liquid points still pass on their OWN prints. Decide by asking FROM WHERE the thin points would borrow: (a) another FACTOR's pillars → REGULATORY (only the grid may pool across factors); (b) UNCLAIMED tenor space where no factor lives → OWN captures it (route 4 below); (c) no borrowing anywhere → OWN. Record every election, with rationale and review date, in the register (documentation map at the foot of this sheet).
A39: Anatomy of ONE election — the HUF swap curve, tenor by tenor (why 'own for the liquid pillars' is never a reason to split an object)
A40: Tenor (liquidity) | B40: Row-A band it lands in | C40: Liquid neighbour in the band | D40: Verdict under a WHOLE-CURVE regulatory election
A41: 2Y — liquid | B41: 1.5 ≤ t < 4y | C41: — (itself) | D41: passes on its OWN prints — exactly what own bucketing would deliver
A42: 3Y — sporadic | B42: 1.5 ≤ t < 4y | C42: the 2Y | D42: borrows the 2Y's prints → passes (31.17)
A43: 5Y — liquid | B43: 4 ≤ t < 7y | C43: — (itself) | D43: passes on its own prints
A44: 6Y — sporadic | B44: 4 ≤ t < 7y | C44: the 5Y | D44: borrows → passes
A45: 7Y — sporadic | B45: 7 ≤ t < 12y (bands are closed-left / open-right: 7Y is NOT in 4–7y) | C45: the 10Y | D45: borrows the 10Y's prints → passes
...

Sheet 45_guardrail
A1: RTPL Grid, Nomenclature & the 31.16(1)(a) Guardrail
A2: What a risk factor / bucket / SA bucket really are, the SA floor (31.3), and the four routes for a thin tenor.
A4: 0 · Nomenclature — four terms, and why 'bucket' is overloaded
A5: 'Bucket' means DIFFERENT things in the SA and in the RFET, and 'risk factor' vs 'bucket' get confused. Bucketing NEVER creates a risk factor — the factors are the model's; a bucket only GROUPS them (for aggregation in the SA, for counting real prices in the RFET). Example — EUR general interest-rate risk (GIRR):
A6: Term | B6: What it is | E6: Example (EUR GIRR)
A7: Risk factor | B7: a market point the ES model reprices at (a point of the RTPL grid) | E7: EUR 5Y risk-free rate
A8: SA tenor vertex (MAR21) | B8: a prescribed SA risk-factor point | E8: EUR 5Y (SA vertices 0.25/0.5/1/2/3/5/10/15/20/30y)
A9: SA 'bucket' (MAR21) | B9: a GROUP of risk factors aggregated for capital — a DIFFERENT use of 'bucket' | E9: 'EUR' — the whole currency (all its tenors)
A10: RFET 'bucket' (MAR31.16) | B10: a maturity/strike WINDOW used only to COUNT real prices for modellability | E10: the 4–7y maturity band
A11: So an SA bucket ('EUR', a currency GROUP for aggregation) and an RFET bucket ('4–7y', a maturity WINDOW for counting prices) are unrelated despite sharing the word — and an RFET bucket does NOT define a new risk factor; the 5Y and 7Y factors are the model's, the bucket just counts trades toward them.
A13: 1 · The RTPL grid — and the SA floor (MAR31.3)
A14: RTPL grid = the exact curve/surface POINTS your risk engine reprices at to produce RTPL — each is one risk factor shocked independently. MAR31.3: the model MUST INCLUDE all Standardised-Approach risk factors for the class (a FLOOR); it may be FINER (MAR31.6: ≥6 yield-curve factors, more for complex books). So RTPL grid ⊇ SA vertices. Example — an ACME Corp credit-spread curve RTPL grid:
A15: 0.5Y · 1Y · 2Y · 3Y · 5Y · 7Y · 10Y
A16: Note: a 7Y is often a bank-ADDED finer factor — for credit spread the SA (CSR non-sec) vertices are 0.5/1/3/5/10y (MAR21.9), no 7Y (GIRR likewise jumps 5Y→10Y within its 0.25–30y set, MAR21.8) — added because the desk trades 7Y. A desk with NO 7Y exposure need not add a 7Y factor (interpolate from neighbours); an SA-mandated factor with no exposure still sits in the model but has zero sensitivity, so it is immaterial to that desk's PLA.
A18: 2 · The guardrail — what MAR31.16(1)(a) actually forbids
A19: Under the OWN bucketing approach each bucket must equal ONE RTPL risk factor. This blocks the 'FREE LUNCH': a wide SELF-DEFINED bucket (pool many trades → pass the RFET) sitting over a FINE RTPL (pass PLA). BCBS's logic — if you want CROSS-FACTOR pooling (another pillar's prints), use OUR fixed grid (the regulatory approach), where the pooling width is controlled, not one you choose. A regulatory RFET bucket is only a COUNTING window; it does NOT coarsen RTPL, so it carries no PLA cost. THE FLOOR CAPS COARSENESS: own buckets may absorb bank-ADDED pillars (7Y), but may never span two SA vertices (e.g. the CSR 5Y & 10Y) — RTPL must retain every SA vertex (31.3), so such a bucket would hold ≥2 RTPL factors and violate 31.16(1)(a); merging the vertices instead breaches the floor itself (escape only via supervisory sign-off for the omission, 31.3(1)).
A21: 3 · A thin tenor — the four routes (routes 1–3 below; route 4 worked on 40_own_vs_regulatory)
A22: Route | B22: What you do | F22: Outcome
A23: 1 · Keep fine → NMRF | B23: Leave the 7Y as its own factor; it fails the RFET on ~12 trades | F23: HONEST — NMRF stressed add-on; RTPL fine, PLA fine
A24: 2 · Coarsen RTPL (own) | B24: Two variants: (2a) merge 5Y/7Y/10Y into one blended 5–10Y factor; (2b) drop only the bank-ADDED 7Y factor, reprice 7Y exposure by INTERPOLATING the 5Y & 10Y factors, and widen the 5Y own bucket to absorb the 7Y trades (still one RTPL factor per bucket) | F24: 2a BLOCKED ex ante — swallows SA CSR vertices 5Y & 10Y, breaching the MAR31.3 floor (omission needs 31.3(1) sign-off; implausible with material exposure). 2b legal — but coarse RTPL → FAILS PLA (worked below). Self-defeating either way
A25: 3 · Regulatory pooling | B25: Use the BCBS grid; the 3.5–7.5y band pools the 7Y's trades with the 5Y's | F25: PASSES RFET, RTPL keeps 5Y & 7Y SEPARATE → PLA fine ← legit escape
A26: Route 2a is pincered from both sides: keep 5Y & 10Y separate (as 31.3 requires) and a 5–10Y own bucket holds TWO RTPL factors — a 31.16(1)(a) violation; merge them instead and you breach the 31.3 floor itself. 31.16(1)(a) also forbids the free-lunch cousin — a wide SELF-defined bucket over FINE RTPL. Route 3 is the sanctioned way to help a thin tenor: BCBS controls the pooling width via its own grid. ROUTE 4 — own-bucket capture: when the spare liquidity sits in tenor space where NO model factor lives (an active 6Y market, no 6Y factor), draw the thin factor's OWN bucket around it — passes the RFET with zero PLA cost; worked on 40 rows 50–52.
A28: 4 · Worked example — Credit desk & the illiquid 7Y CDS (route 2b — the LEGAL coarsening)
A29: The Credit desk holds $100m 7Y single-name CDS on ACME Corp (CS01 ≈ $60k per bp of spread) on a THIN 7Y credit-spread point (~12 real trades/yr → fails the RFET alone). Route 2b: it DROPS the bank-added 7Y factor (legal — 7Y is not an SA vertex; the CSR floor 0.5/1/3/5/10y stays intact), reprices the 7Y exposure by INTERPOLATING the 5Y and 10Y factors, and widens the 5Y own bucket to absorb the 7Y trades (legal: the bucket still holds ONE RTPL factor). Compare two days:
A30: Day | B30: 5Y spr | C30: 7Y spr | D30: 10Y spr | E30: HPL (front office) | F30: RTPL — narrow (true 7Y) | G30: RTPL — coarse (7Y interp. of 5Y/10Y)
A31: Calm / parallel | B31: +5bp | C31: +5bp | D31: +5bp | E31: −$300k | F31: −$300k ✓ match | G31: −$300k ✓ match
A32: Credit TWIST | B32: +2bp | C32: +8bp | D32: +3bp | E32: −$480k | F32: −$480k ✓ match | G32: ≈ −$144k ✗ $336k gap
A33: On the twist day the front office reprices the ACTUAL +8bp 7Y spread move (HPL = −$480k @ $60k/bp), but the coarse engine only sees the interpolated +2.4bp (RTPL ≈ −$144k: 2 + (3−2)×(7−5)/(10−5)) — it no longer has a 7Y factor to carry the hump, and unlike the (blocked) blended 2a engine it does not even see the 7Y quote. A $336k gap opens — BIGGER than 2a's would have been (≈ −$258k). Calm days match; every credit-curve twist / flattening diverges.
A35: 5 · The consequence chain (route 2)
A36: Drop the bank-added 7Y & interpolate (route 2b) → coarse RTPL → HPL−RTPL diverges on every credit-curve twist → over the 250-day window Spearman ↓ (e.g. 0.95 → 0.72 — already below the 0.80 amber line) and KS ↑ (> 0.12 — RED on its own; red zone = Spearman < 0.70 OR KS > 0.12, MAR32.42, Table 2) → desk in the PLA RED zone → desk loses IMA (MAR32.43) → the WHOLE desk falls to the Standardised Approach. The capital jump dwarfs the NMRF add-on the desk tried to dodge. (Route 2a — blending across 5Y & 10Y — never even reaches PLA: it dies at the MAR31.3 floor.)
A38: 6 · Bottom line
A39: PLA fails when the RTPL GRID is too coarse to track HPL — NOT because an RFET bucket is wide. So the honest answers for a thin tenor are route 1 (NMRF, keep RTPL fine) or route 3 (regulatory pooling, keep RTPL fine). Never route 2. You may only CLAIM a factor modellable if your model genuinely USES it at that resolution: modellable → IMA; unmodellable → NMRF; and you cannot disguise the second as the first. The SA floor bounds the whole game: legal coarsening stops at the SA vertex grid (31.3).

Sheet 50_special_cases
A1: Special Cases & Maintenance Rules (MAR31.17–31.21)
A2: Counting, ageing, parametric curves, and systematic factors.
A4: Clause | B4: Rule | C4: Practical implication
A5: 31.17 — Pooling | B5: All real prices allocated to a bucket count toward EVERY risk factor in that bucket; a price must be allocated to a bucket it is representative of. | C5: This is what lets sparse curve/surface points pass — observations are shared within a bucket.
A6: 31.18 — Ageing / roll-down | B6: As instruments mature, observations stay in their original bucket; when a credit-spread point is no longer modelled, its prices may be re-allocated to the adjacent SHORTER maturity bucket. Each price counts in ONLY one bucket. | C6: A 4Y bond observed 8 months ago may sit in the 1.5–3.5y bucket rather than 3.5–7.5y. No double-counting across buckets.
A7: 31.19 — Parametric curves | B7: If the curve/surface is a parametric function and its PARAMETERS are the risk factors (e.g. SABR, Nelson-Siegel), the RFET is passed on the underlying MARKET DATA used to calibrate, not on the parameters themselves. | C7: You cannot observe 'the SABR β' in the market — so test the inputs. Mirrors Principle 1 (PCA / latent params).
A8: 31.20 — Systematic factors | B8: Systematic credit/equity factors (market/region/sector) are allowed; the issuer-specific IDIOSYNCRATIC part is NMRF unless that issuer itself has enough real prices. Index/name prices can represent a systematic factor if they share its attributes. | C8: Index proxy captures general risk; the idiosyncratic residual is the NMRF / PLA risk (ties to Principle 2 & 7).
A9: 31.21 — Systematic + maturity | B9: If a systematic factor has a maturity axis (e.g. a sector credit-spread curve), one of the bucketing approaches MUST be applied to that axis to count observations. | C9: Even market-wide curves get bucketed on tenor — row C for credit/equity.
A11: MAR31.20 worked example — systematic vs idiosyncratic (Credit desk)
A12: Set-up | B12: The Credit desk prices an ACME Corp bond/CDS as two pieces: a SYSTEMATIC sector factor + an ISSUER-SPECIFIC (idiosyncratic) residual.
A13: Systematic factor | B13: EUR IG-Industrials sector credit-spread factor — captures market/sector-wide moves. Backed by a LIQUID index (e.g. iTraxx / CDX or a sector CDS index).
A14: → modellable? | B14: YES — the index's real trades represent it (they 'share the same attributes': sector, region, quality, per 31.20). Goes in the ES model.
A15: Idiosyncratic residual | B15: ACME's own spread MINUS the sector factor — the name-specific part. ACME single-name CDS is illiquid: ~12 real trades/yr.
A16: → modellable? | B16: NO — fails the RFET on its own trades → NON-MODELLABLE RISK FACTOR (NMRF) → separate stressed (SES) capital add-on, unless ACME itself gets ≥24 real prices.
A17: Equity analogue | B17: A sector / market BETA factor is modellable from an index; the SINGLE-STOCK residual is NMRF unless the stock trades enough.
A18: Ties to | B18: Principle 2 (capture idiosyncratic AND general risk) and Principle 7 (proxies: index captures general, residual basis must be capitalised).
A19: → 31.19 worked example below (rows 41+): the FX vol surface as a 3-parameter smile — RFET passed on the ATM/RR/BF calibration quotes. The same principle governs SABR / Nelson-Siegel parameters (you cannot observe β in the market — test the inputs).
A21: MAR31.17 worked example — the pooling SUBSIDY (sentence 1) vs the representativeness BILL (sentence 2)
A22: Set-up (subsidy) | B22: RTPL holds ACME 5Y and ACME 7Y credit-spread factors; both sit in regulatory row C bucket 3 (3.5–7.5y). The year brings 40 real trades ~5Y and 12 ~7Y. Alone, the 7Y fails (12 < 24). Pooled, the bucket holds 52 observations and EVERY factor in the bucket — the 7Y included — is assessed on all 52 (sentence 1). Both pass.
A23: The bill (sentence 2) | B23: Each price must be allocated to a bucket for which it is REPRESENTATIVE of the risk factors in it. Representative (31.15) = the bank can EXTRACT the factor's value from the price, under written mapping policies the supervisor can inspect. The 40 borrowed 5Y trades count toward the 7Y only through that claim.
A24: Candidate observation | B24: In 3.5–7.5y band? | C24: Representative of ACME 7Y? | D24: Counts toward ACME 7Y?
A25: ACME 5Y CDS trade | B25: Yes | C25: YES — same name, seniority, doc clause; a curve model extracts the 7Y point from a 5Y price | D25: ✓ counts — the legitimate borrow
A26: DEF Corp 5Y CDS trade | B26: Yes | C26: NO — different issuer = different risk factor (categorical attributes must match exactly; the tenor band was never the only coordinate) | D26: ✗ does not count
A27: iTraxx Europe 5Y index trade | B27: Yes | C27: Only of the SYSTEMATIC sector factor (31.20) — not of ACME's name-specific spread | D27: ✗ for ACME 7Y (✓ for the sector curve's bucket)
A28: ACME 3.6y trade → a 7.4y factor | B28: Yes | C28: STRETCH — both ends of the band, but a 3.6y price says little about 7.4y in a steepening; the extraction claim is thin | D28: ✓ only if defended; supervisor can challenge, and 31.23 can force NMRF even after an RFET pass
A30: Moral: regulatory pooling converts a COUNTING problem into an EVIDENCE problem — the marginal observations that lift a thin factor over 24 are exactly the borrowed ones resting on an argument, not on identity. Under OWN bucketing sentence 2 barely arises: each bucket IS one factor, so every observation is the factor's own evidence. Both approaches face 31.25 (source accuracy) equally; only regulatory pooling faces sentence 2 doing real work. Backstop: 31.23 — supervisor may deem the data unsuitable and push the factor to NMRF despite an RFET pass.
A32: 31.17 in THREE dimensions — the swaption cube: what prints daily, what a 'wing' is, and where pooling stops
A33: The cube | B33: A swaption vol risk factor is a TRIPLE: (option expiry, underlying swap tenor, strike δ) — '2Y into 10Y at δ0.5' = an option expiring in 2y on a swap that then runs 10y, struck ATM. A regulatory bucket is therefore a BOX: one row-C band (expiry) × one row-B band (tenor) × one row-D band (strike).
A34: What prints daily | B34: Brokers quote vols daily at the BENCHMARK expiry×tenor pairs, almost always at-the-money: 1Y×10Y, 2Y×10Y, 5Y×5Y, 3M×2Y… Each committed quote is ONE real-price observation at coordinates (that expiry, that tenor, δ≈0.5). Away from the benchmark pairs (odd combinations like 2.5Y×12Y) and away from ATM, quotes are sporadic.
A35: 'Wings' — two senses | B35: Strictly, wings = the far-from-ATM ends of the STRIKE axis (deep OTM/ITM, δ near 0.05 or 0.95 — smile terminology). Loosely, 'wings' gets used for ANY sparse off-benchmark region of the cube. The two behave DIFFERENTLY under pooling — see the two worked rows below.
A36: Where pooling HELPS | B36: Factor (expiry 2.5Y, tenor 12Y, δ0.60) — off-benchmark, itself almost never traded. Its box: expiry 1.5–3.5y (C2) × tenor 10–18y (B4) × δ 0.3–0.7 (D3). The daily 2Y×10Y ATM quote lands in the SAME box (2Y∈C2 ✓, 10Y∈B4 ✓, δ0.5∈D3 ✓); so do 3Y×15Y ATM prints → ~250 obs/yr in the box → it passes the RFET and EVERY factor in it is modellable (31.17), including the untraded 2.5Y×12Y point. Under OWN bucketing that point would stand alone on its own trades → NMRF. This is why the cube elects REGULATORY in the 40-sheet table.
A37: Where pooling STOPS | B37: Pooling NEVER crosses a band boundary. Factor (2Y, 10Y, δ0.85) sits in D4 (0.7–0.95): the daily ATM prints (D3) count for NOTHING there. That box only receives prints from actual OTM/collar trades — if there aren't ≥24 with the 90-day density, the point is an NMRF, full stop.
A38: Deep wings & band widths | B38: The middle strike band D3 (0.3–0.7) is deliberately BROAD, so near-ATM strikes pool generously with the ATM benchmark flow. The outermost bands (D1: δ<0.05, D5: δ≥0.95) are narrow AND thinly traded — the classic residual NMRFs on a swaption desk. Their SES may, with approval, be computed at bucket level using these same buckets (MAR33.16).
A39: Moral | B39: The regulatory election lets benchmark liquidity carry off-benchmark model points WITHIN each 3-D box — off-benchmark expiry×tenor combinations and near-ATM strikes ride the daily prints; the deep strike wings sit in their own D-bands and typically stay NMRF. 'Wide boxes' are a subsidy with a hard edge: the band boundary.
A41: 31.19 worked example — FX vol surface as a 3-parameter smile (ATM / RR / BF): the RFET is passed on the CALIBRATION QUOTES
A42: The market quotes | B42: FX options are not quoted strike-by-strike. Per expiry, brokers quote three instruments: ATM straddle vol (the smile's LEVEL), 25Δ risk reversal RR = vol(25Δ call) − vol(25Δ put) (the SKEW), and 25Δ butterfly BF = average of the 25Δ wings − ATM (the CURVATURE). E.g. 1Y EURUSD: ATM 7.0%, RR −0.8%, BF +0.25% → 25Δ put vol = ATM + BF − RR/2 = 7.65%; 25Δ call vol = 6.85%.
A43: The model / RTPL factors | B43: The desk stores THREE parameters per expiry pillar (1W, 1M, 3M, 6M, 1Y, 2Y…): ATM, RR, BF — not a dense strike grid. These parameters ARE the risk factors in the model and hence in RTPL.
A44: The 31.19 rule | B44: Parameters of a functional form are not directly traded, so the RFET must be passed at the level of the MARKET DATA used to calibrate them — not at the parameter level. FX is the friendly case: the calibration inputs are themselves COMMITTED broker quotes (ATM/RR/BF — real prices per 31.12(3)), so those are what get counted.
A45: Why the desk elects OWN | B45: Each own bucket must hold exactly ONE RTPL factor — and this desk has exactly three strike-dimension factors per expiry. So it draws expiry bands around its quoted pillars and strike ranges matching each parameter (ATM region → ATM factor; 25Δ wing quotes → RR/BF). ONE segmentation then serves RFET + RTPL + PLA — footnote 5's 'same buckets' requirement satisfied by construction. EURUSD pillars are deeply liquid → every bucket gets ≥24 obs from its OWN quotes: no pooling, no representativeness debate. (The EBA modellability RTS explicitly contemplates own strike ranges per ATM / skew / smile parameter.)
A46: Why NOT regulatory | B46: The fixed row-D bands (0.05 / 0.3 / 0.7 / 0.95) do not map to ATM/RR/BF — 25Δ quotes land in D2, ATM in D3, and no band corresponds to 'the RR factor' or 'the BF factor'. The desk has no thin points needing the pooling subsidy (contrast the swaption cube above), so regulatory would add a quote→band mapping layer for nothing.
...

Sheet 55_systematic_proxy_nmrf
A1: Quantifying the Split — Systematic (modellable) vs Idiosyncratic / Proxy Basis (NMRF)
A2: Numerical companions to 31.20 (systematic credit/equity), 31.5 & 31.26 Principle 7 (proxies), 31.22 (calibration data ≠ RFET data) and MAR33.16 (SES). All calibrations ILLUSTRATIVE — replace with own data. Gaussian 97.5% ES multiplier 2.34 used throughout; σ's quoted from the worst 12-month (stress) window.
A4: 1 · CREDIT — index-mapped SYSTEMATIC factor + idiosyncratic residual left as NMRF (31.20)
A5: Desk holds $10m 5Y CDS on XYZ Corp (EUR IG Industrials; CS01 ≈ $4.6k per bp) — the calculator's thin name: ~12 real prices/yr, so the full name-specific spread FAILS the RFET. The desk therefore models the spread as s_XYZ(t) = β · s_SECTOR(t) + s_RESID(t), where s_SECTOR is a EUR IG-Industrials sector credit-spread curve backed by liquid iTraxx Europe / sector-index trades (shares the sector's attributes: region EUR, quality IG, sector Industrials → those trades REPRESENT it, 31.20; its maturity axis is bucketed row C per 31.21 and passes the RFET with hundreds of prints).
A6: How the split is QUANTIFIED — 31.22 lets calibration use vendor marks even though the RFET counts real prices; P7(a): β must be EMPIRICAL, never judgment:
A7: Quantity | B7: Value | C7: How obtained | D7: Notes
A8: Regression | B8: Δs_XYZ = β·Δs_SECTOR + ε | C8: weekly changes, 2y window (104 obs) of vendor consensus marks | D8: re-estimate at least every 2 weeks (Principle 5)
A9: Beta β | B9: 1.25 | C9: OLS slope | D9: high-beta name within its sector; empirical per P7(a)
A10: σ(Δs_SECTOR), weekly | B10: 6.0 bp | C10: sample st.dev. | D10: the systematic driver
A11: σ(ε), weekly (residual) | B11: 4.0 bp | C11: regression residuals | D11: the idiosyncratic component
A12: R² (variance explained) | B12: ≈ 0.78 | C12: (1.25·6)² / [(1.25·6)² + 4²] = 56.25 / 72.25 | D12: 'significant explanatory power' required, P7(a)
A13: Daily P&L split | B13: systematic = β·Δs_SECTOR·CS01; idio = ε·CS01 | C13: same β as the ES model | D13: keeps RTPL consistent with the decomposition
A15: RFET / capital treatment of the two components:
A16: Component | B16: RFET outcome | C16: Capital treatment
A17: Systematic sector factor s_SECTOR | B17: MODELLABLE — index & constituent trades represent it (31.20); hundreds of obs across row-C buckets (31.21) | C17: → ES model (diversifies with the rest of the book)
A18: Idiosyncratic residual s_RESID | B18: NMRF — it needs XYZ's OWN real prices: 12/yr < 24 | C18: → SES stress-scenario add-on (MAR33.16); ZERO-correlation aggregation across idio credit NMRFs allowed with supervisor demonstration (33.16(2))
A20: What the decomposition is WORTH — SES on a 40-day IG credit-spread horizon (MAR33.12 LH = 40d ⇒ √8 weekly scaling; move = weekly σ × √8 × 2.34):
A21: Treatment | B21: Stressed 40-day move | C21: SES charge | D21: In the ES model | E21: Comment
A22: No decomposition — whole XYZ spread as NMRF | B22: 8.5 bp × √8 × 2.34 ≈ 56 bp (8.5 = √(56.25+16) total σ) | C22: 56.3 bp × $4.6k ≈ $259k | D22: nothing | E22: punitive; no diversification, full spread stressed
A23: With decomposition — only the residual as NMRF | B23: 4.0 bp × √8 × 2.34 ≈ 26 bp | C23: 26.5 bp × $4.6k ≈ $122k | D23: the systematic 78% of variance | E23: saves ≈ $137k (~53%) on ONE name; scales across the book
A24: IF XYZ LATER PRINTS ≥24 REAL PRICES/YR (incl. the 90-day density — re-tested QUARTERLY): the RESIDUAL component becomes modellable — 31.20's own wording: idiosyncratic risk is NMRF 'unless there are sufficient real price observations of that issuer' — and its capital routing flips SES → ES. THE DECOMPOSITION STAYS: the factor-model architecture is the model (Principle 1), not a workaround for missing prints — β keeps driving the daily P&L split, the hedge analytics and RTPL. Keeping the split constant means a quarterly RFET flip changes ONLY the residual's capital treatment (one line in the NMRF register) — never the model, the RTPL, or the PLA time series. A bank MAY instead re-model the whole spread as one directly-calibrated factor once it passes — permitted, but a name hovering at 22–26 prints flips across the boundary quarter to quarter, and re-architecting on every flip is a model change (validation, supervisor notification, an RTPL structural break) each time. The regression does not become meaningless — it becomes fully funded: the same machinery now feeds an ES factor with diversification benefit instead of a punitive SES add-on.
A26: 2 · EQUITY — thin single name: CHOOSING a substitute risk factor (proxy) & quantifying the basis NMRF (31.5, 31.26-P7)
A27: Desk is long €8m NovaTech AG (DACH mid-cap, industrial software; sporadic block trades → ~15 real prices/yr → the NovaTech spot factor FAILS the RFET; total weekly σ = 4.0%). Two candidate proxies, both liquid and modellable — P7: a proxy must match REGION, QUALITY and TYPE, with a track record (31.5):
A28: Candidate proxy | B28: Region | C28: Sub-industry | D28: Size / balance-sheet | E28: β (OLS, 2y weekly) | F28: ρ (corr., R²) | G28: Residual σ, weekly
A29: STOXX Europe 600 Technology (index) | B29: Europe ~ (broad) | C29: Tech ~ (broad) | D29: large-cap ✗ | E29: 1.10 | F29: 0.68 (R² 0.46) | G29: 2.9% = 4%·√(1−0.46)
A30: TechnoSys SE (peer stock) | B30: DACH ✓ | C30: industrial software ✓ | D30: mid-cap, similar leverage ✓ | E30: 0.95 | F30: 0.78 (R² 0.61) | G30: 2.5% = 4%·√(1−0.61)
A31: Selection: the PEER STOCK dominates on attribute match, correlation and residual σ → proxy = 0.95 × TechnoSys. Document the track record (31.5); re-estimate β at least every 2 weeks (P5). RTPL rule (P7(b)): the PROXY representation — not NovaTech itself — goes into RTPL, UNLESS the basis (NovaTech − 0.95·TechnoSys) is identified and capitalised (in ES if modellable, else as NMRF); once the basis is properly capitalised, RTPL may carry either proxy+basis or the actual factor.
A32: Quantifying the basis NMRF — equity small-cap LH 20d = 4 weeks (MAR33.12; ≥20d floor per 33.16(1)); move = weekly σ × √4 × 2.34:
A33: Treatment | B33: Stressed 20-day move | C33: SES | D33: Comment
A34: No proxy — whole NovaTech position as NMRF | B34: 4.0% × √4 × 2.34 ≈ 19% | C34: €8m × 18.7% ≈ €1.50m | D34: worst case: nothing in ES, everything stressed
A35: Index proxy — basis as NMRF | B35: 2.9% × √4 × 2.34 ≈ 13.7% | C35: ≈ €1.10m | D35: weak proxy leaves a fat basis
A36: Peer-stock proxy — basis as NMRF | B36: 2.5% × √4 × 2.34 ≈ 11.7% | C36: ≈ €0.94m | D36: best proxy → smallest NMRF; the systematic part lives in ES and RTPL stays PLA-aligned
A37: Proxy choice is itself a capital AND attribution lever: peer stock vs index saves ≈ €160k of SES on one name and tightens HPL−RTPL (PLA). Zero-correlation aggregation across idiosyncratic equity NMRFs is permitted with demonstration (33.16(2)). If NovaTech later prints ≥24 real prices/yr, the actual factor passes the RFET and the proxy scaffolding can be retired.
A39: NMRF HOUSEKEEPING — BUCKET-LEVEL SES (MAR33.16), a separate concession unrelated to any single name's flip: for whatever REMAINS non-modellable on a curve/surface/cube (other names' residuals, stranded long tenors like the HUF 15Y, deep strike wings), the bank may — with supervisory approval — compute ONE stress-scenario charge per MAR31.16 BUCKET, using the SAME buckets it used to disprove modellability, instead of one charge per risk factor. An operational concession for sparse regions of the grid; it changes how the SES bill is computed, never who owes it.
A40: PRECISION ON THE MECHANICS: the stress PERIOD is never per-NMRF — MAR33.16 fixes ONE common 12-month window per RISK CLASS. What is per-NMRF by default is the SCENARIO: the calibrated extreme shock within that window, scaled to max(LH, 20d), at ≥97.5%-ES prudence. The bucket concession consolidates the SCENARIO, not the period — one joint shock for all the bucket's NMRFs — and thereby implicitly grants INTRA-BUCKET NETTING: under per-factor scenarios a long-13Y / short-15Y pair is stressed adversely on BOTH legs, while one joint bucket scenario lets the hedge offset. That is why approval is required, and why the buckets must be the SAME ones that disproved modellability — the geometry that earned the pooling benefit is the only one allowed to earn the netting benefit. Aggregation across buckets stays per MAR33.17.

Sheet 57_seven_principles
A1: The Seven Data Principles (MAR31.25–31.26) — the rent a factor pays to STAY in the ES model
A2: Applied AFTER a factor passes the RFET, to the data used to CALIBRATE the ES model (which need not be the RFET data, 31.22). 31.25 chapeau: never rely on observation COUNTS alone — source ACCURACY matters. 31.26 chapeau: banks must demonstrate the principles to their supervisor; principles unmet ⇒ the supervisor may deem the data unsuitable and the factor becomes an NMRF DESPITE the RFET pass (31.23). The RFET is the entry ticket; these principles are the rent.
A4: # | B4: Principle | C4: What it requires (gist of the text) | D4: Where it bites in this workbook
