Workbook

Sheet CurrentPor-All Factor Movements
C1: LH = 10 | G1: LH = 20 | H1: LH = 40 | I1: LH = 60 | J1: LH = 20 | K1: Standard deviation of factors
A2: DATE | C2: 1Y_Treasury | D2: 2Y_Treasury | E2: MSFT price | F2: Intel price | G2: Credit spread: sovereign (investment grade, or IG) | H2: Credit spread: sovereign (high yield, or HY) | I2: Credit Spread: Corporate(HY) | J2: Carbon Credits | K2: 1Y_Treasury | L2: 2Y_Treasury | M2: MSFT price | N2: Intel price | O2: Credit spread: sovereign (investment grade, or IG) | P2: Credit spread: sovereign (high yield, or HY) | Q2: Credit Spread: Corporate(HY) | R2: Carbon Credits
A3: 45474 | B3: 45474 | C3: 4.2673967 | D3: 4.5673967 | E3: 521.43896 | F3: 36.962945 | G3: 0.51 | H3: 0.58622522 | I3: 0.69637381 | J3: 20.644002 | K3: =_xlfn.STDEV.P(C3:C263) -> 0.0045375175 | L3: =_xlfn.STDEV.P(D3:D263) -> 0.0044961099 | M3: =_xlfn.STDEV.P(E3:E263) -> 2.2034077 | N3: =_xlfn.STDEV.P(F3:F263) -> 2.0972959 | O3: =_xlfn.STDEV.P(G3:G263) -> 0.060694822 | P3: =_xlfn.STDEV.P(H3:H263) -> 0.052996577 | Q3: =_xlfn.STDEV.P(I3:I263) -> 0.0059420423 | R3: =_xlfn.STDEV.P(J3:J263) -> 4.9886877e-05
A4: 45475 | B4: 45475 | C4: 4.269368 | D4: 4.569368 | E4: 522.87989 | F4: 36.780622 | G4: 0.51 | H4: 0.66683919 | I4: 0.70908799 | J4: 20.644056 | K4: Standard deviation/Average%
A5: 45476 | B5: 45476 | C5: 4.2604934 | D5: 4.5604934 | E5: 522.63871 | F5: 33.649896 | G5: 0.51 | H5: 0.5738683 | I5: 0.70174466 | J5: 20.644002 | K5: =_xlfn.STDEV.P(C3:C263)/AVERAGE(C3:C263) -> 0.0010627636 | L5: =_xlfn.STDEV.P(D3:D263)/AVERAGE(D3:D263) -> 0.00098390709 | M5: =_xlfn.STDEV.P(E3:E263)/AVERAGE(E3:E263) -> 0.0042190212 | N5: =_xlfn.STDEV.P(F3:F263)/AVERAGE(F3:F263) -> 0.054559229 | O5: =_xlfn.STDEV.P(G3:G263)/AVERAGE(G3:G263) -> 0.15633269 | P5: =_xlfn.STDEV.P(H3:H263)/AVERAGE(H3:H263) -> 0.088635041 | Q5: =_xlfn.STDEV.P(I3:I263)/AVERAGE(I3:I263) -> 0.0084803547 | R5: =_xlfn.STDEV.P(J3:J263)/AVERAGE(J3:J263) -> 2.4165314e-06
A6: 45477 | B6: 45477 | C6: 4.2669615 | D6: 4.5669615 | E6: 523.30347 | F6: 37.081656 | G6: 0.51 | H6: 0.55415584 | I6: 0.68446686 | J6: 20.643982
A7: 45478 | B7: 45478 | C7: 4.2761961 | D7: 4.5761961 | E7: 520.65488 | F7: 38.854788 | G7: 0.5 | H7: 0.70278175 | I7: 0.70703017 | J7: 20.643926
A8: 45481 | B8: 45481 | C8: 4.2774526 | D8: 4.5774526 | E8: 524.18643 | F8: 39.915108 | G8: 0.52 | H8: 0.69285184 | I8: 0.70188085 | J8: 20.643945
A9: 45482 | B9: 45482 | C9: 4.2662063 | D9: 4.5662063 | E9: 526.7626 | F9: 38.826037 | G9: 0.52 | H9: 0.62109307 | I9: 0.69910659 | J9: 20.644019
A10: 45483 | B10: 45483 | C10: 4.2698552 | D10: 4.5698552 | E10: 526.48411 | F10: 40.559422 | G10: 0.51 | H10: 0.62999665 | I10: 0.70233 | J10: 20.644012
A11: 45484 | B11: 45484 | C11: 4.2725652 | D11: 4.5725652 | E11: 523.52381 | F11: 36.703913 | G11: 0.51 | H11: 0.6105303 | I11: 0.7157203 | J11: 20.64394
A12: 45485 | B12: 45485 | C12: 4.2675941 | D12: 4.5675941 | E12: 520.59333 | F12: 36.072425 | G12: 0.51 | H12: 0.62792874 | I12: 0.69935472 | J12: 20.644027
A13: 45488 | B13: 45488 | C13: 4.264274 | D13: 4.564274 | E13: 522.01054 | F13: 36.576999 | G13: 0.48 | H13: 0.68700411 | I13: 0.70432056 | J13: 20.64398
A14: 45489 | B14: 45489 | C14: 4.257758 | D14: 4.557758 | E14: 524.55069 | F14: 39.626477 | G14: 0.5 | H14: 0.54610546 | I14: 0.70274327 | J14: 20.643987
A15: 45490 | B15: 45490 | C15: 4.2781558 | D15: 4.5781558 | E15: 524.05111 | F15: 33.354785 | G15: 0.5 | H15: 0.562373 | I15: 0.69713657 | J15: 20.643925
A16: 45491 | B16: 45491 | C16: 4.2698508 | D16: 4.5698508 | E16: 527.45429 | F16: 38.030585 | G16: 0.49 | H16: 0.61849849 | I16: 0.68759396 | J16: 20.64396
A17: 45492 | B17: 45492 | C17: 4.2720218 | D17: 4.5720218 | E17: 524.03204 | F17: 33.90236 | G17: 0.5 | H17: 0.54908808 | I17: 0.70006206 | J17: 20.644061
... A263: 45838 | B263: 45838 | C263: 4.2660029 | D263: 4.5702642 | E263: 519.28943 | F263: 41.554981 | G263: 0.24184791 | H263: 0.57001071 | I263: 0.7082136 | J263: 20.644058

Sheet CurrentPor-N10Unchanged
C1: LH = 10 | G1: LH = 20 | H1: LH = 40 | I1: LH = 60 | J1: LH = 20
A2: DATE | C2: 1Y_Treasury | D2: 2Y_Treasury | E2: MSFT price | F2: Intel price | G2: Credit spread: sovereign (investment grade, or IG) | H2: Credit spread: sovereign (high yield, or HY) | I2: Credit Spread: Corporate(HY) | J2: Carbon Credits
A3: 45474 | B3: {=_xlfn._xlws.FILTER(A3, WEEKDAY(A3, 2) <= 5)} -> 45474 | C3: 4.2673967 | D3: 4.5673967 | E3: 521.43896 | F3: 36.962945 | G3: 0.51 | H3: 0.58622522 | I3: 0.1693 | J3: 20.644002
A4: 45475 | B4: {=_xlfn._xlws.FILTER(A4, WEEKDAY(A4, 2) <= 5)} -> 45475 | C4: 4.2673967 | D4: 4.5673967 | E4: 521.43896 | F4: 36.962945 | G4: 0.51 | H4: 0.66683919 | I4: 0.17030001 | J4: 20.644056
A5: 45476 | B5: {=_xlfn._xlws.FILTER(A5, WEEKDAY(A5, 2) <= 5)} -> 45476 | C5: 4.2673967 | D5: 4.5673967 | E5: 521.43896 | F5: 36.962945 | G5: 0.51 | H5: 0.5738683 | I5: 0.17120001 | J5: 20.644002
A6: 45477 | B6: {=_xlfn._xlws.FILTER(A6, WEEKDAY(A6, 2) <= 5)} -> 45477 | C6: 4.2673967 | D6: 4.5673967 | E6: 521.43896 | F6: 36.962945 | G6: 0.51 | H6: 0.55415584 | I6: 0.1799 | J6: 20.643982
A7: 45478 | B7: {=_xlfn._xlws.FILTER(A7, WEEKDAY(A7, 2) <= 5)} -> 45478 | C7: 4.2673967 | D7: 4.5673967 | E7: 521.43896 | F7: 36.962945 | G7: 0.5 | H7: 0.70278175 | I7: 0.16870001 | J7: 20.643926
A8: 45481 | B8: {=_xlfn._xlws.FILTER(A8, WEEKDAY(A8, 2) <= 5)} -> 45481 | C8: 4.2673967 | D8: 4.5673967 | E8: 521.43896 | F8: 36.962945 | G8: 0.52 | H8: 0.69285184 | I8: 0.17209999 | J8: 20.643945
A9: 45482 | B9: {=_xlfn._xlws.FILTER(A9, WEEKDAY(A9, 2) <= 5)} -> 45482 | C9: 4.2673967 | D9: 4.5673967 | E9: 521.43896 | F9: 36.962945 | G9: 0.52 | H9: 0.62109307 | I9: 0.18530001 | J9: 20.644019
A10: 45483 | B10: {=_xlfn._xlws.FILTER(A10, WEEKDAY(A10, 2) <= 5)} -> 45483 | C10: 4.2673967 | D10: 4.5673967 | E10: 521.43896 | F10: 36.962945 | G10: 0.51 | H10: 0.62999665 | I10: 0.20030001 | J10: 20.644012
A11: 45484 | B11: {=_xlfn._xlws.FILTER(A11, WEEKDAY(A11, 2) <= 5)} -> 45484 | C11: 4.2673967 | D11: 4.5673967 | E11: 521.43896 | F11: 36.962945 | G11: 0.51 | H11: 0.6105303 | I11: 0.19139999 | J11: 20.64394
A12: 45485 | B12: {=_xlfn._xlws.FILTER(A12, WEEKDAY(A12, 2) <= 5)} -> 45485 | C12: 4.2673967 | D12: 4.5673967 | E12: 521.43896 | F12: 36.962945 | G12: 0.51 | H12: 0.62792874 | I12: 0.17950001 | J12: 20.644027
A13: 45488 | B13: {=_xlfn._xlws.FILTER(A13, WEEKDAY(A13, 2) <= 5)} -> 45488 | C13: 4.2673967 | D13: 4.5673967 | E13: 521.43896 | F13: 36.962945 | G13: 0.48 | H13: 0.68700411 | I13: 0.1565 | J13: 20.64398
A14: 45489 | B14: {=_xlfn._xlws.FILTER(A14, WEEKDAY(A14, 2) <= 5)} -> 45489 | C14: 4.2673967 | D14: 4.5673967 | E14: 521.43896 | F14: 36.962945 | G14: 0.5 | H14: 0.54610546 | I14: 0.146 | J14: 20.643987
... A187: 45730 | B187: {=_xlfn._xlws.FILTER(A187, WEEKDAY(A187, 2) <= 5)} -> 45730 | C187: 4.2673967 | D187: 4.5673967 | E187: 521.43896 | F187: 36.962945 | G187: 0.34 | H187: 0.59979654 | I187: 0.1199 | J187: 20.643989
A188: 45733 | B188: 45733 | C188: 4.2673967 | D188: 4.5673967 | E188: 521.43896 | F188: 36.962945 | G188: 0.32999931 | H188: 0.43157288 | I188: 0.70088629 | J188: 20.644007
A189: 45734 | B189: 45734 | C189: 4.2673967 | D189: 4.5673967 | E189: 521.43896 | F189: 36.962945 | G189: 0.34192723 | H189: 0.66292372 | I189: 0.70231786 | J189: 20.644023
A190: 45735 | B190: 45735 | C190: 4.2673967 | D190: 4.5673967 | E190: 521.43896 | F190: 36.962945 | G190: 0.34562635 | H190: 0.50838655 | I190: 0.69270909 | J190: 20.64402
A191: 45736 | B191: 45736 | C191: 4.2673967 | D191: 4.5673967 | E191: 521.43896 | F191: 36.962945 | G191: 0.22857621 | H191: 0.57103235 | I191: 0.69588886 | J191: 20.644059
A192: 45737 | B192: 45737 | C192: 4.2673967 | D192: 4.5673967 | E192: 521.43896 | F192: 36.962945 | G192: 0.3645339 | H192: 0.55946806 | I192: 0.71396939 | J192: 20.643956
A193: 45740 | B193: 45740 | C193: 4.2673967 | D193: 4.5673967 | E193: 521.43896 | F193: 36.962945 | G193: 0.3294564 | H193: 0.58843681 | I193: 0.69846672 | J193: 20.644061
A194: 45741 | B194: 45741 | C194: 4.2673967 | D194: 4.5673967 | E194: 521.43896 | F194: 36.962945 | G194: 0.32413504 | H194: 0.55630345 | I194: 0.69976781 | J194: 20.643919
A195: 45742 | B195: 45742 | C195: 4.2673967 | D195: 4.5673967 | E195: 521.43896 | F195: 36.962945 | G195: 0.31860546 | H195: 0.60832137 | I195: 0.71379241 | J195: 20.644031
A196: 45743 | B196: 45743 | C196: 4.2673967 | D196: 4.5673967 | E196: 521.43896 | F196: 36.962945 | G196: 0.31363146 | H196: 0.5819883 | I196: 0.70190304 | J196: 20.643987
A197: 45744 | B197: 45744 | C197: 4.2673967 | D197: 4.5673967 | E197: 521.43896 | F197: 36.962945 | G197: 0.38175173 | H197: 0.60195799 | I197: 0.70470311 | J197: 20.644045
A198: 45747 | B198: 45747 | C198: 4.2673967 | D198: 4.5673967 | E198: 521.43896 | F198: 36.962945 | G198: 0.40592629 | H198: 0.51641148 | I198: 0.69118004 | J198: 20.644006
A199: 45748 | B199: 45748 | C199: 4.2673967 | D199: 4.5673967 | E199: 521.43896 | F199: 36.962945 | G199: 0.35998084 | H199: 0.63600457 | I199: 0.70525911 | J199: 20.644074
... A263: 45838 | B263: 45838 | C263: 4.2673967 | D263: 4.5673967 | E263: 521.43896 | F263: 36.962945 | G263: 0.24184791 | H263: 0.57001071 | I263: 0.7082136 | J263: 20.644058

Sheet CurrentFact-N10,20Unchanged
C1: LH = 10 | G1: LH = 20 | H1: LH = 40 | I1: LH = 60 | J1: LH = 20
A2: DATE | C2: 1Y_Treasury | D2: 2Y_Treasury | E2: MSFT price | F2: Intel price | G2: Credit spread: sovereign (investment grade, or IG) | H2: Credit spread: sovereign (high yield, or HY) | I2: Credit Spread: Corporate(HY) | J2: Carbon Credits
A3: 45474 | B3: {=_xlfn._xlws.FILTER(A3, WEEKDAY(A3, 2) <= 5)} -> 45474 | C3: 4.2673967 | D3: 4.5673967 | E3: 521.43896 | F3: 36.962945 | G3: 0.51 | H3: 0.58622522 | I3: 0.1693 | J3: 20.64455
A4: 45475 | B4: {=_xlfn._xlws.FILTER(A4, WEEKDAY(A4, 2) <= 5)} -> 45475 | C4: 4.2673967 | D4: 4.5673967 | E4: 521.43896 | F4: 36.962945 | G4: 0.51 | H4: 0.66683919 | I4: 0.17030001 | J4: 20.64455
A5: 45476 | B5: {=_xlfn._xlws.FILTER(A5, WEEKDAY(A5, 2) <= 5)} -> 45476 | C5: 4.2673967 | D5: 4.5673967 | E5: 521.43896 | F5: 36.962945 | G5: 0.51 | H5: 0.5738683 | I5: 0.17120001 | J5: 20.64455
A6: 45477 | B6: {=_xlfn._xlws.FILTER(A6, WEEKDAY(A6, 2) <= 5)} -> 45477 | C6: 4.2673967 | D6: 4.5673967 | E6: 521.43896 | F6: 36.962945 | G6: 0.51 | H6: 0.55415584 | I6: 0.1799 | J6: 20.64455
A7: 45478 | B7: {=_xlfn._xlws.FILTER(A7, WEEKDAY(A7, 2) <= 5)} -> 45478 | C7: 4.2673967 | D7: 4.5673967 | E7: 521.43896 | F7: 36.962945 | G7: 0.51 | H7: 0.70278175 | I7: 0.16870001 | J7: 20.64455
A8: 45481 | B8: {=_xlfn._xlws.FILTER(A8, WEEKDAY(A8, 2) <= 5)} -> 45481 | C8: 4.2673967 | D8: 4.5673967 | E8: 521.43896 | F8: 36.962945 | G8: 0.51 | H8: 0.69285184 | I8: 0.17209999 | J8: 20.64455
A9: 45482 | B9: {=_xlfn._xlws.FILTER(A9, WEEKDAY(A9, 2) <= 5)} -> 45482 | C9: 4.2673967 | D9: 4.5673967 | E9: 521.43896 | F9: 36.962945 | G9: 0.51 | H9: 0.62109307 | I9: 0.18530001 | J9: 20.64455
A10: 45483 | B10: {=_xlfn._xlws.FILTER(A10, WEEKDAY(A10, 2) <= 5)} -> 45483 | C10: 4.2673967 | D10: 4.5673967 | E10: 521.43896 | F10: 36.962945 | G10: 0.51 | H10: 0.62999665 | I10: 0.20030001 | J10: 20.64455
A11: 45484 | B11: {=_xlfn._xlws.FILTER(A11, WEEKDAY(A11, 2) <= 5)} -> 45484 | C11: 4.2673967 | D11: 4.5673967 | E11: 521.43896 | F11: 36.962945 | G11: 0.51 | H11: 0.6105303 | I11: 0.19139999 | J11: 20.64455
A12: 45485 | B12: {=_xlfn._xlws.FILTER(A12, WEEKDAY(A12, 2) <= 5)} -> 45485 | C12: 4.2673967 | D12: 4.5673967 | E12: 521.43896 | F12: 36.962945 | G12: 0.51 | H12: 0.62792874 | I12: 0.17950001 | J12: 20.64455
A13: 45488 | B13: {=_xlfn._xlws.FILTER(A13, WEEKDAY(A13, 2) <= 5)} -> 45488 | C13: 4.2673967 | D13: 4.5673967 | E13: 521.43896 | F13: 36.962945 | G13: 0.51 | H13: 0.68700411 | I13: 0.1565 | J13: 20.64455
A14: 45489 | B14: {=_xlfn._xlws.FILTER(A14, WEEKDAY(A14, 2) <= 5)} -> 45489 | C14: 4.2673967 | D14: 4.5673967 | E14: 521.43896 | F14: 36.962945 | G14: 0.51 | H14: 0.54610546 | I14: 0.146 | J14: 20.64455
... A187: 45730 | B187: {=_xlfn._xlws.FILTER(A187, WEEKDAY(A187, 2) <= 5)} -> 45730 | C187: 4.2673967 | D187: 4.5673967 | E187: 521.43896 | F187: 36.962945 | G187: 0.51 | H187: 0.59979654 | I187: 0.1199 | J187: 20.64455
A188: 45733 | B188: 45733 | C188: 4.2673967 | D188: 4.5673967 | E188: 521.43896 | F188: 36.962945 | G188: 0.51 | H188: 0.43157288 | I188: 0.70088629 | J188: 20.64455
A189: 45734 | B189: 45734 | C189: 4.2673967 | D189: 4.5673967 | E189: 521.43896 | F189: 36.962945 | G189: 0.51 | H189: 0.66292372 | I189: 0.70231786 | J189: 20.64455
A190: 45735 | B190: 45735 | C190: 4.2673967 | D190: 4.5673967 | E190: 521.43896 | F190: 36.962945 | G190: 0.51 | H190: 0.50838655 | I190: 0.69270909 | J190: 20.64455
A191: 45736 | B191: 45736 | C191: 4.2673967 | D191: 4.5673967 | E191: 521.43896 | F191: 36.962945 | G191: 0.51 | H191: 0.57103235 | I191: 0.69588886 | J191: 20.64455
A192: 45737 | B192: 45737 | C192: 4.2673967 | D192: 4.5673967 | E192: 521.43896 | F192: 36.962945 | G192: 0.51 | H192: 0.55946806 | I192: 0.71396939 | J192: 20.64455
A193: 45740 | B193: 45740 | C193: 4.2673967 | D193: 4.5673967 | E193: 521.43896 | F193: 36.962945 | G193: 0.51 | H193: 0.58843681 | I193: 0.69846672 | J193: 20.64455
A194: 45741 | B194: 45741 | C194: 4.2673967 | D194: 4.5673967 | E194: 521.43896 | F194: 36.962945 | G194: 0.51 | H194: 0.55630345 | I194: 0.69976781 | J194: 20.64455
A195: 45742 | B195: 45742 | C195: 4.2673967 | D195: 4.5673967 | E195: 521.43896 | F195: 36.962945 | G195: 0.51 | H195: 0.60832137 | I195: 0.71379241 | J195: 20.64455
A196: 45743 | B196: 45743 | C196: 4.2673967 | D196: 4.5673967 | E196: 521.43896 | F196: 36.962945 | G196: 0.51 | H196: 0.5819883 | I196: 0.70190304 | J196: 20.64455
A197: 45744 | B197: 45744 | C197: 4.2673967 | D197: 4.5673967 | E197: 521.43896 | F197: 36.962945 | G197: 0.51 | H197: 0.60195799 | I197: 0.70470311 | J197: 20.64455
A198: 45747 | B198: 45747 | C198: 4.2673967 | D198: 4.5673967 | E198: 521.43896 | F198: 36.962945 | G198: 0.51 | H198: 0.51641148 | I198: 0.69118004 | J198: 20.64455
A199: 45748 | B199: 45748 | C199: 4.2673967 | D199: 4.5673967 | E199: 521.43896 | F199: 36.962945 | G199: 0.51 | H199: 0.63600457 | I199: 0.70525911 | J199: 20.64455
... A263: 45838 | B263: 45838 | C263: 4.2673967 | D263: 4.5673967 | E263: 521.43896 | F263: 36.962945 | G263: 0.51 | H263: 0.57001071 | I263: 0.7082136 | J263: 20.64455

Sheet CurrentFact-N10,20,40Unchanged
C1: LH = 10 | G1: LH = 20 | H1: LH = 40 | I1: LH = 60 | J1: LH = 20
A2: DATE | C2: 1Y_Treasury | D2: 2Y_Treasury | E2: MSFT price | F2: Intel price | G2: Credit spread: sovereign (investment grade, or IG) | H2: Credit spread: sovereign (high yield, or HY) | I2: Credit Spread: Corporate(HY) | J2: Carbon Credits
A3: 45474 | B3: {=_xlfn._xlws.FILTER(A3, WEEKDAY(A3, 2) <= 5)} -> 45474 | C3: 4.2673967 | D3: 4.5673967 | E3: 521.43896 | F3: 36.962945 | G3: 0.51 | H3: 0.58622522 | I3: 0.1693 | J3: 20.64455
A4: 45475 | B4: {=_xlfn._xlws.FILTER(A4, WEEKDAY(A4, 2) <= 5)} -> 45475 | C4: 4.2673967 | D4: 4.5673967 | E4: 521.43896 | F4: 36.962945 | G4: 0.51 | H4: 0.58622522 | I4: 0.17030001 | J4: 20.64455
A5: 45476 | B5: {=_xlfn._xlws.FILTER(A5, WEEKDAY(A5, 2) <= 5)} -> 45476 | C5: 4.2673967 | D5: 4.5673967 | E5: 521.43896 | F5: 36.962945 | G5: 0.51 | H5: 0.58622522 | I5: 0.17120001 | J5: 20.64455
A6: 45477 | B6: {=_xlfn._xlws.FILTER(A6, WEEKDAY(A6, 2) <= 5)} -> 45477 | C6: 4.2673967 | D6: 4.5673967 | E6: 521.43896 | F6: 36.962945 | G6: 0.51 | H6: 0.58622522 | I6: 0.1799 | J6: 20.64455
A7: 45478 | B7: {=_xlfn._xlws.FILTER(A7, WEEKDAY(A7, 2) <= 5)} -> 45478 | C7: 4.2673967 | D7: 4.5673967 | E7: 521.43896 | F7: 36.962945 | G7: 0.51 | H7: 0.58622522 | I7: 0.16870001 | J7: 20.64455
A8: 45481 | B8: {=_xlfn._xlws.FILTER(A8, WEEKDAY(A8, 2) <= 5)} -> 45481 | C8: 4.2673967 | D8: 4.5673967 | E8: 521.43896 | F8: 36.962945 | G8: 0.51 | H8: 0.58622522 | I8: 0.17209999 | J8: 20.64455
A9: 45482 | B9: {=_xlfn._xlws.FILTER(A9, WEEKDAY(A9, 2) <= 5)} -> 45482 | C9: 4.2673967 | D9: 4.5673967 | E9: 521.43896 | F9: 36.962945 | G9: 0.51 | H9: 0.58622522 | I9: 0.18530001 | J9: 20.64455
A10: 45483 | B10: {=_xlfn._xlws.FILTER(A10, WEEKDAY(A10, 2) <= 5)} -> 45483 | C10: 4.2673967 | D10: 4.5673967 | E10: 521.43896 | F10: 36.962945 | G10: 0.51 | H10: 0.58622522 | I10: 0.20030001 | J10: 20.64455
A11: 45484 | B11: {=_xlfn._xlws.FILTER(A11, WEEKDAY(A11, 2) <= 5)} -> 45484 | C11: 4.2673967 | D11: 4.5673967 | E11: 521.43896 | F11: 36.962945 | G11: 0.51 | H11: 0.58622522 | I11: 0.19139999 | J11: 20.64455
A12: 45485 | B12: {=_xlfn._xlws.FILTER(A12, WEEKDAY(A12, 2) <= 5)} -> 45485 | C12: 4.2673967 | D12: 4.5673967 | E12: 521.43896 | F12: 36.962945 | G12: 0.51 | H12: 0.58622522 | I12: 0.17950001 | J12: 20.64455
A13: 45488 | B13: {=_xlfn._xlws.FILTER(A13, WEEKDAY(A13, 2) <= 5)} -> 45488 | C13: 4.2673967 | D13: 4.5673967 | E13: 521.43896 | F13: 36.962945 | G13: 0.51 | H13: 0.58622522 | I13: 0.1565 | J13: 20.64455
A14: 45489 | B14: {=_xlfn._xlws.FILTER(A14, WEEKDAY(A14, 2) <= 5)} -> 45489 | C14: 4.2673967 | D14: 4.5673967 | E14: 521.43896 | F14: 36.962945 | G14: 0.51 | H14: 0.58622522 | I14: 0.146 | J14: 20.64455
... A187: 45730 | B187: {=_xlfn._xlws.FILTER(A187, WEEKDAY(A187, 2) <= 5)} -> 45730 | C187: 4.2673967 | D187: 4.5673967 | E187: 521.43896 | F187: 36.962945 | G187: 0.51 | H187: 0.58622522 | I187: 0.1199 | J187: 20.64455
A188: 45733 | B188: 45733 | C188: 4.2673967 | D188: 4.5673967 | E188: 521.43896 | F188: 36.962945 | G188: 0.51 | H188: 0.58622522 | I188: 0.70088629 | J188: 20.64455
A189: 45734 | B189: 45734 | C189: 4.2673967 | D189: 4.5673967 | E189: 521.43896 | F189: 36.962945 | G189: 0.51 | H189: 0.58622522 | I189: 0.70231786 | J189: 20.64455
A190: 45735 | B190: 45735 | C190: 4.2673967 | D190: 4.5673967 | E190: 521.43896 | F190: 36.962945 | G190: 0.51 | H190: 0.58622522 | I190: 0.69270909 | J190: 20.64455
A191: 45736 | B191: 45736 | C191: 4.2673967 | D191: 4.5673967 | E191: 521.43896 | F191: 36.962945 | G191: 0.51 | H191: 0.58622522 | I191: 0.69588886 | J191: 20.64455
A192: 45737 | B192: 45737 | C192: 4.2673967 | D192: 4.5673967 | E192: 521.43896 | F192: 36.962945 | G192: 0.51 | H192: 0.58622522 | I192: 0.71396939 | J192: 20.64455
A193: 45740 | B193: 45740 | C193: 4.2673967 | D193: 4.5673967 | E193: 521.43896 | F193: 36.962945 | G193: 0.51 | H193: 0.58622522 | I193: 0.69846672 | J193: 20.64455
A194: 45741 | B194: 45741 | C194: 4.2673967 | D194: 4.5673967 | E194: 521.43896 | F194: 36.962945 | G194: 0.51 | H194: 0.58622522 | I194: 0.69976781 | J194: 20.64455
A195: 45742 | B195: 45742 | C195: 4.2673967 | D195: 4.5673967 | E195: 521.43896 | F195: 36.962945 | G195: 0.51 | H195: 0.58622522 | I195: 0.71379241 | J195: 20.64455
A196: 45743 | B196: 45743 | C196: 4.2673967 | D196: 4.5673967 | E196: 521.43896 | F196: 36.962945 | G196: 0.51 | H196: 0.58622522 | I196: 0.70190304 | J196: 20.64455
A197: 45744 | B197: 45744 | C197: 4.2673967 | D197: 4.5673967 | E197: 521.43896 | F197: 36.962945 | G197: 0.51 | H197: 0.58622522 | I197: 0.70470311 | J197: 20.64455
A198: 45747 | B198: 45747 | C198: 4.2673967 | D198: 4.5673967 | E198: 521.43896 | F198: 36.962945 | G198: 0.51 | H198: 0.58622522 | I198: 0.69118004 | J198: 20.64455
A199: 45748 | B199: 45748 | C199: 4.2673967 | D199: 4.5673967 | E199: 521.43896 | F199: 36.962945 | G199: 0.51 | H199: 0.58622522 | I199: 0.70525911 | J199: 20.64455
... A263: 45838 | B263: 45838 | C263: 4.2673967 | D263: 4.5673967 | E263: 521.43896 | F263: 36.962945 | G263: 0.51 | H263: 0.58622522 | I263: 0.7082136 | J263: 20.64455

Sheet CurrentFact-N10,20,40,60Unchan
C1: LH = 10 | G1: LH = 20 | H1: LH = 40 | I1: LH = 60 | J1: LH = 20
A2: DATE | C2: 1Y_Treasury | D2: 2Y_Treasury | E2: MSFT price | F2: Intel price | G2: Credit spread: sovereign (investment grade, or IG) | H2: Credit spread: sovereign (high yield, or HY) | I2: Credit Spread: Corporate(HY) | J2: Carbon Credits
A3: 45474 | B3: {=_xlfn._xlws.FILTER(A3, WEEKDAY(A3, 2) <= 5)} -> 45474 | C3: 4.2673967 | D3: 4.5673967 | E3: 521.43896 | F3: 36.962945 | G3: 0.51 | H3: 0.58622522 | I3: 0.1693 | J3: 20.64455
A4: 45475 | B4: {=_xlfn._xlws.FILTER(A4, WEEKDAY(A4, 2) <= 5)} -> 45475 | C4: 4.2673967 | D4: 4.5673967 | E4: 521.43896 | F4: 36.962945 | G4: 0.51 | H4: 0.58622522 | I4: 0.1693 | J4: 20.64455
A5: 45476 | B5: {=_xlfn._xlws.FILTER(A5, WEEKDAY(A5, 2) <= 5)} -> 45476 | C5: 4.2673967 | D5: 4.5673967 | E5: 521.43896 | F5: 36.962945 | G5: 0.51 | H5: 0.58622522 | I5: 0.1693 | J5: 20.64455
A6: 45477 | B6: {=_xlfn._xlws.FILTER(A6, WEEKDAY(A6, 2) <= 5)} -> 45477 | C6: 4.2673967 | D6: 4.5673967 | E6: 521.43896 | F6: 36.962945 | G6: 0.51 | H6: 0.58622522 | I6: 0.1693 | J6: 20.64455
A7: 45478 | B7: {=_xlfn._xlws.FILTER(A7, WEEKDAY(A7, 2) <= 5)} -> 45478 | C7: 4.2673967 | D7: 4.5673967 | E7: 521.43896 | F7: 36.962945 | G7: 0.51 | H7: 0.58622522 | I7: 0.1693 | J7: 20.64455
A8: 45481 | B8: {=_xlfn._xlws.FILTER(A8, WEEKDAY(A8, 2) <= 5)} -> 45481 | C8: 4.2673967 | D8: 4.5673967 | E8: 521.43896 | F8: 36.962945 | G8: 0.51 | H8: 0.58622522 | I8: 0.1693 | J8: 20.64455
A9: 45482 | B9: {=_xlfn._xlws.FILTER(A9, WEEKDAY(A9, 2) <= 5)} -> 45482 | C9: 4.2673967 | D9: 4.5673967 | E9: 521.43896 | F9: 36.962945 | G9: 0.51 | H9: 0.58622522 | I9: 0.1693 | J9: 20.64455
A10: 45483 | B10: {=_xlfn._xlws.FILTER(A10, WEEKDAY(A10, 2) <= 5)} -> 45483 | C10: 4.2673967 | D10: 4.5673967 | E10: 521.43896 | F10: 36.962945 | G10: 0.51 | H10: 0.58622522 | I10: 0.1693 | J10: 20.64455
A11: 45484 | B11: {=_xlfn._xlws.FILTER(A11, WEEKDAY(A11, 2) <= 5)} -> 45484 | C11: 4.2673967 | D11: 4.5673967 | E11: 521.43896 | F11: 36.962945 | G11: 0.51 | H11: 0.58622522 | I11: 0.1693 | J11: 20.64455
A12: 45485 | B12: {=_xlfn._xlws.FILTER(A12, WEEKDAY(A12, 2) <= 5)} -> 45485 | C12: 4.2673967 | D12: 4.5673967 | E12: 521.43896 | F12: 36.962945 | G12: 0.51 | H12: 0.58622522 | I12: 0.1693 | J12: 20.64455
A13: 45488 | B13: {=_xlfn._xlws.FILTER(A13, WEEKDAY(A13, 2) <= 5)} -> 45488 | C13: 4.2673967 | D13: 4.5673967 | E13: 521.43896 | F13: 36.962945 | G13: 0.51 | H13: 0.58622522 | I13: 0.1693 | J13: 20.64455
A14: 45489 | B14: {=_xlfn._xlws.FILTER(A14, WEEKDAY(A14, 2) <= 5)} -> 45489 | C14: 4.2673967 | D14: 4.5673967 | E14: 521.43896 | F14: 36.962945 | G14: 0.51 | H14: 0.58622522 | I14: 0.1693 | J14: 20.64455
... A187: 45730 | B187: {=_xlfn._xlws.FILTER(A187, WEEKDAY(A187, 2) <= 5)} -> 45730 | C187: 4.2673967 | D187: 4.5673967 | E187: 521.43896 | F187: 36.962945 | G187: 0.51 | H187: 0.58622522 | I187: 0.1693 | J187: 20.64455
A188: 45733 | B188: 45733 | C188: 4.2673967 | D188: 4.5673967 | E188: 521.43896 | F188: 36.962945 | G188: 0.51 | H188: 0.58622522 | I188: 0.1693 | J188: 20.64455
A189: 45734 | B189: 45734 | C189: 4.2673967 | D189: 4.5673967 | E189: 521.43896 | F189: 36.962945 | G189: 0.51 | H189: 0.58622522 | I189: 0.1693 | J189: 20.64455
A190: 45735 | B190: 45735 | C190: 4.2673967 | D190: 4.5673967 | E190: 521.43896 | F190: 36.962945 | G190: 0.51 | H190: 0.58622522 | I190: 0.1693 | J190: 20.64455
A191: 45736 | B191: 45736 | C191: 4.2673967 | D191: 4.5673967 | E191: 521.43896 | F191: 36.962945 | G191: 0.51 | H191: 0.58622522 | I191: 0.1693 | J191: 20.64455
A192: 45737 | B192: 45737 | C192: 4.2673967 | D192: 4.5673967 | E192: 521.43896 | F192: 36.962945 | G192: 0.51 | H192: 0.58622522 | I192: 0.1693 | J192: 20.64455
A193: 45740 | B193: 45740 | C193: 4.2673967 | D193: 4.5673967 | E193: 521.43896 | F193: 36.962945 | G193: 0.51 | H193: 0.58622522 | I193: 0.1693 | J193: 20.64455
A194: 45741 | B194: 45741 | C194: 4.2673967 | D194: 4.5673967 | E194: 521.43896 | F194: 36.962945 | G194: 0.51 | H194: 0.58622522 | I194: 0.1693 | J194: 20.64455
A195: 45742 | B195: 45742 | C195: 4.2673967 | D195: 4.5673967 | E195: 521.43896 | F195: 36.962945 | G195: 0.51 | H195: 0.58622522 | I195: 0.1693 | J195: 20.64455
A196: 45743 | B196: 45743 | C196: 4.2673967 | D196: 4.5673967 | E196: 521.43896 | F196: 36.962945 | G196: 0.51 | H196: 0.58622522 | I196: 0.1693 | J196: 20.64455
A197: 45744 | B197: 45744 | C197: 4.2673967 | D197: 4.5673967 | E197: 521.43896 | F197: 36.962945 | G197: 0.51 | H197: 0.58622522 | I197: 0.1693 | J197: 20.64455
A198: 45747 | B198: 45747 | C198: 4.2673967 | D198: 4.5673967 | E198: 521.43896 | F198: 36.962945 | G198: 0.51 | H198: 0.58622522 | I198: 0.1693 | J198: 20.64455
A199: 45748 | B199: 45748 | C199: 4.2673967 | D199: 4.5673967 | E199: 521.43896 | F199: 36.962945 | G199: 0.51 | H199: 0.58622522 | I199: 0.1693 | J199: 20.64455
... A263: 45838 | B263: 45838 | C263: 4.2673967 | D263: 4.5673967 | E263: 521.43896 | F263: 36.962945 | G263: 0.51 | H263: 0.58622522 | I263: 0.1693 | J263: 20.64455

Sheet Portfolio
A1: Holding | B1: Quantity | C1: Coupon | D1: Notional | E1: Price | F1: Total | J1: T | N1: LH | O1: ES | P1: Absolute ES | Q1: Calculated value
A2: Treasury bonds | B2: 100 | C2: 3 | D2: 100 | F2: =B2*D2 -> 10000 | J2: 10 | M2: EST(P) | N2: 10 | O2: ='ES, All factor movement'!L3 -> -992.45414 | P2: =ABS(O2) -> 992.45414 | Q2: =P2*P2 -> 984965.22
A3: Sovereign Bonds HY | B3: 100 | C3: 3 | D3: 100 | F3: =B3*D3 -> 10000 | M3: EST(P,2) | N3: 20 | O3: ='ES,N10 unchanged'!L3 -> -104.17405 | P3: =ABS(O3) -> 104.17405 | Q3: =POWER(P3*SQRT(10/10),2) -> 10852.233
A4: Sovereign Bonds IG | B4: 100 | C4: 3 | D4: 100 | F4: =B4*D4 -> 10000 | M4: EST(P,3) | N4: 40 | O4: ='ES,N10,20 unchanged'!L3 -> -102.76959 | P4: =ABS(O4) -> 102.76959 | Q4: =POWER(P4*SQRT(20/10),2) -> 21123.179
A5: MSFT stocks | B5: 100 | E5: 500 | F5: =B5*E5 -> 50000 | M5: EST(P,4) | N5: 60 | O5: ='ES,N10,20,40 unchanged'!L3 -> -104.1336 | P5: =ABS(O5) -> 104.1336 | Q5: =POWER(P5*SQRT(20/10),2) -> 21687.614
A6: Intel Stock | B6: 100 | E6: 36 | F6: =B6*E6 -> 3600 | P6: ESF,C | Q6: =SQRT(SUM(Q2:Q5)) -> 1019.1311
A7: Carbon credits | B7: 100 | E7: 20 | F7: =B7*E7 -> 2000
A8: Credit Spread Corporate HY | B8: 100 | C8: 3 | D8: 100 | F8: =B8*D8 -> 10000
F9: =SUM(F2:F8) -> 95600

Sheet ES, All factor movement
B1: LH=10 | C1: LH=10, 20 | D1: LH=10, 40 | E1: LH=10, 60 | F1: LH=10 | G1: LH=10 | H1: LH=20
B2: Treasury Bonds IG valuation | C2: Credit spread: Sovereign Bonds IG valuation | D2: Credit spread: sovereign (high yield, or HY) | E2: Credit Spread:Corporate HY | F2: MSFT | G2: Intel | H2: carbon credits | I2: Portfolio value | J2: 10 day PnL | K2: VaR | L2: ES, Q(pi,1)
A3: 45474 | B3: =(3/(1+('CurrentPor-All Factor Movements'!C3)/100)+103/POWER(1+('CurrentPor-All Factor Movements'!D3)/100,2))*100 -> 9707.5858 | C3: =(3/(1+('CurrentPor-All Factor Movements'!C3+'CurrentPor-All Factor Movements'!G3)/100)+103/POWER(1+('CurrentPor-All Factor Movements'!D3+'CurrentPor-All Factor Movements'!G3)/100,2))*100 -> 9614.9674 | D3: =(3/(1+('CurrentPor-All Factor Movements'!C3+'CurrentPor-All Factor Movements'!H3)/100)+103/POWER(1+('CurrentPor-All Factor Movements'!D3+'CurrentPor-All Factor Movements'!H3)/100,2))*100 -> 9601.2396 | E3: =(3/(1+('CurrentPor-All Factor Movements'!C3+'CurrentPor-All Factor Movements'!I3)/100)+103/POWER(1+('CurrentPor-All Factor Movements'!D3+'CurrentPor-All Factor Movements'!I3)/100,2))*100 -> 9581.4547 | F3: =Portfolio!B$5*'CurrentPor-All Factor Movements'!E3 -> 52143.896 | G3: =Portfolio!B$6*'CurrentPor-All Factor Movements'!F3 -> 3696.2945 | H3: =Portfolio!B$7*'CurrentPor-All Factor Movements'!J3 -> 2064.4002 | I3: =SUM(B3:H3) -> 96409.838 | K3: =_xlfn.PERCENTILE.INC(J13:J263, 0.025) -> -809.31275 | L3: =AVERAGEIF(J13:J263, "<="&K3,J13:J263) -> -992.45414
A4: 45475 | B4: =(3/(1+('CurrentPor-All Factor Movements'!C4)/100)+103/POWER(1+('CurrentPor-All Factor Movements'!D4)/100,2))*100 -> 9707.2252 | C4: =(3/(1+('CurrentPor-All Factor Movements'!C4+'CurrentPor-All Factor Movements'!G4)/100)+103/POWER(1+('CurrentPor-All Factor Movements'!D4+'CurrentPor-All Factor Movements'!G4)/100,2))*100 -> 9614.6119 | D4: =(3/(1+('CurrentPor-All Factor Movements'!C4+'CurrentPor-All Factor Movements'!H4)/100)+103/POWER(1+('CurrentPor-All Factor Movements'!D4+'CurrentPor-All Factor Movements'!H4)/100,2))*100 -> 9586.3998 | E4: =(3/(1+('CurrentPor-All Factor Movements'!C4+'CurrentPor-All Factor Movements'!I4)/100)+103/POWER(1+('CurrentPor-All Factor Movements'!D4+'CurrentPor-All Factor Movements'!I4)/100,2))*100 -> 9578.8216 | F4: =Portfolio!B$5*'CurrentPor-All Factor Movements'!E4 -> 52287.989 | G4: =Portfolio!B$6*'CurrentPor-All Factor Movements'!F4 -> 3678.0622 | H4: =Portfolio!B$7*'CurrentPor-All Factor Movements'!J4 -> 2064.4056 | I4: =SUM(B4:H4) -> 96517.515
A5: 45476 | B5: =(3/(1+('CurrentPor-All Factor Movements'!C5)/100)+103/POWER(1+('CurrentPor-All Factor Movements'!D5)/100,2))*100 -> 9708.8487 | C5: =(3/(1+('CurrentPor-All Factor Movements'!C5+'CurrentPor-All Factor Movements'!G5)/100)+103/POWER(1+('CurrentPor-All Factor Movements'!D5+'CurrentPor-All Factor Movements'!G5)/100,2))*100 -> 9616.2121 | D5: =(3/(1+('CurrentPor-All Factor Movements'!C5+'CurrentPor-All Factor Movements'!H5)/100)+103/POWER(1+('CurrentPor-All Factor Movements'!D5+'CurrentPor-All Factor Movements'!H5)/100,2))*100 -> 9604.7054 | E5: =(3/(1+('CurrentPor-All Factor Movements'!C5+'CurrentPor-All Factor Movements'!I5)/100)+103/POWER(1+('CurrentPor-All Factor Movements'!D5+'CurrentPor-All Factor Movements'!I5)/100,2))*100 -> 9581.7295 | F5: =Portfolio!B$5*'CurrentPor-All Factor Movements'!E5 -> 52263.871 | G5: =Portfolio!B$6*'CurrentPor-All Factor Movements'!F5 -> 3364.9896 | H5: =Portfolio!B$7*'CurrentPor-All Factor Movements'!J5 -> 2064.4002 | I5: =SUM(B5:H5) -> 96204.757
A6: 45477 | B6: =(3/(1+('CurrentPor-All Factor Movements'!C6)/100)+103/POWER(1+('CurrentPor-All Factor Movements'!D6)/100,2))*100 -> 9707.6654 | C6: =(3/(1+('CurrentPor-All Factor Movements'!C6+'CurrentPor-All Factor Movements'!G6)/100)+103/POWER(1+('CurrentPor-All Factor Movements'!D6+'CurrentPor-All Factor Movements'!G6)/100,2))*100 -> 9615.0458 | D6: =(3/(1+('CurrentPor-All Factor Movements'!C6+'CurrentPor-All Factor Movements'!H6)/100)+103/POWER(1+('CurrentPor-All Factor Movements'!D6+'CurrentPor-All Factor Movements'!H6)/100,2))*100 -> 9607.0898 | E6: =(3/(1+('CurrentPor-All Factor Movements'!C6+'CurrentPor-All Factor Movements'!I6)/100)+103/POWER(1+('CurrentPor-All Factor Movements'!D6+'CurrentPor-All Factor Movements'!I6)/100,2))*100 -> 9583.6685 | F6: =Portfolio!B$5*'CurrentPor-All Factor Movements'!E6 -> 52330.347 | G6: =Portfolio!B$6*'CurrentPor-All Factor Movements'!F6 -> 3708.1656 | H6: =Portfolio!B$7*'CurrentPor-All Factor Movements'!J6 -> 2064.3982 | I6: =SUM(B6:H6) -> 96616.381
A7: 45478 | B7: =(3/(1+('CurrentPor-All Factor Movements'!C7)/100)+103/POWER(1+('CurrentPor-All Factor Movements'!D7)/100,2))*100 -> 9705.9763 | C7: =(3/(1+('CurrentPor-All Factor Movements'!C7+'CurrentPor-All Factor Movements'!G7)/100)+103/POWER(1+('CurrentPor-All Factor Movements'!D7+'CurrentPor-All Factor Movements'!G7)/100,2))*100 -> 9615.1838 | D7: =(3/(1+('CurrentPor-All Factor Movements'!C7+'CurrentPor-All Factor Movements'!H7)/100)+103/POWER(1+('CurrentPor-All Factor Movements'!D7+'CurrentPor-All Factor Movements'!H7)/100,2))*100 -> 9578.728 | E7: =(3/(1+('CurrentPor-All Factor Movements'!C7+'CurrentPor-All Factor Movements'!I7)/100)+103/POWER(1+('CurrentPor-All Factor Movements'!D7+'CurrentPor-All Factor Movements'!I7)/100,2))*100 -> 9577.9665 | F7: =Portfolio!B$5*'CurrentPor-All Factor Movements'!E7 -> 52065.488 | G7: =Portfolio!B$6*'CurrentPor-All Factor Movements'!F7 -> 3885.4788 | H7: =Portfolio!B$7*'CurrentPor-All Factor Movements'!J7 -> 2064.3926 | I7: =SUM(B7:H7) -> 96493.214
A8: 45481 | B8: =(3/(1+('CurrentPor-All Factor Movements'!C8)/100)+103/POWER(1+('CurrentPor-All Factor Movements'!D8)/100,2))*100 -> 9705.7465 | C8: =(3/(1+('CurrentPor-All Factor Movements'!C8+'CurrentPor-All Factor Movements'!G8)/100)+103/POWER(1+('CurrentPor-All Factor Movements'!D8+'CurrentPor-All Factor Movements'!G8)/100,2))*100 -> 9611.3525 | D8: =(3/(1+('CurrentPor-All Factor Movements'!C8+'CurrentPor-All Factor Movements'!H8)/100)+103/POWER(1+('CurrentPor-All Factor Movements'!D8+'CurrentPor-All Factor Movements'!H8)/100,2))*100 -> 9580.283 | E8: =(3/(1+('CurrentPor-All Factor Movements'!C8+'CurrentPor-All Factor Movements'!I8)/100)+103/POWER(1+('CurrentPor-All Factor Movements'!D8+'CurrentPor-All Factor Movements'!I8)/100,2))*100 -> 9578.6643 | F8: =Portfolio!B$5*'CurrentPor-All Factor Movements'!E8 -> 52418.643 | G8: =Portfolio!B$6*'CurrentPor-All Factor Movements'!F8 -> 3991.5108 | H8: =Portfolio!B$7*'CurrentPor-All Factor Movements'!J8 -> 2064.3945 | I8: =SUM(B8:H8) -> 96950.594
A9: 45482 | B9: =(3/(1+('CurrentPor-All Factor Movements'!C9)/100)+103/POWER(1+('CurrentPor-All Factor Movements'!D9)/100,2))*100 -> 9707.8035 | C9: =(3/(1+('CurrentPor-All Factor Movements'!C9+'CurrentPor-All Factor Movements'!G9)/100)+103/POWER(1+('CurrentPor-All Factor Movements'!D9+'CurrentPor-All Factor Movements'!G9)/100,2))*100 -> 9613.3793 | D9: =(3/(1+('CurrentPor-All Factor Movements'!C9+'CurrentPor-All Factor Movements'!H9)/100)+103/POWER(1+('CurrentPor-All Factor Movements'!D9+'CurrentPor-All Factor Movements'!H9)/100,2))*100 -> 9595.1839 | E9: =(3/(1+('CurrentPor-All Factor Movements'!C9+'CurrentPor-All Factor Movements'!I9)/100)+103/POWER(1+('CurrentPor-All Factor Movements'!D9+'CurrentPor-All Factor Movements'!I9)/100,2))*100 -> 9581.1781 | F9: =Portfolio!B$5*'CurrentPor-All Factor Movements'!E9 -> 52676.26 | G9: =Portfolio!B$6*'CurrentPor-All Factor Movements'!F9 -> 3882.6037 | H9: =Portfolio!B$7*'CurrentPor-All Factor Movements'!J9 -> 2064.4019 | I9: =SUM(B9:H9) -> 97120.811
A10: 45483 | B10: =(3/(1+('CurrentPor-All Factor Movements'!C10)/100)+103/POWER(1+('CurrentPor-All Factor Movements'!D10)/100,2))*100 -> 9707.1361 | C10: =(3/(1+('CurrentPor-All Factor Movements'!C10+'CurrentPor-All Factor Movements'!G10)/100)+103/POWER(1+('CurrentPor-All Factor Movements'!D10+'CurrentPor-All Factor Movements'!G10)/100,2))*100 -> 9614.5241 | D10: =(3/(1+('CurrentPor-All Factor Movements'!C10+'CurrentPor-All Factor Movements'!H10)/100)+103/POWER(1+('CurrentPor-All Factor Movements'!D10+'CurrentPor-All Factor Movements'!H10)/100,2))*100 -> 9592.9282 | E10: =(3/(1+('CurrentPor-All Factor Movements'!C10+'CurrentPor-All Factor Movements'!I10)/100)+103/POWER(1+('CurrentPor-All Factor Movements'!D10+'CurrentPor-All Factor Movements'!I10)/100,2))*100 -> 9579.9458 | F10: =Portfolio!B$5*'CurrentPor-All Factor Movements'!E10 -> 52648.411 | G10: =Portfolio!B$6*'CurrentPor-All Factor Movements'!F10 -> 4055.9422 | H10: =Portfolio!B$7*'CurrentPor-All Factor Movements'!J10 -> 2064.4012 | I10: =SUM(B10:H10) -> 97263.288
A11: 45484 | B11: =(3/(1+('CurrentPor-All Factor Movements'!C11)/100)+103/POWER(1+('CurrentPor-All Factor Movements'!D11)/100,2))*100 -> 9706.6404 | C11: =(3/(1+('CurrentPor-All Factor Movements'!C11+'CurrentPor-All Factor Movements'!G11)/100)+103/POWER(1+('CurrentPor-All Factor Movements'!D11+'CurrentPor-All Factor Movements'!G11)/100,2))*100 -> 9614.0356 | D11: =(3/(1+('CurrentPor-All Factor Movements'!C11+'CurrentPor-All Factor Movements'!H11)/100)+103/POWER(1+('CurrentPor-All Factor Movements'!D11+'CurrentPor-All Factor Movements'!H11)/100,2))*100 -> 9595.9395 | E11: =(3/(1+('CurrentPor-All Factor Movements'!C11+'CurrentPor-All Factor Movements'!I11)/100)+103/POWER(1+('CurrentPor-All Factor Movements'!D11+'CurrentPor-All Factor Movements'!I11)/100,2))*100 -> 9577.0597 | F11: =Portfolio!B$5*'CurrentPor-All Factor Movements'!E11 -> 52352.381 | G11: =Portfolio!B$6*'CurrentPor-All Factor Movements'!F11 -> 3670.3913 | H11: =Portfolio!B$7*'CurrentPor-All Factor Movements'!J11 -> 2064.394 | I11: =SUM(B11:H11) -> 96580.841
A12: 45485 | B12: =(3/(1+('CurrentPor-All Factor Movements'!C12)/100)+103/POWER(1+('CurrentPor-All Factor Movements'!D12)/100,2))*100 -> 9707.5497 | C12: =(3/(1+('CurrentPor-All Factor Movements'!C12+'CurrentPor-All Factor Movements'!G12)/100)+103/POWER(1+('CurrentPor-All Factor Movements'!D12+'CurrentPor-All Factor Movements'!G12)/100,2))*100 -> 9614.9318 | D12: =(3/(1+('CurrentPor-All Factor Movements'!C12+'CurrentPor-All Factor Movements'!H12)/100)+103/POWER(1+('CurrentPor-All Factor Movements'!D12+'CurrentPor-All Factor Movements'!H12)/100,2))*100 -> 9593.706 | E12: =(3/(1+('CurrentPor-All Factor Movements'!C12+'CurrentPor-All Factor Movements'!I12)/100)+103/POWER(1+('CurrentPor-All Factor Movements'!D12+'CurrentPor-All Factor Movements'!I12)/100,2))*100 -> 9580.8847 | F12: =Portfolio!B$5*'CurrentPor-All Factor Movements'!E12 -> 52059.333 | G12: =Portfolio!B$6*'CurrentPor-All Factor Movements'!F12 -> 3607.2425 | H12: =Portfolio!B$7*'CurrentPor-All Factor Movements'!J12 -> 2064.4027 | I12: =SUM(B12:H12) -> 96228.05
A13: 45488 | B13: =(3/(1+('CurrentPor-All Factor Movements'!C13)/100)+103/POWER(1+('CurrentPor-All Factor Movements'!D13)/100,2))*100 -> 9708.157 | C13: =(3/(1+('CurrentPor-All Factor Movements'!C13+'CurrentPor-All Factor Movements'!G13)/100)+103/POWER(1+('CurrentPor-All Factor Movements'!D13+'CurrentPor-All Factor Movements'!G13)/100,2))*100 -> 9620.9419 | D13: =(3/(1+('CurrentPor-All Factor Movements'!C13+'CurrentPor-All Factor Movements'!H13)/100)+103/POWER(1+('CurrentPor-All Factor Movements'!D13+'CurrentPor-All Factor Movements'!H13)/100,2))*100 -> 9583.6955 | E13: =(3/(1+('CurrentPor-All Factor Movements'!C13+'CurrentPor-All Factor Movements'!I13)/100)+103/POWER(1+('CurrentPor-All Factor Movements'!D13+'CurrentPor-All Factor Movements'!I13)/100,2))*100 -> 9580.5896 | F13: =Portfolio!B$5*'CurrentPor-All Factor Movements'!E13 -> 52201.054 | G13: =Portfolio!B$6*'CurrentPor-All Factor Movements'!F13 -> 3657.6999 | H13: =Portfolio!B$7*'CurrentPor-All Factor Movements'!J13 -> 2064.398 | I13: =SUM(B13:H13) -> 96416.536 | J13: =I13-I3 -> 6.6986007
A14: 45489 | B14: =(3/(1+('CurrentPor-All Factor Movements'!C14)/100)+103/POWER(1+('CurrentPor-All Factor Movements'!D14)/100,2))*100 -> 9709.3492 | C14: =(3/(1+('CurrentPor-All Factor Movements'!C14+'CurrentPor-All Factor Movements'!G14)/100)+103/POWER(1+('CurrentPor-All Factor Movements'!D14+'CurrentPor-All Factor Movements'!G14)/100,2))*100 -> 9618.509 | D14: =(3/(1+('CurrentPor-All Factor Movements'!C14+'CurrentPor-All Factor Movements'!H14)/100)+103/POWER(1+('CurrentPor-All Factor Movements'!D14+'CurrentPor-All Factor Movements'!H14)/100,2))*100 -> 9610.1974 | E14: =(3/(1+('CurrentPor-All Factor Movements'!C14+'CurrentPor-All Factor Movements'!I14)/100)+103/POWER(1+('CurrentPor-All Factor Movements'!D14+'CurrentPor-All Factor Movements'!I14)/100,2))*100 -> 9582.041 | F14: =Portfolio!B$5*'CurrentPor-All Factor Movements'!E14 -> 52455.069 | G14: =Portfolio!B$6*'CurrentPor-All Factor Movements'!F14 -> 3962.6477 | H14: =Portfolio!B$7*'CurrentPor-All Factor Movements'!J14 -> 2064.3987 | I14: =SUM(B14:H14) -> 97002.212 | J14: =I14-I4 -> 484.69716
A15: 45490 | B15: =(3/(1+('CurrentPor-All Factor Movements'!C15)/100)+103/POWER(1+('CurrentPor-All Factor Movements'!D15)/100,2))*100 -> 9705.6179 | C15: =(3/(1+('CurrentPor-All Factor Movements'!C15+'CurrentPor-All Factor Movements'!G15)/100)+103/POWER(1+('CurrentPor-All Factor Movements'!D15+'CurrentPor-All Factor Movements'!G15)/100,2))*100 -> 9614.8305 | D15: =(3/(1+('CurrentPor-All Factor Movements'!C15+'CurrentPor-All Factor Movements'!H15)/100)+103/POWER(1+('CurrentPor-All Factor Movements'!D15+'CurrentPor-All Factor Movements'!H15)/100,2))*100 -> 9603.5954 | E15: =(3/(1+('CurrentPor-All Factor Movements'!C15+'CurrentPor-All Factor Movements'!I15)/100)+103/POWER(1+('CurrentPor-All Factor Movements'!D15+'CurrentPor-All Factor Movements'!I15)/100,2))*100 -> 9579.3887 | F15: =Portfolio!B$5*'CurrentPor-All Factor Movements'!E15 -> 52405.111 | G15: =Portfolio!B$6*'CurrentPor-All Factor Movements'!F15 -> 3335.4785 | H15: =Portfolio!B$7*'CurrentPor-All Factor Movements'!J15 -> 2064.3925 | I15: =SUM(B15:H15) -> 96308.415 | J15: =I15-I5 -> 103.65811
A16: 45491 | B16: =(3/(1+('CurrentPor-All Factor Movements'!C16)/100)+103/POWER(1+('CurrentPor-All Factor Movements'!D16)/100,2))*100 -> 9707.1369 | C16: =(3/(1+('CurrentPor-All Factor Movements'!C16+'CurrentPor-All Factor Movements'!G16)/100)+103/POWER(1+('CurrentPor-All Factor Movements'!D16+'CurrentPor-All Factor Movements'!G16)/100,2))*100 -> 9618.1315 | D16: =(3/(1+('CurrentPor-All Factor Movements'!C16+'CurrentPor-All Factor Movements'!H16)/100)+103/POWER(1+('CurrentPor-All Factor Movements'!D16+'CurrentPor-All Factor Movements'!H16)/100,2))*100 -> 9594.9952 | E16: =(3/(1+('CurrentPor-All Factor Movements'!C16+'CurrentPor-All Factor Movements'!I16)/100)+103/POWER(1+('CurrentPor-All Factor Movements'!D16+'CurrentPor-All Factor Movements'!I16)/100,2))*100 -> 9582.5893 | F16: =Portfolio!B$5*'CurrentPor-All Factor Movements'!E16 -> 52745.429 | G16: =Portfolio!B$6*'CurrentPor-All Factor Movements'!F16 -> 3803.0585 | H16: =Portfolio!B$7*'CurrentPor-All Factor Movements'!J16 -> 2064.396 | I16: =SUM(B16:H16) -> 97115.737 | J16: =I16-I6 -> 499.35589
A17: 45492 | B17: =(3/(1+('CurrentPor-All Factor Movements'!C17)/100)+103/POWER(1+('CurrentPor-All Factor Movements'!D17)/100,2))*100 -> 9706.7398 | C17: =(3/(1+('CurrentPor-All Factor Movements'!C17+'CurrentPor-All Factor Movements'!G17)/100)+103/POWER(1+('CurrentPor-All Factor Movements'!D17+'CurrentPor-All Factor Movements'!G17)/100,2))*100 -> 9615.9365 | D17: =(3/(1+('CurrentPor-All Factor Movements'!C17+'CurrentPor-All Factor Movements'!H17)/100)+103/POWER(1+('CurrentPor-All Factor Movements'!D17+'CurrentPor-All Factor Movements'!H17)/100,2))*100 -> 9607.0912 | E17: =(3/(1+('CurrentPor-All Factor Movements'!C17+'CurrentPor-All Factor Movements'!I17)/100)+103/POWER(1+('CurrentPor-All Factor Movements'!D17+'CurrentPor-All Factor Movements'!I17)/100,2))*100 -> 9579.964 | F17: =Portfolio!B$5*'CurrentPor-All Factor Movements'!E17 -> 52403.204 | G17: =Portfolio!B$6*'CurrentPor-All Factor Movements'!F17 -> 3390.236 | H17: =Portfolio!B$7*'CurrentPor-All Factor Movements'!J17 -> 2064.4061 | I17: =SUM(B17:H17) -> 96367.578 | J17: =I17-I7 -> -125.63594
A18: 45495 | B18: =(3/(1+('CurrentPor-All Factor Movements'!C18)/100)+103/POWER(1+('CurrentPor-All Factor Movements'!D18)/100,2))*100 -> 9707.4841 | C18: =(3/(1+('CurrentPor-All Factor Movements'!C18+'CurrentPor-All Factor Movements'!G18)/100)+103/POWER(1+('CurrentPor-All Factor Movements'!D18+'CurrentPor-All Factor Movements'!G18)/100,2))*100 -> 9616.6703 | D18: =(3/(1+('CurrentPor-All Factor Movements'!C18+'CurrentPor-All Factor Movements'!H18)/100)+103/POWER(1+('CurrentPor-All Factor Movements'!D18+'CurrentPor-All Factor Movements'!H18)/100,2))*100 -> 9603.6417 | E18: =(3/(1+('CurrentPor-All Factor Movements'!C18+'CurrentPor-All Factor Movements'!I18)/100)+103/POWER(1+('CurrentPor-All Factor Movements'!D18+'CurrentPor-All Factor Movements'!I18)/100,2))*100 -> 9580.7471 | F18: =Portfolio!B$5*'CurrentPor-All Factor Movements'!E18 -> 52207.785 | G18: =Portfolio!B$6*'CurrentPor-All Factor Movements'!F18 -> 3584.9289 | H18: =Portfolio!B$7*'CurrentPor-All Factor Movements'!J18 -> 2064.3975 | I18: =SUM(B18:H18) -> 96365.655 | J18: =I18-I8 -> -584.93926
A19: 45496 | B19: =(3/(1+('CurrentPor-All Factor Movements'!C19)/100)+103/POWER(1+('CurrentPor-All Factor Movements'!D19)/100,2))*100 -> 9707.5858 | C19: =(3/(1+('CurrentPor-All Factor Movements'!C19+'CurrentPor-All Factor Movements'!G19)/100)+103/POWER(1+('CurrentPor-All Factor Movements'!D19+'CurrentPor-All Factor Movements'!G19)/100,2))*100 -> 9616.7705 | D19: =(3/(1+('CurrentPor-All Factor Movements'!C19+'CurrentPor-All Factor Movements'!H19)/100)+103/POWER(1+('CurrentPor-All Factor Movements'!D19+'CurrentPor-All Factor Movements'!H19)/100,2))*100 -> 9590.1449 | E19: =(3/(1+('CurrentPor-All Factor Movements'!C19+'CurrentPor-All Factor Movements'!I19)/100)+103/POWER(1+('CurrentPor-All Factor Movements'!D19+'CurrentPor-All Factor Movements'!I19)/100,2))*100 -> 9581.9982 | F19: =Portfolio!B$5*'CurrentPor-All Factor Movements'!E19 -> 52419.479 | G19: =Portfolio!B$6*'CurrentPor-All Factor Movements'!F19 -> 3504.4107 | H19: =Portfolio!B$7*'CurrentPor-All Factor Movements'!J19 -> 2064.3967 | I19: =SUM(B19:H19) -> 96484.786 | J19: =I19-I9 -> -636.02431
A20: 45497 | B20: =(3/(1+('CurrentPor-All Factor Movements'!C20)/100)+103/POWER(1+('CurrentPor-All Factor Movements'!D20)/100,2))*100 -> 9707.0759 | C20: =(3/(1+('CurrentPor-All Factor Movements'!C20+'CurrentPor-All Factor Movements'!G20)/100)+103/POWER(1+('CurrentPor-All Factor Movements'!D20+'CurrentPor-All Factor Movements'!G20)/100,2))*100 -> 9616.2678 | D20: =(3/(1+('CurrentPor-All Factor Movements'!C20+'CurrentPor-All Factor Movements'!H20)/100)+103/POWER(1+('CurrentPor-All Factor Movements'!D20+'CurrentPor-All Factor Movements'!H20)/100,2))*100 -> 9589.5798 | E20: =(3/(1+('CurrentPor-All Factor Movements'!C20+'CurrentPor-All Factor Movements'!I20)/100)+103/POWER(1+('CurrentPor-All Factor Movements'!D20+'CurrentPor-All Factor Movements'!I20)/100,2))*100 -> 9580.4066 | F20: =Portfolio!B$5*'CurrentPor-All Factor Movements'!E20 -> 52396.248 | G20: =Portfolio!B$6*'CurrentPor-All Factor Movements'!F20 -> 3835.9849 | H20: =Portfolio!B$7*'CurrentPor-All Factor Movements'!J20 -> 2064.3958 | I20: =SUM(B20:H20) -> 96789.959 | J20: =I20-I10 -> -473.32909
A21: 45498 | B21: =(3/(1+('CurrentPor-All Factor Movements'!C21)/100)+103/POWER(1+('CurrentPor-All Factor Movements'!D21)/100,2))*100 -> 9706.7602 | C21: =(3/(1+('CurrentPor-All Factor Movements'!C21+'CurrentPor-All Factor Movements'!G21)/100)+103/POWER(1+('CurrentPor-All Factor Movements'!D21+'CurrentPor-All Factor Movements'!G21)/100,2))*100 -> 9614.1537 | D21: =(3/(1+('CurrentPor-All Factor Movements'!C21+'CurrentPor-All Factor Movements'!H21)/100)+103/POWER(1+('CurrentPor-All Factor Movements'!D21+'CurrentPor-All Factor Movements'!H21)/100,2))*100 -> 9600.5358 | E21: =(3/(1+('CurrentPor-All Factor Movements'!C21+'CurrentPor-All Factor Movements'!I21)/100)+103/POWER(1+('CurrentPor-All Factor Movements'!D21+'CurrentPor-All Factor Movements'!I21)/100,2))*100 -> 9581.8316 | F21: =Portfolio!B$5*'CurrentPor-All Factor Movements'!E21 -> 52152.22 | G21: =Portfolio!B$6*'CurrentPor-All Factor Movements'!F21 -> 3792.7617 | H21: =Portfolio!B$7*'CurrentPor-All Factor Movements'!J21 -> 2064.3985 | I21: =SUM(B21:H21) -> 96512.661 | J21: =I21-I11 -> -68.1798
A22: 45499 | B22: =(3/(1+('CurrentPor-All Factor Movements'!C22)/100)+103/POWER(1+('CurrentPor-All Factor Movements'!D22)/100,2))*100 -> 9707.4401 | C22: =(3/(1+('CurrentPor-All Factor Movements'!C22+'CurrentPor-All Factor Movements'!G22)/100)+103/POWER(1+('CurrentPor-All Factor Movements'!D22+'CurrentPor-All Factor Movements'!G22)/100,2))*100 -> 9616.6269 | D22: =(3/(1+('CurrentPor-All Factor Movements'!C22+'CurrentPor-All Factor Movements'!H22)/100)+103/POWER(1+('CurrentPor-All Factor Movements'!D22+'CurrentPor-All Factor Movements'!H22)/100,2))*100 -> 9591.4991 | E22: =(3/(1+('CurrentPor-All Factor Movements'!C22+'CurrentPor-All Factor Movements'!I22)/100)+103/POWER(1+('CurrentPor-All Factor Movements'!D22+'CurrentPor-All Factor Movements'!I22)/100,2))*100 -> 9581.3245 | F22: =Portfolio!B$5*'CurrentPor-All Factor Movements'!E22 -> 52162.492 | G22: =Portfolio!B$6*'CurrentPor-All Factor Movements'!F22 -> 4243.6434 | H22: =Portfolio!B$7*'CurrentPor-All Factor Movements'!J22 -> 2064.4022 | I22: =SUM(B22:H22) -> 96967.428 | J22: =I22-I12 -> 739.37829
A23: 45502 | B23: =(3/(1+('CurrentPor-All Factor Movements'!C23)/100)+103/POWER(1+('CurrentPor-All Factor Movements'!D23)/100,2))*100 -> 9708.159 | C23: =(3/(1+('CurrentPor-All Factor Movements'!C23+'CurrentPor-All Factor Movements'!G23)/100)+103/POWER(1+('CurrentPor-All Factor Movements'!D23+'CurrentPor-All Factor Movements'!G23)/100,2))*100 -> 9622.7487 | D23: =(3/(1+('CurrentPor-All Factor Movements'!C23+'CurrentPor-All Factor Movements'!H23)/100)+103/POWER(1+('CurrentPor-All Factor Movements'!D23+'CurrentPor-All Factor Movements'!H23)/100,2))*100 -> 9613.5262 | E23: =(3/(1+('CurrentPor-All Factor Movements'!C23+'CurrentPor-All Factor Movements'!I23)/100)+103/POWER(1+('CurrentPor-All Factor Movements'!D23+'CurrentPor-All Factor Movements'!I23)/100,2))*100 -> 9580.8711 | F23: =Portfolio!B$5*'CurrentPor-All Factor Movements'!E23 -> 52291.142 | G23: =Portfolio!B$6*'CurrentPor-All Factor Movements'!F23 -> 3688.9522 | H23: =Portfolio!B$7*'CurrentPor-All Factor Movements'!J23 -> 2064.4004 | I23: =SUM(B23:H23) -> 96569.8 | J23: =I23-I13 -> 153.26338
A24: 45503 | B24: =(3/(1+('CurrentPor-All Factor Movements'!C24)/100)+103/POWER(1+('CurrentPor-All Factor Movements'!D24)/100,2))*100 -> 9707.8407 | C24: =(3/(1+('CurrentPor-All Factor Movements'!C24+'CurrentPor-All Factor Movements'!G24)/100)+103/POWER(1+('CurrentPor-All Factor Movements'!D24+'CurrentPor-All Factor Movements'!G24)/100,2))*100 -> 9622.4346 | D24: =(3/(1+('CurrentPor-All Factor Movements'!C24+'CurrentPor-All Factor Movements'!H24)/100)+103/POWER(1+('CurrentPor-All Factor Movements'!D24+'CurrentPor-All Factor Movements'!H24)/100,2))*100 -> 9604.5609 | E24: =(3/(1+('CurrentPor-All Factor Movements'!C24+'CurrentPor-All Factor Movements'!I24)/100)+103/POWER(1+('CurrentPor-All Factor Movements'!D24+'CurrentPor-All Factor Movements'!I24)/100,2))*100 -> 9580.67 | F24: =Portfolio!B$5*'CurrentPor-All Factor Movements'!E24 -> 52436.307 | G24: =Portfolio!B$6*'CurrentPor-All Factor Movements'!F24 -> 3719.2101 | H24: =Portfolio!B$7*'CurrentPor-All Factor Movements'!J24 -> 2064.4099 | I24: =SUM(B24:H24) -> 96735.433 | J24: =I24-I14 -> -266.77897
... A263: 45838 | B263: =(3/(1+('CurrentPor-All Factor Movements'!C263)/100)+103/POWER(1+('CurrentPor-All Factor Movements'!D263)/100,2))*100 -> 9707.073 | C263: =(3/(1+('CurrentPor-All Factor Movements'!C263+'CurrentPor-All Factor Movements'!G263)/100)+103/POWER(1+('CurrentPor-All Factor Movements'!D263+'CurrentPor-All Factor Movements'!G263)/100,2))*100 -> 9662.9881 | D263: =(3/(1+('CurrentPor-All Factor Movements'!C263+'CurrentPor-All Factor Movements'!H263)/100)+103/POWER(1+('CurrentPor-All Factor Movements'!D263+'CurrentPor-All Factor Movements'!H263)/100,2))*100 -> 9603.6528 | E263: =(3/(1+('CurrentPor-All Factor Movements'!C263+'CurrentPor-All Factor Movements'!I263)/100)+103/POWER(1+('CurrentPor-All Factor Movements'!D263+'CurrentPor-All Factor Movements'!I263)/100,2))*100 -> 9578.8293 | F263: =Portfolio!B$5*'CurrentPor-All Factor Movements'!E263 -> 51928.943 | G263: =Portfolio!B$6*'CurrentPor-All Factor Movements'!F263 -> 4155.4981 | H263: =Portfolio!B$7*'CurrentPor-All Factor Movements'!J263 -> 2064.4058 | I263: =SUM(B263:H263) -> 96701.39 | J263: =I263-I253 -> 511.39236

Sheet ES,N10 unchanged
B1: LH=10 | C1: LH=10, 20 | D1: LH=10, 40 | E1: LH=10, 60 | F1: LH=10 | G1: LH=10 | H1: LH=20
B2: Treasury Bonds IG valuation | C2: Credit spread: Sovereign Bonds IG valuation | D2: Credit spread: sovereign (high yield, or HY) | E2: Credit Spread:Corporate HY | F2: MSFT | G2: Intel | H2: carbon credits | I2: Portfolio value | J2: 10 day PnL | K2: VaR | L2: ES, Q(pi,2)
A3: 45474 | B3: =(3/(1+('CurrentPor-N10Unchanged'!C3)/100)+103/POWER(1+('CurrentPor-N10Unchanged'!D3)/100,2))*100 -> 9707.5858 | C3: =(3/(1+('CurrentPor-N10Unchanged'!C3+'CurrentPor-N10Unchanged'!G3)/100)+103/POWER(1+('CurrentPor-N10Unchanged'!D3+'CurrentPor-N10Unchanged'!G3)/100,2))*100 -> 9614.9674 | D3: =(3/(1+('CurrentPor-N10Unchanged'!C3+'CurrentPor-N10Unchanged'!H3)/100)+103/POWER(1+('CurrentPor-N10Unchanged'!D3+'CurrentPor-N10Unchanged'!H3)/100,2))*100 -> 9601.2396 | E3: =(3/(1+('CurrentPor-N10Unchanged'!C3+'CurrentPor-N10Unchanged'!I3)/100)+103/POWER(1+('CurrentPor-N10Unchanged'!D3+'CurrentPor-N10Unchanged'!I3)/100,2))*100 -> 9676.6908 | F3: =Portfolio!B$5*'CurrentPor-N10Unchanged'!E3 -> 52143.896 | G3: =Portfolio!B$6*'CurrentPor-N10Unchanged'!F3 -> 3696.2945 | H3: =Portfolio!B$7*'CurrentPor-N10Unchanged'!J3 -> 2064.4002 | I3: =SUM(B3:H3) -> 96505.074 | K3: =_xlfn.PERCENTILE.INC(J13:J263, 0.025) -> -95.160939 | L3: =AVERAGEIF(J13:J263, "<="&K3,J13:J263) -> -104.17405
A4: 45475 | B4: =(3/(1+('CurrentPor-N10Unchanged'!C4)/100)+103/POWER(1+('CurrentPor-N10Unchanged'!D4)/100,2))*100 -> 9707.5858 | C4: =(3/(1+('CurrentPor-N10Unchanged'!C4+'CurrentPor-N10Unchanged'!G4)/100)+103/POWER(1+('CurrentPor-N10Unchanged'!D4+'CurrentPor-N10Unchanged'!G4)/100,2))*100 -> 9614.9674 | D4: =(3/(1+('CurrentPor-N10Unchanged'!C4+'CurrentPor-N10Unchanged'!H4)/100)+103/POWER(1+('CurrentPor-N10Unchanged'!D4+'CurrentPor-N10Unchanged'!H4)/100,2))*100 -> 9586.7536 | E4: =(3/(1+('CurrentPor-N10Unchanged'!C4+'CurrentPor-N10Unchanged'!I4)/100)+103/POWER(1+('CurrentPor-N10Unchanged'!D4+'CurrentPor-N10Unchanged'!I4)/100,2))*100 -> 9676.5087 | F4: =Portfolio!B$5*'CurrentPor-N10Unchanged'!E4 -> 52143.896 | G4: =Portfolio!B$6*'CurrentPor-N10Unchanged'!F4 -> 3696.2945 | H4: =Portfolio!B$7*'CurrentPor-N10Unchanged'!J4 -> 2064.4056 | I4: =SUM(B4:H4) -> 96490.411
A5: 45476 | B5: =(3/(1+('CurrentPor-N10Unchanged'!C5)/100)+103/POWER(1+('CurrentPor-N10Unchanged'!D5)/100,2))*100 -> 9707.5858 | C5: =(3/(1+('CurrentPor-N10Unchanged'!C5+'CurrentPor-N10Unchanged'!G5)/100)+103/POWER(1+('CurrentPor-N10Unchanged'!D5+'CurrentPor-N10Unchanged'!G5)/100,2))*100 -> 9614.9674 | D5: =(3/(1+('CurrentPor-N10Unchanged'!C5+'CurrentPor-N10Unchanged'!H5)/100)+103/POWER(1+('CurrentPor-N10Unchanged'!D5+'CurrentPor-N10Unchanged'!H5)/100,2))*100 -> 9603.463 | E5: =(3/(1+('CurrentPor-N10Unchanged'!C5+'CurrentPor-N10Unchanged'!I5)/100)+103/POWER(1+('CurrentPor-N10Unchanged'!D5+'CurrentPor-N10Unchanged'!I5)/100,2))*100 -> 9676.3449 | F5: =Portfolio!B$5*'CurrentPor-N10Unchanged'!E5 -> 52143.896 | G5: =Portfolio!B$6*'CurrentPor-N10Unchanged'!F5 -> 3696.2945 | H5: =Portfolio!B$7*'CurrentPor-N10Unchanged'!J5 -> 2064.4002 | I5: =SUM(B5:H5) -> 96506.951
A6: 45477 | B6: =(3/(1+('CurrentPor-N10Unchanged'!C6)/100)+103/POWER(1+('CurrentPor-N10Unchanged'!D6)/100,2))*100 -> 9707.5858 | C6: =(3/(1+('CurrentPor-N10Unchanged'!C6+'CurrentPor-N10Unchanged'!G6)/100)+103/POWER(1+('CurrentPor-N10Unchanged'!D6+'CurrentPor-N10Unchanged'!G6)/100,2))*100 -> 9614.9674 | D6: =(3/(1+('CurrentPor-N10Unchanged'!C6+'CurrentPor-N10Unchanged'!H6)/100)+103/POWER(1+('CurrentPor-N10Unchanged'!D6+'CurrentPor-N10Unchanged'!H6)/100,2))*100 -> 9607.0115 | E6: =(3/(1+('CurrentPor-N10Unchanged'!C6+'CurrentPor-N10Unchanged'!I6)/100)+103/POWER(1+('CurrentPor-N10Unchanged'!D6+'CurrentPor-N10Unchanged'!I6)/100,2))*100 -> 9674.7614 | F6: =Portfolio!B$5*'CurrentPor-N10Unchanged'!E6 -> 52143.896 | G6: =Portfolio!B$6*'CurrentPor-N10Unchanged'!F6 -> 3696.2945 | H6: =Portfolio!B$7*'CurrentPor-N10Unchanged'!J6 -> 2064.3982 | I6: =SUM(B6:H6) -> 96508.914
A7: 45478 | B7: =(3/(1+('CurrentPor-N10Unchanged'!C7)/100)+103/POWER(1+('CurrentPor-N10Unchanged'!D7)/100,2))*100 -> 9707.5858 | C7: =(3/(1+('CurrentPor-N10Unchanged'!C7+'CurrentPor-N10Unchanged'!G7)/100)+103/POWER(1+('CurrentPor-N10Unchanged'!D7+'CurrentPor-N10Unchanged'!G7)/100,2))*100 -> 9616.7705 | D7: =(3/(1+('CurrentPor-N10Unchanged'!C7+'CurrentPor-N10Unchanged'!H7)/100)+103/POWER(1+('CurrentPor-N10Unchanged'!D7+'CurrentPor-N10Unchanged'!H7)/100,2))*100 -> 9580.3056 | E7: =(3/(1+('CurrentPor-N10Unchanged'!C7+'CurrentPor-N10Unchanged'!I7)/100)+103/POWER(1+('CurrentPor-N10Unchanged'!D7+'CurrentPor-N10Unchanged'!I7)/100,2))*100 -> 9676.8 | F7: =Portfolio!B$5*'CurrentPor-N10Unchanged'!E7 -> 52143.896 | G7: =Portfolio!B$6*'CurrentPor-N10Unchanged'!F7 -> 3696.2945 | H7: =Portfolio!B$7*'CurrentPor-N10Unchanged'!J7 -> 2064.3926 | I7: =SUM(B7:H7) -> 96486.045
A8: 45481 | B8: =(3/(1+('CurrentPor-N10Unchanged'!C8)/100)+103/POWER(1+('CurrentPor-N10Unchanged'!D8)/100,2))*100 -> 9707.5858 | C8: =(3/(1+('CurrentPor-N10Unchanged'!C8+'CurrentPor-N10Unchanged'!G8)/100)+103/POWER(1+('CurrentPor-N10Unchanged'!D8+'CurrentPor-N10Unchanged'!G8)/100,2))*100 -> 9613.1647 | D8: =(3/(1+('CurrentPor-N10Unchanged'!C8+'CurrentPor-N10Unchanged'!H8)/100)+103/POWER(1+('CurrentPor-N10Unchanged'!D8+'CurrentPor-N10Unchanged'!H8)/100,2))*100 -> 9582.0864 | E8: =(3/(1+('CurrentPor-N10Unchanged'!C8+'CurrentPor-N10Unchanged'!I8)/100)+103/POWER(1+('CurrentPor-N10Unchanged'!D8+'CurrentPor-N10Unchanged'!I8)/100,2))*100 -> 9676.1811 | F8: =Portfolio!B$5*'CurrentPor-N10Unchanged'!E8 -> 52143.896 | G8: =Portfolio!B$6*'CurrentPor-N10Unchanged'!F8 -> 3696.2945 | H8: =Portfolio!B$7*'CurrentPor-N10Unchanged'!J8 -> 2064.3945 | I8: =SUM(B8:H8) -> 96483.602
A9: 45482 | B9: =(3/(1+('CurrentPor-N10Unchanged'!C9)/100)+103/POWER(1+('CurrentPor-N10Unchanged'!D9)/100,2))*100 -> 9707.5858 | C9: =(3/(1+('CurrentPor-N10Unchanged'!C9+'CurrentPor-N10Unchanged'!G9)/100)+103/POWER(1+('CurrentPor-N10Unchanged'!D9+'CurrentPor-N10Unchanged'!G9)/100,2))*100 -> 9613.1647 | D9: =(3/(1+('CurrentPor-N10Unchanged'!C9+'CurrentPor-N10Unchanged'!H9)/100)+103/POWER(1+('CurrentPor-N10Unchanged'!D9+'CurrentPor-N10Unchanged'!H9)/100,2))*100 -> 9594.9699 | E9: =(3/(1+('CurrentPor-N10Unchanged'!C9+'CurrentPor-N10Unchanged'!I9)/100)+103/POWER(1+('CurrentPor-N10Unchanged'!D9+'CurrentPor-N10Unchanged'!I9)/100,2))*100 -> 9673.7787 | F9: =Portfolio!B$5*'CurrentPor-N10Unchanged'!E9 -> 52143.896 | G9: =Portfolio!B$6*'CurrentPor-N10Unchanged'!F9 -> 3696.2945 | H9: =Portfolio!B$7*'CurrentPor-N10Unchanged'!J9 -> 2064.4019 | I9: =SUM(B9:H9) -> 96494.091
A10: 45483 | B10: =(3/(1+('CurrentPor-N10Unchanged'!C10)/100)+103/POWER(1+('CurrentPor-N10Unchanged'!D10)/100,2))*100 -> 9707.5858 | C10: =(3/(1+('CurrentPor-N10Unchanged'!C10+'CurrentPor-N10Unchanged'!G10)/100)+103/POWER(1+('CurrentPor-N10Unchanged'!D10+'CurrentPor-N10Unchanged'!G10)/100,2))*100 -> 9614.9674 | D10: =(3/(1+('CurrentPor-N10Unchanged'!C10+'CurrentPor-N10Unchanged'!H10)/100)+103/POWER(1+('CurrentPor-N10Unchanged'!D10+'CurrentPor-N10Unchanged'!H10)/100,2))*100 -> 9593.3699 | E10: =(3/(1+('CurrentPor-N10Unchanged'!C10+'CurrentPor-N10Unchanged'!I10)/100)+103/POWER(1+('CurrentPor-N10Unchanged'!D10+'CurrentPor-N10Unchanged'!I10)/100,2))*100 -> 9671.0498 | F10: =Portfolio!B$5*'CurrentPor-N10Unchanged'!E10 -> 52143.896 | G10: =Portfolio!B$6*'CurrentPor-N10Unchanged'!F10 -> 3696.2945 | H10: =Portfolio!B$7*'CurrentPor-N10Unchanged'!J10 -> 2064.4012 | I10: =SUM(B10:H10) -> 96491.564
A11: 45484 | B11: =(3/(1+('CurrentPor-N10Unchanged'!C11)/100)+103/POWER(1+('CurrentPor-N10Unchanged'!D11)/100,2))*100 -> 9707.5858 | C11: =(3/(1+('CurrentPor-N10Unchanged'!C11+'CurrentPor-N10Unchanged'!G11)/100)+103/POWER(1+('CurrentPor-N10Unchanged'!D11+'CurrentPor-N10Unchanged'!G11)/100,2))*100 -> 9614.9674 | D11: =(3/(1+('CurrentPor-N10Unchanged'!C11+'CurrentPor-N10Unchanged'!H11)/100)+103/POWER(1+('CurrentPor-N10Unchanged'!D11+'CurrentPor-N10Unchanged'!H11)/100,2))*100 -> 9596.8686 | E11: =(3/(1+('CurrentPor-N10Unchanged'!C11+'CurrentPor-N10Unchanged'!I11)/100)+103/POWER(1+('CurrentPor-N10Unchanged'!D11+'CurrentPor-N10Unchanged'!I11)/100,2))*100 -> 9672.6688 | F11: =Portfolio!B$5*'CurrentPor-N10Unchanged'!E11 -> 52143.896 | G11: =Portfolio!B$6*'CurrentPor-N10Unchanged'!F11 -> 3696.2945 | H11: =Portfolio!B$7*'CurrentPor-N10Unchanged'!J11 -> 2064.394 | I11: =SUM(B11:H11) -> 96496.675
A12: 45485 | B12: =(3/(1+('CurrentPor-N10Unchanged'!C12)/100)+103/POWER(1+('CurrentPor-N10Unchanged'!D12)/100,2))*100 -> 9707.5858 | C12: =(3/(1+('CurrentPor-N10Unchanged'!C12+'CurrentPor-N10Unchanged'!G12)/100)+103/POWER(1+('CurrentPor-N10Unchanged'!D12+'CurrentPor-N10Unchanged'!G12)/100,2))*100 -> 9614.9674 | D12: =(3/(1+('CurrentPor-N10Unchanged'!C12+'CurrentPor-N10Unchanged'!H12)/100)+103/POWER(1+('CurrentPor-N10Unchanged'!D12+'CurrentPor-N10Unchanged'!H12)/100,2))*100 -> 9593.7415 | E12: =(3/(1+('CurrentPor-N10Unchanged'!C12+'CurrentPor-N10Unchanged'!I12)/100)+103/POWER(1+('CurrentPor-N10Unchanged'!D12+'CurrentPor-N10Unchanged'!I12)/100,2))*100 -> 9674.8342 | F12: =Portfolio!B$5*'CurrentPor-N10Unchanged'!E12 -> 52143.896 | G12: =Portfolio!B$6*'CurrentPor-N10Unchanged'!F12 -> 3696.2945 | H12: =Portfolio!B$7*'CurrentPor-N10Unchanged'!J12 -> 2064.4027 | I12: =SUM(B12:H12) -> 96495.722
