Workbook

Sheet CurrentPor-All Factor Movements
B1: LH = 10 | F1: LH = 20 | G1: LH = 40 | H1: LH = 60
A2: DATE | B2: 1Y_Treasury | C2: 2Y_Treasury | D2: MSFT price | E2: Intel price | F2: Credit spread: sovereign (investment grade, or IG) | G2: Credit spread: sovereign (high yield, or HY) | H2: Credit Spread: Corporate(HY)
A3: 39261 | B3: 5.0827211 | C3: 3.757601 | D3: 530.0671 | E3: 38.486313 | F3: 0.54698984 | G3: 0.54598365 | H3: 0.73149659
A4: 39262 | B4: 4.3206271 | C4: 4.3032671 | D4: 522.828 | E4: 35.525856 | F4: 0.4768308 | G4: 0.69977849 | H4: 0.54770034
A5: 39265 | B5: 3.7975784 | C5: 4.6944415 | D5: 510.1185 | E5: 36.378868 | F5: 0.50678783 | G5: 0.5863137 | H5: 0.75066502
A6: 39266 | B6: 3.6141194 | C6: 4.1556962 | D6: 516.68968 | E6: 36.138276 | F6: 0.47000134 | G6: 0.61756551 | H6: 0.7426038
A7: 39267 | B7: 3.6710365 | C7: 4.4072511 | D7: 511.90516 | E7: 35.611754 | F7: 0.53750179 | G7: 0.58417944 | H7: 0.59754414
A8: 39268 | B8: 3.9313791 | C8: 5.1639098 | D8: 513.45231 | E8: 37.709248 | F8: 0.4680766 | G8: 0.63677568 | H8: 0.68369645
A9: 39269 | B9: 3.0612983 | C9: 5.3991583 | D9: 519.33854 | E9: 36.256978 | F9: 0.51467052 | G9: 0.56761299 | H9: 0.67972678
A10: 39272 | B10: 4.7294171 | C10: 4.813724 | D10: 515.82192 | E10: 35.112746 | F10: 0.49766367 | G10: 0.52563263 | H10: 0.69548422
A11: 39273 | B11: 3.8815719 | C11: 4.5487413 | D11: 529.18295 | E11: 35.866392 | F11: 0.46665381 | G11: 0.6418315 | H11: 0.68681553
A12: 39274 | B12: 4.8060444 | C12: 4.3212833 | D12: 528.77176 | E12: 34.84045 | F12: 0.51901746 | G12: 0.5740927 | H12: 0.75370085
A13: 39275 | B13: 3.5245765 | C13: 5.3444637 | D13: 509.46564 | E13: 38.812221 | F13: 0.54636882 | G13: 0.57967181 | H13: 0.67532012
A14: 39276 | B14: 3.7644957 | C14: 4.4495093 | D14: 544.08626 | E14: 36.566971 | F14: 0.55817954 | G14: 0.66068468 | H14: 0.65013775
... A263: 39625 | B263: 4.5183979 | C263: 4.6873624 | D263: 510.79332 | E263: 36.152701 | F263: 0.59365408 | G263: 0.64227219 | H263: 0.62799143

Sheet CurrentPor-N10Unchanged
B1: LH = 10 | F1: LH = 20 | G1: LH = 40 | H1: LH = 60
B2: 1Y_Treasury | C2: 2Y_Treasury | D2: MSFT price | E2: Intel price | F2: Credit spread: sovereign (investment grade, or IG) | G2: Credit spread: sovereign (high yield, or HY) | H2: Credit Spread: Corporate(HY)
A3: 39261 | B3: 4.2673967 | C3: 4.5673967 | D3: 521.43896 | E3: 36.962945 | F3: 0.51 | G3: 0.58622522 | H3: 0.1693
A4: 39262 | B4: 4.2673967 | C4: 4.5673967 | D4: 521.43896 | E4: 36.962945 | F4: 0.51 | G4: 0.66683919 | H4: 0.17030001
A5: 39265 | B5: 4.2673967 | C5: 4.5673967 | D5: 521.43896 | E5: 36.962945 | F5: 0.51 | G5: 0.5738683 | H5: 0.17120001
A6: 39266 | B6: 4.2673967 | C6: 4.5673967 | D6: 521.43896 | E6: 36.962945 | F6: 0.51 | G6: 0.55415584 | H6: 0.1799
A7: 39267 | B7: 4.2673967 | C7: 4.5673967 | D7: 521.43896 | E7: 36.962945 | F7: 0.5 | G7: 0.70278175 | H7: 0.16870001
A8: 39268 | B8: 4.2673967 | C8: 4.5673967 | D8: 521.43896 | E8: 36.962945 | F8: 0.52 | G8: 0.69285184 | H8: 0.17209999
A9: 39269 | B9: 4.2673967 | C9: 4.5673967 | D9: 521.43896 | E9: 36.962945 | F9: 0.52 | G9: 0.62109307 | H9: 0.18530001
A10: 39272 | B10: 4.2673967 | C10: 4.5673967 | D10: 521.43896 | E10: 36.962945 | F10: 0.51 | G10: 0.62999665 | H10: 0.20030001
A11: 39273 | B11: 4.2673967 | C11: 4.5673967 | D11: 521.43896 | E11: 36.962945 | F11: 0.51 | G11: 0.6105303 | H11: 0.19139999
A12: 39274 | B12: 4.2673967 | C12: 4.5673967 | D12: 521.43896 | E12: 36.962945 | F12: 0.51 | G12: 0.62792874 | H12: 0.17950001
A13: 39275 | B13: 4.2673967 | C13: 4.5673967 | D13: 521.43896 | E13: 36.962945 | F13: 0.48 | G13: 0.68700411 | H13: 0.1565
A14: 39276 | B14: 4.2673967 | C14: 4.5673967 | D14: 521.43896 | E14: 36.962945 | F14: 0.5 | G14: 0.54610546 | H14: 0.146
... A263: 39625 | B263: 4.2673967 | C263: 4.5673967 | D263: 521.43896 | E263: 36.962945 | F263: 0.59365408 | G263: 0.64227219 | H263: 0.62799143

Sheet CurrentFact-N10,20Unchanged
B1: LH = 10 | F1: LH = 20 | G1: LH = 40 | H1: LH = 60
A2: DATE | B2: 1Y_Treasury | C2: 2Y_Treasury | D2: MSFT price | E2: Intel price | F2: Credit spread: sovereign (investment grade, or IG) | G2: Credit spread: sovereign (high yield, or HY) | H2: Credit Spread: Corporate(HY)
A3: 39261 | B3: 4.2673967 | C3: 4.5673967 | D3: 521.43896 | E3: 36.962945 | F3: 0.51 | G3: 0.58622522 | H3: 0.1693
A4: 39262 | B4: 4.2673967 | C4: 4.5673967 | D4: 521.43896 | E4: 36.962945 | F4: 0.51 | G4: 0.66683919 | H4: 0.17030001
A5: 39265 | B5: 4.2673967 | C5: 4.5673967 | D5: 521.43896 | E5: 36.962945 | F5: 0.51 | G5: 0.5738683 | H5: 0.17120001
A6: 39266 | B6: 4.2673967 | C6: 4.5673967 | D6: 521.43896 | E6: 36.962945 | F6: 0.51 | G6: 0.55415584 | H6: 0.1799
A7: 39267 | B7: 4.2673967 | C7: 4.5673967 | D7: 521.43896 | E7: 36.962945 | F7: 0.51 | G7: 0.70278175 | H7: 0.16870001
A8: 39268 | B8: 4.2673967 | C8: 4.5673967 | D8: 521.43896 | E8: 36.962945 | F8: 0.51 | G8: 0.69285184 | H8: 0.17209999
A9: 39269 | B9: 4.2673967 | C9: 4.5673967 | D9: 521.43896 | E9: 36.962945 | F9: 0.51 | G9: 0.62109307 | H9: 0.18530001
A10: 39272 | B10: 4.2673967 | C10: 4.5673967 | D10: 521.43896 | E10: 36.962945 | F10: 0.51 | G10: 0.62999665 | H10: 0.20030001
A11: 39273 | B11: 4.2673967 | C11: 4.5673967 | D11: 521.43896 | E11: 36.962945 | F11: 0.51 | G11: 0.6105303 | H11: 0.19139999
A12: 39274 | B12: 4.2673967 | C12: 4.5673967 | D12: 521.43896 | E12: 36.962945 | F12: 0.51 | G12: 0.62792874 | H12: 0.17950001
A13: 39275 | B13: 4.2673967 | C13: 4.5673967 | D13: 521.43896 | E13: 36.962945 | F13: 0.51 | G13: 0.68700411 | H13: 0.1565
A14: 39276 | B14: 4.2673967 | C14: 4.5673967 | D14: 521.43896 | E14: 36.962945 | F14: 0.51 | G14: 0.54610546 | H14: 0.146
... A263: 39625 | B263: 4.2673967 | C263: 4.5673967 | D263: 521.43896 | E263: 36.962945 | F263: 0.51 | G263: 0.64227219 | H263: 0.62799143

Sheet CurrentFact-N10,20,40Unchanged
C1: LH = 10 | G1: LH = 20 | H1: LH = 40 | I1: LH = 60
A2: DATE | C2: 1Y_Treasury | D2: 2Y_Treasury | E2: MSFT price | F2: Intel price | G2: Credit spread: sovereign (investment grade, or IG) | H2: Credit spread: sovereign (high yield, or HY) | I2: Credit Spread: Corporate(HY)
A3: 39261 | B3: {=_xlfn._xlws.FILTER(A3, WEEKDAY(A3, 2) <= 5)} -> 39261 | C3: 4.2673967 | D3: 4.5673967 | E3: 521.43896 | F3: 36.962945 | G3: 0.51 | H3: 0.58622522 | I3: 0.1693
A4: 39262 | B4: {=_xlfn._xlws.FILTER(A4, WEEKDAY(A4, 2) <= 5)} -> 39262 | C4: 4.2673967 | D4: 4.5673967 | E4: 521.43896 | F4: 36.962945 | G4: 0.51 | H4: 0.58622522 | I4: 0.17030001
A5: 39265 | B5: {=_xlfn._xlws.FILTER(A5, WEEKDAY(A5, 2) <= 5)} -> 39265 | C5: 4.2673967 | D5: 4.5673967 | E5: 521.43896 | F5: 36.962945 | G5: 0.51 | H5: 0.58622522 | I5: 0.17120001
A6: 39266 | B6: {=_xlfn._xlws.FILTER(A6, WEEKDAY(A6, 2) <= 5)} -> 39266 | C6: 4.2673967 | D6: 4.5673967 | E6: 521.43896 | F6: 36.962945 | G6: 0.51 | H6: 0.58622522 | I6: 0.1799
A7: 39267 | B7: {=_xlfn._xlws.FILTER(A7, WEEKDAY(A7, 2) <= 5)} -> 39267 | C7: 4.2673967 | D7: 4.5673967 | E7: 521.43896 | F7: 36.962945 | G7: 0.51 | H7: 0.58622522 | I7: 0.16870001
A8: 39268 | B8: {=_xlfn._xlws.FILTER(A8, WEEKDAY(A8, 2) <= 5)} -> 39268 | C8: 4.2673967 | D8: 4.5673967 | E8: 521.43896 | F8: 36.962945 | G8: 0.51 | H8: 0.58622522 | I8: 0.17209999
A9: 39269 | B9: {=_xlfn._xlws.FILTER(A9, WEEKDAY(A9, 2) <= 5)} -> 39269 | C9: 4.2673967 | D9: 4.5673967 | E9: 521.43896 | F9: 36.962945 | G9: 0.51 | H9: 0.58622522 | I9: 0.18530001
A10: 39272 | B10: {=_xlfn._xlws.FILTER(A10, WEEKDAY(A10, 2) <= 5)} -> 39272 | C10: 4.2673967 | D10: 4.5673967 | E10: 521.43896 | F10: 36.962945 | G10: 0.51 | H10: 0.58622522 | I10: 0.20030001
A11: 39273 | B11: {=_xlfn._xlws.FILTER(A11, WEEKDAY(A11, 2) <= 5)} -> 39273 | C11: 4.2673967 | D11: 4.5673967 | E11: 521.43896 | F11: 36.962945 | G11: 0.51 | H11: 0.58622522 | I11: 0.19139999
A12: 39274 | B12: {=_xlfn._xlws.FILTER(A12, WEEKDAY(A12, 2) <= 5)} -> 39274 | C12: 4.2673967 | D12: 4.5673967 | E12: 521.43896 | F12: 36.962945 | G12: 0.51 | H12: 0.58622522 | I12: 0.17950001
A13: 39275 | B13: {=_xlfn._xlws.FILTER(A13, WEEKDAY(A13, 2) <= 5)} -> 39275 | C13: 4.2673967 | D13: 4.5673967 | E13: 521.43896 | F13: 36.962945 | G13: 0.51 | H13: 0.58622522 | I13: 0.1565
A14: 39276 | B14: {=_xlfn._xlws.FILTER(A14, WEEKDAY(A14, 2) <= 5)} -> 39276 | C14: 4.2673967 | D14: 4.5673967 | E14: 521.43896 | F14: 36.962945 | G14: 0.51 | H14: 0.58622522 | I14: 0.146
... A187: 39519 | B187: {=_xlfn._xlws.FILTER(A187, WEEKDAY(A187, 2) <= 5)} -> 39519 | C187: 4.2673967 | D187: 4.5673967 | E187: 521.43896 | F187: 36.962945 | G187: 0.51 | H187: 0.58622522 | I187: 0.1199
A188: 39520 | C188: 4.2673967 | D188: 4.5673967 | E188: 521.43896 | F188: 36.962945 | G188: 0.51 | H188: 0.58622522 | I188: 0.65288878
A189: 39521 | C189: 4.2673967 | D189: 4.5673967 | E189: 521.43896 | F189: 36.962945 | G189: 0.51 | H189: 0.58622522 | I189: 0.60642847
A190: 39524 | C190: 4.2673967 | D190: 4.5673967 | E190: 521.43896 | F190: 36.962945 | G190: 0.51 | H190: 0.58622522 | I190: 0.60514873
A191: 39525 | C191: 4.2673967 | D191: 4.5673967 | E191: 521.43896 | F191: 36.962945 | G191: 0.51 | H191: 0.58622522 | I191: 0.70687396
A192: 39526 | C192: 4.2673967 | D192: 4.5673967 | E192: 521.43896 | F192: 36.962945 | G192: 0.51 | H192: 0.58622522 | I192: 0.69923744
A193: 39527 | C193: 4.2673967 | D193: 4.5673967 | E193: 521.43896 | F193: 36.962945 | G193: 0.51 | H193: 0.58622522 | I193: 0.77718673
A194: 39528 | C194: 4.2673967 | D194: 4.5673967 | E194: 521.43896 | F194: 36.962945 | G194: 0.51 | H194: 0.58622522 | I194: 0.6203323
A195: 39531 | C195: 4.2673967 | D195: 4.5673967 | E195: 521.43896 | F195: 36.962945 | G195: 0.51 | H195: 0.58622522 | I195: 0.60489426
A196: 39532 | C196: 4.2673967 | D196: 4.5673967 | E196: 521.43896 | F196: 36.962945 | G196: 0.51 | H196: 0.58622522 | I196: 0.62920456
A197: 39533 | C197: 4.2673967 | D197: 4.5673967 | E197: 521.43896 | F197: 36.962945 | G197: 0.51 | H197: 0.58622522 | I197: 0.56075077
A198: 39534 | C198: 4.2673967 | D198: 4.5673967 | E198: 521.43896 | F198: 36.962945 | G198: 0.51 | H198: 0.58622522 | I198: 0.73662889
A199: 39535 | C199: 4.2673967 | D199: 4.5673967 | E199: 521.43896 | F199: 36.962945 | G199: 0.51 | H199: 0.58622522 | I199: 0.56905645
... A263: 39625 | C263: 4.2673967 | D263: 4.5673967 | E263: 521.43896 | F263: 36.962945 | G263: 0.51 | H263: 0.58622522 | I263: 0.62799143

Sheet CurrentFact-N10,20,40,60Unchan
C1: LH = 10 | G1: LH = 20 | H1: LH = 40 | I1: LH = 60
A2: DATE | C2: 1Y_Treasury | D2: 2Y_Treasury | E2: MSFT price | F2: Intel price | G2: Credit spread: sovereign (investment grade, or IG) | H2: Credit spread: sovereign (high yield, or HY) | I2: Credit Spread: Corporate(HY)
A3: 39261 | B3: {=_xlfn._xlws.FILTER(A3, WEEKDAY(A3, 2) <= 5)} -> 39261 | C3: 4.2673967 | D3: 4.5673967 | E3: 521.43896 | F3: 36.962945 | G3: 0.51 | H3: 0.58622522 | I3: 0.1693
A4: 39262 | B4: {=_xlfn._xlws.FILTER(A4, WEEKDAY(A4, 2) <= 5)} -> 39262 | C4: 4.2673967 | D4: 4.5673967 | E4: 521.43896 | F4: 36.962945 | G4: 0.51 | H4: 0.58622522 | I4: 0.1693
A5: 39265 | B5: {=_xlfn._xlws.FILTER(A5, WEEKDAY(A5, 2) <= 5)} -> 39265 | C5: 4.2673967 | D5: 4.5673967 | E5: 521.43896 | F5: 36.962945 | G5: 0.51 | H5: 0.58622522 | I5: 0.1693
A6: 39266 | B6: {=_xlfn._xlws.FILTER(A6, WEEKDAY(A6, 2) <= 5)} -> 39266 | C6: 4.2673967 | D6: 4.5673967 | E6: 521.43896 | F6: 36.962945 | G6: 0.51 | H6: 0.58622522 | I6: 0.1693
A7: 39267 | B7: {=_xlfn._xlws.FILTER(A7, WEEKDAY(A7, 2) <= 5)} -> 39267 | C7: 4.2673967 | D7: 4.5673967 | E7: 521.43896 | F7: 36.962945 | G7: 0.51 | H7: 0.58622522 | I7: 0.1693
A8: 39268 | B8: {=_xlfn._xlws.FILTER(A8, WEEKDAY(A8, 2) <= 5)} -> 39268 | C8: 4.2673967 | D8: 4.5673967 | E8: 521.43896 | F8: 36.962945 | G8: 0.51 | H8: 0.58622522 | I8: 0.1693
A9: 39269 | B9: {=_xlfn._xlws.FILTER(A9, WEEKDAY(A9, 2) <= 5)} -> 39269 | C9: 4.2673967 | D9: 4.5673967 | E9: 521.43896 | F9: 36.962945 | G9: 0.51 | H9: 0.58622522 | I9: 0.1693
A10: 39272 | B10: {=_xlfn._xlws.FILTER(A10, WEEKDAY(A10, 2) <= 5)} -> 39272 | C10: 4.2673967 | D10: 4.5673967 | E10: 521.43896 | F10: 36.962945 | G10: 0.51 | H10: 0.58622522 | I10: 0.1693
A11: 39273 | B11: {=_xlfn._xlws.FILTER(A11, WEEKDAY(A11, 2) <= 5)} -> 39273 | C11: 4.2673967 | D11: 4.5673967 | E11: 521.43896 | F11: 36.962945 | G11: 0.51 | H11: 0.58622522 | I11: 0.1693
A12: 39274 | B12: {=_xlfn._xlws.FILTER(A12, WEEKDAY(A12, 2) <= 5)} -> 39274 | C12: 4.2673967 | D12: 4.5673967 | E12: 521.43896 | F12: 36.962945 | G12: 0.51 | H12: 0.58622522 | I12: 0.1693
A13: 39275 | B13: {=_xlfn._xlws.FILTER(A13, WEEKDAY(A13, 2) <= 5)} -> 39275 | C13: 4.2673967 | D13: 4.5673967 | E13: 521.43896 | F13: 36.962945 | G13: 0.51 | H13: 0.58622522 | I13: 0.1693
A14: 39276 | B14: {=_xlfn._xlws.FILTER(A14, WEEKDAY(A14, 2) <= 5)} -> 39276 | C14: 4.2673967 | D14: 4.5673967 | E14: 521.43896 | F14: 36.962945 | G14: 0.51 | H14: 0.58622522 | I14: 0.1693
... A187: 39519 | B187: {=_xlfn._xlws.FILTER(A187, WEEKDAY(A187, 2) <= 5)} -> 39519 | C187: 4.2673967 | D187: 4.5673967 | E187: 521.43896 | F187: 36.962945 | G187: 0.51 | H187: 0.58622522 | I187: 0.1693
A188: 39520 | C188: 4.2673967 | D188: 4.5673967 | E188: 521.43896 | F188: 36.962945 | G188: 0.51 | H188: 0.58622522 | I188: 0.1693
A189: 39521 | C189: 4.2673967 | D189: 4.5673967 | E189: 521.43896 | F189: 36.962945 | G189: 0.51 | H189: 0.58622522 | I189: 0.1693
A190: 39524 | C190: 4.2673967 | D190: 4.5673967 | E190: 521.43896 | F190: 36.962945 | G190: 0.51 | H190: 0.58622522 | I190: 0.1693
A191: 39525 | C191: 4.2673967 | D191: 4.5673967 | E191: 521.43896 | F191: 36.962945 | G191: 0.51 | H191: 0.58622522 | I191: 0.1693
A192: 39526 | C192: 4.2673967 | D192: 4.5673967 | E192: 521.43896 | F192: 36.962945 | G192: 0.51 | H192: 0.58622522 | I192: 0.1693
A193: 39527 | C193: 4.2673967 | D193: 4.5673967 | E193: 521.43896 | F193: 36.962945 | G193: 0.51 | H193: 0.58622522 | I193: 0.1693
A194: 39528 | C194: 4.2673967 | D194: 4.5673967 | E194: 521.43896 | F194: 36.962945 | G194: 0.51 | H194: 0.58622522 | I194: 0.1693
A195: 39531 | C195: 4.2673967 | D195: 4.5673967 | E195: 521.43896 | F195: 36.962945 | G195: 0.51 | H195: 0.58622522 | I195: 0.1693
A196: 39532 | C196: 4.2673967 | D196: 4.5673967 | E196: 521.43896 | F196: 36.962945 | G196: 0.51 | H196: 0.58622522 | I196: 0.1693
A197: 39533 | C197: 4.2673967 | D197: 4.5673967 | E197: 521.43896 | F197: 36.962945 | G197: 0.51 | H197: 0.58622522 | I197: 0.1693
A198: 39534 | C198: 4.2673967 | D198: 4.5673967 | E198: 521.43896 | F198: 36.962945 | G198: 0.51 | H198: 0.58622522 | I198: 0.1693
A199: 39535 | C199: 4.2673967 | D199: 4.5673967 | E199: 521.43896 | F199: 36.962945 | G199: 0.51 | H199: 0.58622522 | I199: 0.1693
... A263: 39625 | C263: 4.2673967 | D263: 4.5673967 | E263: 521.43896 | F263: 36.962945 | G263: 0.51 | H263: 0.58622522 | I263: 0.1693

Sheet Portfolio
A1: Holding | B1: Quantity | C1: Coupon | D1: Notional | E1: Price | F1: Total | J1: T | N1: LH | O1: ES | P1: Absolute ES | Q1: Calculated value
A2: Treasury bonds | B2: 100 | C2: 3 | D2: 100 | F2: =B2*D2 -> 10000 | J2: 10 | M2: EST(P,1) | N2: 10 | O2: ='ES, All factor movement'!K3 -> -3506.7804 | P2: =ABS(O2) -> 3506.7804 | Q2: =P2*P2 -> 12297509
A3: Sovereign Bonds HY | B3: 100 | C3: 3 | D3: 100 | F3: =B3*D3 -> 10000 | M3: EST(P,2) | N3: 20 | O3: ='ES,N10 unchanged'!K3 -> -136.7897 | P3: =ABS(O3) -> 136.7897 | Q3: =POWER(P3*SQRT(10/10),2) -> 18711.421
A4: Sovereign Bonds IG | B4: 100 | C4: 3 | D4: 100 | F4: =B4*D4 -> 10000 | M4: EST(P,3) | N4: 40 | O4: ='ES,N10,20 unchanged'!K3 -> -102.83547 | P4: =ABS(O4) -> 102.83547 | Q4: =POWER(P4*SQRT(20/10),2) -> 21150.266
A5: MSFT stocks | B5: 100 | E5: 500 | F5: =B5*E5 -> 50000 | M5: EST(P,4) | N5: 60 | O5: ='ES,N10,20,40 unchanged'!K3 -> -97.20211 | P5: =ABS(O5) -> 97.20211 | Q5: =POWER(P5*SQRT(20/10),2) -> 18896.5
A6: Intel Stock | B6: 100 | E6: 36 | F6: =B6*E6 -> 3600 | P6: ESR,S | Q6: =SQRT(SUM(Q2:Q5)) -> 3515.1482
A7: Credit Spread Corporate HY | B7: 100 | C7: 3 | D7: 100 | F7: =B7*D7 -> 10000
F8: =SUM(F2:F7) -> 93600

Sheet ES, All factor movement
B1: n=10 | C1: n=10, 20 | D1: n=10, 40 | E1: n=10, 60 | F1: n=10 | G1: n=10
B2: Treasury Bonds IG valuation | C2: Credit spread: Sovereign Bonds IG valuation | D2: Credit spread: sovereign (high yield, or HY) | E2: Credit Spread:Corporate HY | F2: MSFT | G2: Intel | H2: Portfolio value | I2: 10 day PnL | J2: VaR | K2: ES, Q(pi,1)
A3: 39261 | B3: =(3/(1+('CurrentPor-All Factor Movements'!B3)/100)+103/POWER(1+('CurrentPor-All Factor Movements'!C3)/100,2))*100 -> 9852.9654 | C3: =(3/(1+('CurrentPor-All Factor Movements'!B3+'CurrentPor-All Factor Movements'!F3)/100)+103/POWER(1+('CurrentPor-All Factor Movements'!C3+'CurrentPor-All Factor Movements'!F3)/100,2))*100 -> 9751.4034 | D3: =(3/(1+('CurrentPor-All Factor Movements'!B3+'CurrentPor-All Factor Movements'!G3)/100)+103/POWER(1+('CurrentPor-All Factor Movements'!C3+'CurrentPor-All Factor Movements'!G3)/100,2))*100 -> 9751.5888 | E3: =(3/(1+('CurrentPor-All Factor Movements'!B3+'CurrentPor-All Factor Movements'!H3)/100)+103/POWER(1+('CurrentPor-All Factor Movements'!C3+'CurrentPor-All Factor Movements'!H3)/100,2))*100 -> 9717.5027 | F3: =Portfolio!B$5*'CurrentPor-All Factor Movements'!D3 -> 53006.71 | G3: =Portfolio!B$6*'CurrentPor-All Factor Movements'!E3 -> 3848.6313 | H3: =SUM(B3:G3) -> 95928.802 | J3: =_xlfn.PERCENTILE.INC(I13:I263, 0.025) -> -3152.1892 | K3: =AVERAGEIF(I13:I263, "<="&J3,I13:I263) -> -3506.7804
A4: 39262 | B4: =(3/(1+('CurrentPor-All Factor Movements'!B4)/100)+103/POWER(1+('CurrentPor-All Factor Movements'!C4)/100,2))*100 -> 9755.2076 | C4: =(3/(1+('CurrentPor-All Factor Movements'!B4+'CurrentPor-All Factor Movements'!F4)/100)+103/POWER(1+('CurrentPor-All Factor Movements'!C4+'CurrentPor-All Factor Movements'!F4)/100,2))*100 -> 9667.9251 | D4: =(3/(1+('CurrentPor-All Factor Movements'!B4+'CurrentPor-All Factor Movements'!G4)/100)+103/POWER(1+('CurrentPor-All Factor Movements'!C4+'CurrentPor-All Factor Movements'!G4)/100,2))*100 -> 9627.5205 | E4: =(3/(1+('CurrentPor-All Factor Movements'!B4+'CurrentPor-All Factor Movements'!H4)/100)+103/POWER(1+('CurrentPor-All Factor Movements'!C4+'CurrentPor-All Factor Movements'!H4)/100,2))*100 -> 9655.0536 | F4: =Portfolio!B$5*'CurrentPor-All Factor Movements'!D4 -> 52282.8 | G4: =Portfolio!B$6*'CurrentPor-All Factor Movements'!E4 -> 3552.5856 | H4: =SUM(B4:G4) -> 94541.093
A5: 39265 | B5: =(3/(1+('CurrentPor-All Factor Movements'!B5)/100)+103/POWER(1+('CurrentPor-All Factor Movements'!C5)/100,2))*100 -> 9686.0403 | C5: =(3/(1+('CurrentPor-All Factor Movements'!B5+'CurrentPor-All Factor Movements'!F5)/100)+103/POWER(1+('CurrentPor-All Factor Movements'!C5+'CurrentPor-All Factor Movements'!F5)/100,2))*100 -> 9594.3172 | D5: =(3/(1+('CurrentPor-All Factor Movements'!B5+'CurrentPor-All Factor Movements'!G5)/100)+103/POWER(1+('CurrentPor-All Factor Movements'!C5+'CurrentPor-All Factor Movements'!G5)/100,2))*100 -> 9580.0434 | E5: =(3/(1+('CurrentPor-All Factor Movements'!B5+'CurrentPor-All Factor Movements'!H5)/100)+103/POWER(1+('CurrentPor-All Factor Movements'!C5+'CurrentPor-All Factor Movements'!H5)/100,2))*100 -> 9550.6464 | F5: =Portfolio!B$5*'CurrentPor-All Factor Movements'!D5 -> 51011.85 | G5: =Portfolio!B$6*'CurrentPor-All Factor Movements'!E5 -> 3637.8868 | H5: =SUM(B5:G5) -> 93060.784
A6: 39266 | B6: =(3/(1+('CurrentPor-All Factor Movements'!B6)/100)+103/POWER(1+('CurrentPor-All Factor Movements'!C6)/100,2))*100 -> 9784.0156 | C6: =(3/(1+('CurrentPor-All Factor Movements'!B6+'CurrentPor-All Factor Movements'!F6)/100)+103/POWER(1+('CurrentPor-All Factor Movements'!C6+'CurrentPor-All Factor Movements'!F6)/100,2))*100 -> 9697.5972 | D6: =(3/(1+('CurrentPor-All Factor Movements'!B6+'CurrentPor-All Factor Movements'!G6)/100)+103/POWER(1+('CurrentPor-All Factor Movements'!C6+'CurrentPor-All Factor Movements'!G6)/100,2))*100 -> 9670.7032 | E6: =(3/(1+('CurrentPor-All Factor Movements'!B6+'CurrentPor-All Factor Movements'!H6)/100)+103/POWER(1+('CurrentPor-All Factor Movements'!C6+'CurrentPor-All Factor Movements'!H6)/100,2))*100 -> 9648.003 | F6: =Portfolio!B$5*'CurrentPor-All Factor Movements'!D6 -> 51668.968 | G6: =Portfolio!B$6*'CurrentPor-All Factor Movements'!E6 -> 3613.8276 | H6: =SUM(B6:G6) -> 94083.115
A7: 39267 | B7: =(3/(1+('CurrentPor-All Factor Movements'!B7)/100)+103/POWER(1+('CurrentPor-All Factor Movements'!C7)/100,2))*100 -> 9738.1604 | C7: =(3/(1+('CurrentPor-All Factor Movements'!B7+'CurrentPor-All Factor Movements'!F7)/100)+103/POWER(1+('CurrentPor-All Factor Movements'!C7+'CurrentPor-All Factor Movements'!F7)/100,2))*100 -> 9640.1269 | D7: =(3/(1+('CurrentPor-All Factor Movements'!B7+'CurrentPor-All Factor Movements'!G7)/100)+103/POWER(1+('CurrentPor-All Factor Movements'!C7+'CurrentPor-All Factor Movements'!G7)/100,2))*100 -> 9631.6841 | E7: =(3/(1+('CurrentPor-All Factor Movements'!B7+'CurrentPor-All Factor Movements'!H7)/100)+103/POWER(1+('CurrentPor-All Factor Movements'!C7+'CurrentPor-All Factor Movements'!H7)/100,2))*100 -> 9629.2689 | F7: =Portfolio!B$5*'CurrentPor-All Factor Movements'!D7 -> 51190.516 | G7: =Portfolio!B$6*'CurrentPor-All Factor Movements'!E7 -> 3561.1754 | H7: =SUM(B7:G7) -> 93390.931
A8: 39268 | B8: =(3/(1+('CurrentPor-All Factor Movements'!B8)/100)+103/POWER(1+('CurrentPor-All Factor Movements'!C8)/100,2))*100 -> 9601.9559 | C8: =(3/(1+('CurrentPor-All Factor Movements'!B8+'CurrentPor-All Factor Movements'!F8)/100)+103/POWER(1+('CurrentPor-All Factor Movements'!C8+'CurrentPor-All Factor Movements'!F8)/100,2))*100 -> 9518.3064 | D8: =(3/(1+('CurrentPor-All Factor Movements'!B8+'CurrentPor-All Factor Movements'!G8)/100)+103/POWER(1+('CurrentPor-All Factor Movements'!C8+'CurrentPor-All Factor Movements'!G8)/100,2))*100 -> 9488.4288 | E8: =(3/(1+('CurrentPor-All Factor Movements'!B8+'CurrentPor-All Factor Movements'!H8)/100)+103/POWER(1+('CurrentPor-All Factor Movements'!C8+'CurrentPor-All Factor Movements'!H8)/100,2))*100 -> 9480.1441 | F8: =Portfolio!B$5*'CurrentPor-All Factor Movements'!D8 -> 51345.231 | G8: =Portfolio!B$6*'CurrentPor-All Factor Movements'!E8 -> 3770.9248 | H8: =SUM(B8:G8) -> 93204.991
A9: 39269 | B9: =(3/(1+('CurrentPor-All Factor Movements'!B9)/100)+103/POWER(1+('CurrentPor-All Factor Movements'!C9)/100,2))*100 -> 9562.8651 | C9: =(3/(1+('CurrentPor-All Factor Movements'!B9+'CurrentPor-All Factor Movements'!F9)/100)+103/POWER(1+('CurrentPor-All Factor Movements'!C9+'CurrentPor-All Factor Movements'!F9)/100,2))*100 -> 9471.5283 | D9: =(3/(1+('CurrentPor-All Factor Movements'!B9+'CurrentPor-All Factor Movements'!G9)/100)+103/POWER(1+('CurrentPor-All Factor Movements'!C9+'CurrentPor-All Factor Movements'!G9)/100,2))*100 -> 9462.2078 | E9: =(3/(1+('CurrentPor-All Factor Movements'!B9+'CurrentPor-All Factor Movements'!H9)/100)+103/POWER(1+('CurrentPor-All Factor Movements'!C9+'CurrentPor-All Factor Movements'!H9)/100,2))*100 -> 9442.5161 | F9: =Portfolio!B$5*'CurrentPor-All Factor Movements'!D9 -> 51933.854 | G9: =Portfolio!B$6*'CurrentPor-All Factor Movements'!E9 -> 3625.6978 | H9: =SUM(B9:G9) -> 93498.669
A10: 39272 | B10: =(3/(1+('CurrentPor-All Factor Movements'!B10)/100)+103/POWER(1+('CurrentPor-All Factor Movements'!C10)/100,2))*100 -> 9662.0924 | C10: =(3/(1+('CurrentPor-All Factor Movements'!B10+'CurrentPor-All Factor Movements'!F10)/100)+103/POWER(1+('CurrentPor-All Factor Movements'!C10+'CurrentPor-All Factor Movements'!F10)/100,2))*100 -> 9572.3353 | D10: =(3/(1+('CurrentPor-All Factor Movements'!B10+'CurrentPor-All Factor Movements'!G10)/100)+103/POWER(1+('CurrentPor-All Factor Movements'!C10+'CurrentPor-All Factor Movements'!G10)/100,2))*100 -> 9567.3284 | E10: =(3/(1+('CurrentPor-All Factor Movements'!B10+'CurrentPor-All Factor Movements'!H10)/100)+103/POWER(1+('CurrentPor-All Factor Movements'!C10+'CurrentPor-All Factor Movements'!H10)/100,2))*100 -> 9537.0074 | F10: =Portfolio!B$5*'CurrentPor-All Factor Movements'!D10 -> 51582.192 | G10: =Portfolio!B$6*'CurrentPor-All Factor Movements'!E10 -> 3511.2746 | H10: =SUM(B10:G10) -> 93432.23
A11: 39273 | B11: =(3/(1+('CurrentPor-All Factor Movements'!B11)/100)+103/POWER(1+('CurrentPor-All Factor Movements'!C11)/100,2))*100 -> 9712.0164 | C11: =(3/(1+('CurrentPor-All Factor Movements'!B11+'CurrentPor-All Factor Movements'!F11)/100)+103/POWER(1+('CurrentPor-All Factor Movements'!C11+'CurrentPor-All Factor Movements'!F11)/100,2))*100 -> 9627.1636 | D11: =(3/(1+('CurrentPor-All Factor Movements'!B11+'CurrentPor-All Factor Movements'!G11)/100)+103/POWER(1+('CurrentPor-All Factor Movements'!C11+'CurrentPor-All Factor Movements'!G11)/100,2))*100 -> 9595.6003 | E11: =(3/(1+('CurrentPor-All Factor Movements'!B11+'CurrentPor-All Factor Movements'!H11)/100)+103/POWER(1+('CurrentPor-All Factor Movements'!C11+'CurrentPor-All Factor Movements'!H11)/100,2))*100 -> 9587.5204 | F11: =Portfolio!B$5*'CurrentPor-All Factor Movements'!D11 -> 52918.295 | G11: =Portfolio!B$6*'CurrentPor-All Factor Movements'!E11 -> 3586.6392 | H11: =SUM(B11:G11) -> 95027.234
A12: 39274 | B12: =(3/(1+('CurrentPor-All Factor Movements'!B12)/100)+103/POWER(1+('CurrentPor-All Factor Movements'!C12)/100,2))*100 -> 9750.6059 | C12: =(3/(1+('CurrentPor-All Factor Movements'!B12+'CurrentPor-All Factor Movements'!F12)/100)+103/POWER(1+('CurrentPor-All Factor Movements'!C12+'CurrentPor-All Factor Movements'!F12)/100,2))*100 -> 9655.7197 | D12: =(3/(1+('CurrentPor-All Factor Movements'!B12+'CurrentPor-All Factor Movements'!G12)/100)+103/POWER(1+('CurrentPor-All Factor Movements'!C12+'CurrentPor-All Factor Movements'!G12)/100,2))*100 -> 9645.733 | E12: =(3/(1+('CurrentPor-All Factor Movements'!B12+'CurrentPor-All Factor Movements'!H12)/100)+103/POWER(1+('CurrentPor-All Factor Movements'!C12+'CurrentPor-All Factor Movements'!H12)/100,2))*100 -> 9613.2737 | F12: =Portfolio!B$5*'CurrentPor-All Factor Movements'!D12 -> 52877.176 | G12: =Portfolio!B$6*'CurrentPor-All Factor Movements'!E12 -> 3484.045 | H12: =SUM(B12:G12) -> 95026.553
A13: 39275 | B13: =(3/(1+('CurrentPor-All Factor Movements'!B13)/100)+103/POWER(1+('CurrentPor-All Factor Movements'!C13)/100,2))*100 -> 9571.1927 | C13: =(3/(1+('CurrentPor-All Factor Movements'!B13+'CurrentPor-All Factor Movements'!F13)/100)+103/POWER(1+('CurrentPor-All Factor Movements'!C13+'CurrentPor-All Factor Movements'!F13)/100,2))*100 -> 9474.1392 | D13: =(3/(1+('CurrentPor-All Factor Movements'!B13+'CurrentPor-All Factor Movements'!G13)/100)+103/POWER(1+('CurrentPor-All Factor Movements'!C13+'CurrentPor-All Factor Movements'!G13)/100,2))*100 -> 9468.2718 | E13: =(3/(1+('CurrentPor-All Factor Movements'!B13+'CurrentPor-All Factor Movements'!H13)/100)+103/POWER(1+('CurrentPor-All Factor Movements'!C13+'CurrentPor-All Factor Movements'!H13)/100,2))*100 -> 9451.4506 | F13: =Portfolio!B$5*'CurrentPor-All Factor Movements'!D13 -> 50946.564 | G13: =Portfolio!B$6*'CurrentPor-All Factor Movements'!E13 -> 3881.2221 | H13: =SUM(B13:G13) -> 92792.841 | I13: =H13-H3 -> -3135.9611
A14: 39276 | B14: =(3/(1+('CurrentPor-All Factor Movements'!B14)/100)+103/POWER(1+('CurrentPor-All Factor Movements'!C14)/100,2))*100 -> 9730.2558 | C14: =(3/(1+('CurrentPor-All Factor Movements'!B14+'CurrentPor-All Factor Movements'!F14)/100)+103/POWER(1+('CurrentPor-All Factor Movements'!C14+'CurrentPor-All Factor Movements'!F14)/100,2))*100 -> 9628.6049 | D14: =(3/(1+('CurrentPor-All Factor Movements'!B14+'CurrentPor-All Factor Movements'!G14)/100)+103/POWER(1+('CurrentPor-All Factor Movements'!C14+'CurrentPor-All Factor Movements'!G14)/100,2))*100 -> 9610.1124 | E14: =(3/(1+('CurrentPor-All Factor Movements'!B14+'CurrentPor-All Factor Movements'!H14)/100)+103/POWER(1+('CurrentPor-All Factor Movements'!C14+'CurrentPor-All Factor Movements'!H14)/100,2))*100 -> 9612.0126 | F14: =Portfolio!B$5*'CurrentPor-All Factor Movements'!D14 -> 54408.626 | G14: =Portfolio!B$6*'CurrentPor-All Factor Movements'!E14 -> 3656.6971 | H14: =SUM(B14:G14) -> 96646.309 | I14: =H14-H4 -> 2105.2165
A15: 39279 | B15: =(3/(1+('CurrentPor-All Factor Movements'!B15)/100)+103/POWER(1+('CurrentPor-All Factor Movements'!C15)/100,2))*100 -> 9666.4742 | C15: =(3/(1+('CurrentPor-All Factor Movements'!B15+'CurrentPor-All Factor Movements'!F15)/100)+103/POWER(1+('CurrentPor-All Factor Movements'!C15+'CurrentPor-All Factor Movements'!F15)/100,2))*100 -> 9578.152 | D15: =(3/(1+('CurrentPor-All Factor Movements'!B15+'CurrentPor-All Factor Movements'!G15)/100)+103/POWER(1+('CurrentPor-All Factor Movements'!C15+'CurrentPor-All Factor Movements'!G15)/100,2))*100 -> 9564.7146 | E15: =(3/(1+('CurrentPor-All Factor Movements'!B15+'CurrentPor-All Factor Movements'!H15)/100)+103/POWER(1+('CurrentPor-All Factor Movements'!C15+'CurrentPor-All Factor Movements'!H15)/100,2))*100 -> 9546.3969 | F15: =Portfolio!B$5*'CurrentPor-All Factor Movements'!D15 -> 53948.766 | G15: =Portfolio!B$6*'CurrentPor-All Factor Movements'!E15 -> 3392.1065 | H15: =SUM(B15:G15) -> 95696.61 | I15: =H15-H5 -> 2635.8265
A16: 39280 | B16: =(3/(1+('CurrentPor-All Factor Movements'!B16)/100)+103/POWER(1+('CurrentPor-All Factor Movements'!C16)/100,2))*100 -> 9607.9795 | C16: =(3/(1+('CurrentPor-All Factor Movements'!B16+'CurrentPor-All Factor Movements'!F16)/100)+103/POWER(1+('CurrentPor-All Factor Movements'!C16+'CurrentPor-All Factor Movements'!F16)/100,2))*100 -> 9517.6032 | D16: =(3/(1+('CurrentPor-All Factor Movements'!B16+'CurrentPor-All Factor Movements'!G16)/100)+103/POWER(1+('CurrentPor-All Factor Movements'!C16+'CurrentPor-All Factor Movements'!G16)/100,2))*100 -> 9494.8547 | E16: =(3/(1+('CurrentPor-All Factor Movements'!B16+'CurrentPor-All Factor Movements'!H16)/100)+103/POWER(1+('CurrentPor-All Factor Movements'!C16+'CurrentPor-All Factor Movements'!H16)/100,2))*100 -> 9485.8533 | F16: =Portfolio!B$5*'CurrentPor-All Factor Movements'!D16 -> 52647.21 | G16: =Portfolio!B$6*'CurrentPor-All Factor Movements'!E16 -> 3870.626 | H16: =SUM(B16:G16) -> 94624.127 | I16: =H16-H6 -> 541.01225
A17: 39281 | B17: =(3/(1+('CurrentPor-All Factor Movements'!B17)/100)+103/POWER(1+('CurrentPor-All Factor Movements'!C17)/100,2))*100 -> 9638.9087 | C17: =(3/(1+('CurrentPor-All Factor Movements'!B17+'CurrentPor-All Factor Movements'!F17)/100)+103/POWER(1+('CurrentPor-All Factor Movements'!C17+'CurrentPor-All Factor Movements'!F17)/100,2))*100 -> 9544.0302 | D17: =(3/(1+('CurrentPor-All Factor Movements'!B17+'CurrentPor-All Factor Movements'!G17)/100)+103/POWER(1+('CurrentPor-All Factor Movements'!C17+'CurrentPor-All Factor Movements'!G17)/100,2))*100 -> 9551.5923 | E17: =(3/(1+('CurrentPor-All Factor Movements'!B17+'CurrentPor-All Factor Movements'!H17)/100)+103/POWER(1+('CurrentPor-All Factor Movements'!C17+'CurrentPor-All Factor Movements'!H17)/100,2))*100 -> 9506.4246 | F17: =Portfolio!B$5*'CurrentPor-All Factor Movements'!D17 -> 52006.071 | G17: =Portfolio!B$6*'CurrentPor-All Factor Movements'!E17 -> 3649.8394 | H17: =SUM(B17:G17) -> 93896.867 | I17: =H17-H7 -> 505.93539
A18: 39282 | B18: =(3/(1+('CurrentPor-All Factor Movements'!B18)/100)+103/POWER(1+('CurrentPor-All Factor Movements'!C18)/100,2))*100 -> 9985.3822 | C18: =(3/(1+('CurrentPor-All Factor Movements'!B18+'CurrentPor-All Factor Movements'!F18)/100)+103/POWER(1+('CurrentPor-All Factor Movements'!C18+'CurrentPor-All Factor Movements'!F18)/100,2))*100 -> 9887.9613 | D18: =(3/(1+('CurrentPor-All Factor Movements'!B18+'CurrentPor-All Factor Movements'!G18)/100)+103/POWER(1+('CurrentPor-All Factor Movements'!C18+'CurrentPor-All Factor Movements'!G18)/100,2))*100 -> 9862.8757 | E18: =(3/(1+('CurrentPor-All Factor Movements'!B18+'CurrentPor-All Factor Movements'!H18)/100)+103/POWER(1+('CurrentPor-All Factor Movements'!C18+'CurrentPor-All Factor Movements'!H18)/100,2))*100 -> 9826.256 | F18: =Portfolio!B$5*'CurrentPor-All Factor Movements'!D18 -> 52195.677 | G18: =Portfolio!B$6*'CurrentPor-All Factor Movements'!E18 -> 3504.6739 | H18: =SUM(B18:G18) -> 95262.826 | I18: =H18-H8 -> 2057.8343
A19: 39283 | B19: =(3/(1+('CurrentPor-All Factor Movements'!B19)/100)+103/POWER(1+('CurrentPor-All Factor Movements'!C19)/100,2))*100 -> 9506.7158 | C19: =(3/(1+('CurrentPor-All Factor Movements'!B19+'CurrentPor-All Factor Movements'!F19)/100)+103/POWER(1+('CurrentPor-All Factor Movements'!C19+'CurrentPor-All Factor Movements'!F19)/100,2))*100 -> 9424.0182 | D19: =(3/(1+('CurrentPor-All Factor Movements'!B19+'CurrentPor-All Factor Movements'!G19)/100)+103/POWER(1+('CurrentPor-All Factor Movements'!C19+'CurrentPor-All Factor Movements'!G19)/100,2))*100 -> 9415.1688 | E19: =(3/(1+('CurrentPor-All Factor Movements'!B19+'CurrentPor-All Factor Movements'!H19)/100)+103/POWER(1+('CurrentPor-All Factor Movements'!C19+'CurrentPor-All Factor Movements'!H19)/100,2))*100 -> 9380.0328 | F19: =Portfolio!B$5*'CurrentPor-All Factor Movements'!D19 -> 52357.378 | G19: =Portfolio!B$6*'CurrentPor-All Factor Movements'!E19 -> 3703.6454 | H19: =SUM(B19:G19) -> 93786.959 | I19: =H19-H9 -> 288.28992
A20: 39286 | B20: =(3/(1+('CurrentPor-All Factor Movements'!B20)/100)+103/POWER(1+('CurrentPor-All Factor Movements'!C20)/100,2))*100 -> 9661.4502 | C20: =(3/(1+('CurrentPor-All Factor Movements'!B20+'CurrentPor-All Factor Movements'!F20)/100)+103/POWER(1+('CurrentPor-All Factor Movements'!C20+'CurrentPor-All Factor Movements'!F20)/100,2))*100 -> 9582.6587 | D20: =(3/(1+('CurrentPor-All Factor Movements'!B20+'CurrentPor-All Factor Movements'!G20)/100)+103/POWER(1+('CurrentPor-All Factor Movements'!C20+'CurrentPor-All Factor Movements'!G20)/100,2))*100 -> 9554.0767 | E20: =(3/(1+('CurrentPor-All Factor Movements'!B20+'CurrentPor-All Factor Movements'!H20)/100)+103/POWER(1+('CurrentPor-All Factor Movements'!C20+'CurrentPor-All Factor Movements'!H20)/100,2))*100 -> 9543.1357 | F20: =Portfolio!B$5*'CurrentPor-All Factor Movements'!D20 -> 51942.921 | G20: =Portfolio!B$6*'CurrentPor-All Factor Movements'!E20 -> 3347.2186 | H20: =SUM(B20:G20) -> 93631.461 | I20: =H20-H10 -> 199.23114
A21: 39287 | B21: =(3/(1+('CurrentPor-All Factor Movements'!B21)/100)+103/POWER(1+('CurrentPor-All Factor Movements'!C21)/100,2))*100 -> 9843.5831 | C21: =(3/(1+('CurrentPor-All Factor Movements'!B21+'CurrentPor-All Factor Movements'!F21)/100)+103/POWER(1+('CurrentPor-All Factor Movements'!C21+'CurrentPor-All Factor Movements'!F21)/100,2))*100 -> 9748.9856 | D21: =(3/(1+('CurrentPor-All Factor Movements'!B21+'CurrentPor-All Factor Movements'!G21)/100)+103/POWER(1+('CurrentPor-All Factor Movements'!C21+'CurrentPor-All Factor Movements'!G21)/100,2))*100 -> 9716.9629 | E21: =(3/(1+('CurrentPor-All Factor Movements'!B21+'CurrentPor-All Factor Movements'!H21)/100)+103/POWER(1+('CurrentPor-All Factor Movements'!C21+'CurrentPor-All Factor Movements'!H21)/100,2))*100 -> 9709.753 | F21: =Portfolio!B$5*'CurrentPor-All Factor Movements'!D21 -> 53461.004 | G21: =Portfolio!B$6*'CurrentPor-All Factor Movements'!E21 -> 3668.1117 | H21: =SUM(B21:G21) -> 96148.4 | I21: =H21-H11 -> 1121.1657
A22: 39288 | B22: =(3/(1+('CurrentPor-All Factor Movements'!B22)/100)+103/POWER(1+('CurrentPor-All Factor Movements'!C22)/100,2))*100 -> 9751.3225 | C22: =(3/(1+('CurrentPor-All Factor Movements'!B22+'CurrentPor-All Factor Movements'!F22)/100)+103/POWER(1+('CurrentPor-All Factor Movements'!C22+'CurrentPor-All Factor Movements'!F22)/100,2))*100 -> 9646.8006 | D22: =(3/(1+('CurrentPor-All Factor Movements'!B22+'CurrentPor-All Factor Movements'!G22)/100)+103/POWER(1+('CurrentPor-All Factor Movements'!C22+'CurrentPor-All Factor Movements'!G22)/100,2))*100 -> 9647.3145 | E22: =(3/(1+('CurrentPor-All Factor Movements'!B22+'CurrentPor-All Factor Movements'!H22)/100)+103/POWER(1+('CurrentPor-All Factor Movements'!C22+'CurrentPor-All Factor Movements'!H22)/100,2))*100 -> 9618.7275 | F22: =Portfolio!B$5*'CurrentPor-All Factor Movements'!D22 -> 52396.808 | G22: =Portfolio!B$6*'CurrentPor-All Factor Movements'!E22 -> 3507.856 | H22: =SUM(B22:G22) -> 94568.829 | I22: =H22-H12 -> -457.72355
A23: 39289 | B23: =(3/(1+('CurrentPor-All Factor Movements'!B23)/100)+103/POWER(1+('CurrentPor-All Factor Movements'!C23)/100,2))*100 -> 9750.9856 | C23: =(3/(1+('CurrentPor-All Factor Movements'!B23+'CurrentPor-All Factor Movements'!F23)/100)+103/POWER(1+('CurrentPor-All Factor Movements'!C23+'CurrentPor-All Factor Movements'!F23)/100,2))*100 -> 9646.6598 | D23: =(3/(1+('CurrentPor-All Factor Movements'!B23+'CurrentPor-All Factor Movements'!G23)/100)+103/POWER(1+('CurrentPor-All Factor Movements'!C23+'CurrentPor-All Factor Movements'!G23)/100,2))*100 -> 9628.3442 | E23: =(3/(1+('CurrentPor-All Factor Movements'!B23+'CurrentPor-All Factor Movements'!H23)/100)+103/POWER(1+('CurrentPor-All Factor Movements'!C23+'CurrentPor-All Factor Movements'!H23)/100,2))*100 -> 9648.5943 | F23: =Portfolio!B$5*'CurrentPor-All Factor Movements'!D23 -> 51493.5 | G23: =Portfolio!B$6*'CurrentPor-All Factor Movements'!E23 -> 3468.3566 | H23: =SUM(B23:G23) -> 93636.441 | I23: =H23-H13 -> 843.60007
A24: 39290 | B24: =(3/(1+('CurrentPor-All Factor Movements'!B24)/100)+103/POWER(1+('CurrentPor-All Factor Movements'!C24)/100,2))*100 -> 9768.1679 | C24: =(3/(1+('CurrentPor-All Factor Movements'!B24+'CurrentPor-All Factor Movements'!F24)/100)+103/POWER(1+('CurrentPor-All Factor Movements'!C24+'CurrentPor-All Factor Movements'!F24)/100,2))*100 -> 9677.4409 | D24: =(3/(1+('CurrentPor-All Factor Movements'!B24+'CurrentPor-All Factor Movements'!G24)/100)+103/POWER(1+('CurrentPor-All Factor Movements'!C24+'CurrentPor-All Factor Movements'!G24)/100,2))*100 -> 9647.1861 | E24: =(3/(1+('CurrentPor-All Factor Movements'!B24+'CurrentPor-All Factor Movements'!H24)/100)+103/POWER(1+('CurrentPor-All Factor Movements'!C24+'CurrentPor-All Factor Movements'!H24)/100,2))*100 -> 9629.6562 | F24: =Portfolio!B$5*'CurrentPor-All Factor Movements'!D24 -> 51737.828 | G24: =Portfolio!B$6*'CurrentPor-All Factor Movements'!E24 -> 3669.7269 | H24: =SUM(B24:G24) -> 94130.006 | I24: =H24-H14 -> -2516.3032
... A263: 39625 | B263: =(3/(1+('CurrentPor-All Factor Movements'!B263)/100)+103/POWER(1+('CurrentPor-All Factor Movements'!C263)/100,2))*100 -> 9685.3179 | C263: =(3/(1+('CurrentPor-All Factor Movements'!B263+'CurrentPor-All Factor Movements'!F263)/100)+103/POWER(1+('CurrentPor-All Factor Movements'!C263+'CurrentPor-All Factor Movements'!F263)/100,2))*100 -> 9578.0063 | D263: =(3/(1+('CurrentPor-All Factor Movements'!B263+'CurrentPor-All Factor Movements'!G263)/100)+103/POWER(1+('CurrentPor-All Factor Movements'!C263+'CurrentPor-All Factor Movements'!G263)/100,2))*100 -> 9569.2978 | E263: =(3/(1+('CurrentPor-All Factor Movements'!B263+'CurrentPor-All Factor Movements'!H263)/100)+103/POWER(1+('CurrentPor-All Factor Movements'!C263+'CurrentPor-All Factor Movements'!H263)/100,2))*100 -> 9571.8546 | F263: =Portfolio!B$5*'CurrentPor-All Factor Movements'!D263 -> 51079.332 | G263: =Portfolio!B$6*'CurrentPor-All Factor Movements'!E263 -> 3615.2701 | H263: =SUM(B263:G263) -> 93099.079 | I263: =H263-H253 -> -1467.2692

Sheet ES,N10 unchanged
B1: n=10 | C1: n=10, 20 | D1: n=10, 40 | E1: n=10, 60 | F1: n=10 | G1: n=10
B2: Treasury Bonds IG valuation | C2: Credit spread: Sovereign Bonds IG valuation | D2: Credit spread: sovereign (high yield, or HY) | E2: Credit Spread:Corporate HY | F2: MSFT | G2: Intel | H2: Portfolio value | I2: 10 day PnL | J2: VaR | K2: ES, Q(pi,2)
A3: 39261 | B3: =(3/(1+('CurrentPor-N10Unchanged'!B3)/100)+103/POWER(1+('CurrentPor-N10Unchanged'!C3)/100,2))*100 -> 9707.5858 | C3: =(3/(1+('CurrentPor-N10Unchanged'!B3+'CurrentPor-N10Unchanged'!F3)/100)+103/POWER(1+('CurrentPor-N10Unchanged'!C3+'CurrentPor-N10Unchanged'!F3)/100,2))*100 -> 9614.9674 | D3: =(3/(1+('CurrentPor-N10Unchanged'!B3+'CurrentPor-N10Unchanged'!G3)/100)+103/POWER(1+('CurrentPor-N10Unchanged'!C3+'CurrentPor-N10Unchanged'!G3)/100,2))*100 -> 9601.2396 | E3: =(3/(1+('CurrentPor-N10Unchanged'!B3+'CurrentPor-N10Unchanged'!H3)/100)+103/POWER(1+('CurrentPor-N10Unchanged'!C3+'CurrentPor-N10Unchanged'!H3)/100,2))*100 -> 9676.6908 | F3: =Portfolio!B$5*'CurrentPor-N10Unchanged'!D3 -> 52143.896 | G3: =Portfolio!B$6*'CurrentPor-N10Unchanged'!E3 -> 3696.2945 | H3: =SUM(B3:G3) -> 94440.674 | J3: =_xlfn.PERCENTILE.INC(I13:I263, 0.025) -> -111.16185 | K3: =AVERAGEIF(I13:I263, "<="&J3,I13:I263) -> -136.7897
A4: 39262 | B4: =(3/(1+('CurrentPor-N10Unchanged'!B4)/100)+103/POWER(1+('CurrentPor-N10Unchanged'!C4)/100,2))*100 -> 9707.5858 | C4: =(3/(1+('CurrentPor-N10Unchanged'!B4+'CurrentPor-N10Unchanged'!F4)/100)+103/POWER(1+('CurrentPor-N10Unchanged'!C4+'CurrentPor-N10Unchanged'!F4)/100,2))*100 -> 9614.9674 | D4: =(3/(1+('CurrentPor-N10Unchanged'!B4+'CurrentPor-N10Unchanged'!G4)/100)+103/POWER(1+('CurrentPor-N10Unchanged'!C4+'CurrentPor-N10Unchanged'!G4)/100,2))*100 -> 9586.7536 | E4: =(3/(1+('CurrentPor-N10Unchanged'!B4+'CurrentPor-N10Unchanged'!H4)/100)+103/POWER(1+('CurrentPor-N10Unchanged'!C4+'CurrentPor-N10Unchanged'!H4)/100,2))*100 -> 9676.5087 | F4: =Portfolio!B$5*'CurrentPor-N10Unchanged'!D4 -> 52143.896 | G4: =Portfolio!B$6*'CurrentPor-N10Unchanged'!E4 -> 3696.2945 | H4: =SUM(B4:G4) -> 94426.006
A5: 39265 | B5: =(3/(1+('CurrentPor-N10Unchanged'!B5)/100)+103/POWER(1+('CurrentPor-N10Unchanged'!C5)/100,2))*100 -> 9707.5858 | C5: =(3/(1+('CurrentPor-N10Unchanged'!B5+'CurrentPor-N10Unchanged'!F5)/100)+103/POWER(1+('CurrentPor-N10Unchanged'!C5+'CurrentPor-N10Unchanged'!F5)/100,2))*100 -> 9614.9674 | D5: =(3/(1+('CurrentPor-N10Unchanged'!B5+'CurrentPor-N10Unchanged'!G5)/100)+103/POWER(1+('CurrentPor-N10Unchanged'!C5+'CurrentPor-N10Unchanged'!G5)/100,2))*100 -> 9603.463 | E5: =(3/(1+('CurrentPor-N10Unchanged'!B5+'CurrentPor-N10Unchanged'!H5)/100)+103/POWER(1+('CurrentPor-N10Unchanged'!C5+'CurrentPor-N10Unchanged'!H5)/100,2))*100 -> 9676.3449 | F5: =Portfolio!B$5*'CurrentPor-N10Unchanged'!D5 -> 52143.896 | G5: =Portfolio!B$6*'CurrentPor-N10Unchanged'!E5 -> 3696.2945 | H5: =SUM(B5:G5) -> 94442.551
A6: 39266 | B6: =(3/(1+('CurrentPor-N10Unchanged'!B6)/100)+103/POWER(1+('CurrentPor-N10Unchanged'!C6)/100,2))*100 -> 9707.5858 | C6: =(3/(1+('CurrentPor-N10Unchanged'!B6+'CurrentPor-N10Unchanged'!F6)/100)+103/POWER(1+('CurrentPor-N10Unchanged'!C6+'CurrentPor-N10Unchanged'!F6)/100,2))*100 -> 9614.9674 | D6: =(3/(1+('CurrentPor-N10Unchanged'!B6+'CurrentPor-N10Unchanged'!G6)/100)+103/POWER(1+('CurrentPor-N10Unchanged'!C6+'CurrentPor-N10Unchanged'!G6)/100,2))*100 -> 9607.0115 | E6: =(3/(1+('CurrentPor-N10Unchanged'!B6+'CurrentPor-N10Unchanged'!H6)/100)+103/POWER(1+('CurrentPor-N10Unchanged'!C6+'CurrentPor-N10Unchanged'!H6)/100,2))*100 -> 9674.7614 | F6: =Portfolio!B$5*'CurrentPor-N10Unchanged'!D6 -> 52143.896 | G6: =Portfolio!B$6*'CurrentPor-N10Unchanged'!E6 -> 3696.2945 | H6: =SUM(B6:G6) -> 94444.516
A7: 39267 | B7: =(3/(1+('CurrentPor-N10Unchanged'!B7)/100)+103/POWER(1+('CurrentPor-N10Unchanged'!C7)/100,2))*100 -> 9707.5858 | C7: =(3/(1+('CurrentPor-N10Unchanged'!B7+'CurrentPor-N10Unchanged'!F7)/100)+103/POWER(1+('CurrentPor-N10Unchanged'!C7+'CurrentPor-N10Unchanged'!F7)/100,2))*100 -> 9616.7705 | D7: =(3/(1+('CurrentPor-N10Unchanged'!B7+'CurrentPor-N10Unchanged'!G7)/100)+103/POWER(1+('CurrentPor-N10Unchanged'!C7+'CurrentPor-N10Unchanged'!G7)/100,2))*100 -> 9580.3056 | E7: =(3/(1+('CurrentPor-N10Unchanged'!B7+'CurrentPor-N10Unchanged'!H7)/100)+103/POWER(1+('CurrentPor-N10Unchanged'!C7+'CurrentPor-N10Unchanged'!H7)/100,2))*100 -> 9676.8 | F7: =Portfolio!B$5*'CurrentPor-N10Unchanged'!D7 -> 52143.896 | G7: =Portfolio!B$6*'CurrentPor-N10Unchanged'!E7 -> 3696.2945 | H7: =SUM(B7:G7) -> 94421.652
A8: 39268 | B8: =(3/(1+('CurrentPor-N10Unchanged'!B8)/100)+103/POWER(1+('CurrentPor-N10Unchanged'!C8)/100,2))*100 -> 9707.5858 | C8: =(3/(1+('CurrentPor-N10Unchanged'!B8+'CurrentPor-N10Unchanged'!F8)/100)+103/POWER(1+('CurrentPor-N10Unchanged'!C8+'CurrentPor-N10Unchanged'!F8)/100,2))*100 -> 9613.1647 | D8: =(3/(1+('CurrentPor-N10Unchanged'!B8+'CurrentPor-N10Unchanged'!G8)/100)+103/POWER(1+('CurrentPor-N10Unchanged'!C8+'CurrentPor-N10Unchanged'!G8)/100,2))*100 -> 9582.0864 | E8: =(3/(1+('CurrentPor-N10Unchanged'!B8+'CurrentPor-N10Unchanged'!H8)/100)+103/POWER(1+('CurrentPor-N10Unchanged'!C8+'CurrentPor-N10Unchanged'!H8)/100,2))*100 -> 9676.1811 | F8: =Portfolio!B$5*'CurrentPor-N10Unchanged'!D8 -> 52143.896 | G8: =Portfolio!B$6*'CurrentPor-N10Unchanged'!E8 -> 3696.2945 | H8: =SUM(B8:G8) -> 94419.208
A9: 39269 | B9: =(3/(1+('CurrentPor-N10Unchanged'!B9)/100)+103/POWER(1+('CurrentPor-N10Unchanged'!C9)/100,2))*100 -> 9707.5858 | C9: =(3/(1+('CurrentPor-N10Unchanged'!B9+'CurrentPor-N10Unchanged'!F9)/100)+103/POWER(1+('CurrentPor-N10Unchanged'!C9+'CurrentPor-N10Unchanged'!F9)/100,2))*100 -> 9613.1647 | D9: =(3/(1+('CurrentPor-N10Unchanged'!B9+'CurrentPor-N10Unchanged'!G9)/100)+103/POWER(1+('CurrentPor-N10Unchanged'!C9+'CurrentPor-N10Unchanged'!G9)/100,2))*100 -> 9594.9699 | E9: =(3/(1+('CurrentPor-N10Unchanged'!B9+'CurrentPor-N10Unchanged'!H9)/100)+103/POWER(1+('CurrentPor-N10Unchanged'!C9+'CurrentPor-N10Unchanged'!H9)/100,2))*100 -> 9673.7787 | F9: =Portfolio!B$5*'CurrentPor-N10Unchanged'!D9 -> 52143.896 | G9: =Portfolio!B$6*'CurrentPor-N10Unchanged'!E9 -> 3696.2945 | H9: =SUM(B9:G9) -> 94429.689
A10: 39272 | B10: =(3/(1+('CurrentPor-N10Unchanged'!B10)/100)+103/POWER(1+('CurrentPor-N10Unchanged'!C10)/100,2))*100 -> 9707.5858 | C10: =(3/(1+('CurrentPor-N10Unchanged'!B10+'CurrentPor-N10Unchanged'!F10)/100)+103/POWER(1+('CurrentPor-N10Unchanged'!C10+'CurrentPor-N10Unchanged'!F10)/100,2))*100 -> 9614.9674 | D10: =(3/(1+('CurrentPor-N10Unchanged'!B10+'CurrentPor-N10Unchanged'!G10)/100)+103/POWER(1+('CurrentPor-N10Unchanged'!C10+'CurrentPor-N10Unchanged'!G10)/100,2))*100 -> 9593.3699 | E10: =(3/(1+('CurrentPor-N10Unchanged'!B10+'CurrentPor-N10Unchanged'!H10)/100)+103/POWER(1+('CurrentPor-N10Unchanged'!C10+'CurrentPor-N10Unchanged'!H10)/100,2))*100 -> 9671.0498 | F10: =Portfolio!B$5*'CurrentPor-N10Unchanged'!D10 -> 52143.896 | G10: =Portfolio!B$6*'CurrentPor-N10Unchanged'!E10 -> 3696.2945 | H10: =SUM(B10:G10) -> 94427.163
A11: 39273 | B11: =(3/(1+('CurrentPor-N10Unchanged'!B11)/100)+103/POWER(1+('CurrentPor-N10Unchanged'!C11)/100,2))*100 -> 9707.5858 | C11: =(3/(1+('CurrentPor-N10Unchanged'!B11+'CurrentPor-N10Unchanged'!F11)/100)+103/POWER(1+('CurrentPor-N10Unchanged'!C11+'CurrentPor-N10Unchanged'!F11)/100,2))*100 -> 9614.9674 | D11: =(3/(1+('CurrentPor-N10Unchanged'!B11+'CurrentPor-N10Unchanged'!G11)/100)+103/POWER(1+('CurrentPor-N10Unchanged'!C11+'CurrentPor-N10Unchanged'!G11)/100,2))*100 -> 9596.8686 | E11: =(3/(1+('CurrentPor-N10Unchanged'!B11+'CurrentPor-N10Unchanged'!H11)/100)+103/POWER(1+('CurrentPor-N10Unchanged'!C11+'CurrentPor-N10Unchanged'!H11)/100,2))*100 -> 9672.6688 | F11: =Portfolio!B$5*'CurrentPor-N10Unchanged'!D11 -> 52143.896 | G11: =Portfolio!B$6*'CurrentPor-N10Unchanged'!E11 -> 3696.2945 | H11: =SUM(B11:G11) -> 94432.281
A12: 39274 | B12: =(3/(1+('CurrentPor-N10Unchanged'!B12)/100)+103/POWER(1+('CurrentPor-N10Unchanged'!C12)/100,2))*100 -> 9707.5858 | C12: =(3/(1+('CurrentPor-N10Unchanged'!B12+'CurrentPor-N10Unchanged'!F12)/100)+103/POWER(1+('CurrentPor-N10Unchanged'!C12+'CurrentPor-N10Unchanged'!F12)/100,2))*100 -> 9614.9674 | D12: =(3/(1+('CurrentPor-N10Unchanged'!B12+'CurrentPor-N10Unchanged'!G12)/100)+103/POWER(1+('CurrentPor-N10Unchanged'!C12+'CurrentPor-N10Unchanged'!G12)/100,2))*100 -> 9593.7415 | E12: =(3/(1+('CurrentPor-N10Unchanged'!B12+'CurrentPor-N10Unchanged'!H12)/100)+103/POWER(1+('CurrentPor-N10Unchanged'!C12+'CurrentPor-N10Unchanged'!H12)/100,2))*100 -> 9674.8342 | F12: =Portfolio!B$5*'CurrentPor-N10Unchanged'!D12 -> 52143.896 | G12: =Portfolio!B$6*'CurrentPor-N10Unchanged'!E12 -> 3696.2945 | H12: =SUM(B12:G12) -> 94431.319
A13: 39275 | B13: =(3/(1+('CurrentPor-N10Unchanged'!B13)/100)+103/POWER(1+('CurrentPor-N10Unchanged'!C13)/100,2))*100 -> 9707.5858 | C13: =(3/(1+('CurrentPor-N10Unchanged'!B13+'CurrentPor-N10Unchanged'!F13)/100)+103/POWER(1+('CurrentPor-N10Unchanged'!C13+'CurrentPor-N10Unchanged'!F13)/100,2))*100 -> 9620.3784 | D13: =(3/(1+('CurrentPor-N10Unchanged'!B13+'CurrentPor-N10Unchanged'!G13)/100)+103/POWER(1+('CurrentPor-N10Unchanged'!C13+'CurrentPor-N10Unchanged'!G13)/100,2))*100 -> 9583.1353 | E13: =(3/(1+('CurrentPor-N10Unchanged'!B13+'CurrentPor-N10Unchanged'!H13)/100)+103/POWER(1+('CurrentPor-N10Unchanged'!C13+'CurrentPor-N10Unchanged'!H13)/100,2))*100 -> 9679.0214 | F13: =Portfolio!B$5*'CurrentPor-N10Unchanged'!D13 -> 52143.896 | G13: =Portfolio!B$6*'CurrentPor-N10Unchanged'!E13 -> 3696.2945 | H13: =SUM(B13:G13) -> 94430.311 | I13: =H13-H3 -> -10.362633
A14: 39276 | B14: =(3/(1+('CurrentPor-N10Unchanged'!B14)/100)+103/POWER(1+('CurrentPor-N10Unchanged'!C14)/100,2))*100 -> 9707.5858 | C14: =(3/(1+('CurrentPor-N10Unchanged'!B14+'CurrentPor-N10Unchanged'!F14)/100)+103/POWER(1+('CurrentPor-N10Unchanged'!C14+'CurrentPor-N10Unchanged'!F14)/100,2))*100 -> 9616.7705 | D14: =(3/(1+('CurrentPor-N10Unchanged'!B14+'CurrentPor-N10Unchanged'!G14)/100)+103/POWER(1+('CurrentPor-N10Unchanged'!C14+'CurrentPor-N10Unchanged'!G14)/100,2))*100 -> 9608.4612 | E14: =(3/(1+('CurrentPor-N10Unchanged'!B14+'CurrentPor-N10Unchanged'!H14)/100)+103/POWER(1+('CurrentPor-N10Unchanged'!C14+'CurrentPor-N10Unchanged'!H14)/100,2))*100 -> 9680.9339 | F14: =Portfolio!B$5*'CurrentPor-N10Unchanged'!D14 -> 52143.896 | G14: =Portfolio!B$6*'CurrentPor-N10Unchanged'!E14 -> 3696.2945 | H14: =SUM(B14:G14) -> 94453.941 | I14: =H14-H4 -> 27.935884
A15: 39279 | B15: =(3/(1+('CurrentPor-N10Unchanged'!B15)/100)+103/POWER(1+('CurrentPor-N10Unchanged'!C15)/100,2))*100 -> 9707.5858 | C15: =(3/(1+('CurrentPor-N10Unchanged'!B15+'CurrentPor-N10Unchanged'!F15)/100)+103/POWER(1+('CurrentPor-N10Unchanged'!C15+'CurrentPor-N10Unchanged'!F15)/100,2))*100 -> 9616.7705 | D15: =(3/(1+('CurrentPor-N10Unchanged'!B15+'CurrentPor-N10Unchanged'!G15)/100)+103/POWER(1+('CurrentPor-N10Unchanged'!C15+'CurrentPor-N10Unchanged'!G15)/100,2))*100 -> 9605.532 | E15: =(3/(1+('CurrentPor-N10Unchanged'!B15+'CurrentPor-N10Unchanged'!H15)/100)+103/POWER(1+('CurrentPor-N10Unchanged'!C15+'CurrentPor-N10Unchanged'!H15)/100,2))*100 -> 9680.6971 | F15: =Portfolio!B$5*'CurrentPor-N10Unchanged'!D15 -> 52143.896 | G15: =Portfolio!B$6*'CurrentPor-N10Unchanged'!E15 -> 3696.2945 | H15: =SUM(B15:G15) -> 94450.775 | I15: =H15-H5 -> 8.224393
A16: 39280 | B16: =(3/(1+('CurrentPor-N10Unchanged'!B16)/100)+103/POWER(1+('CurrentPor-N10Unchanged'!C16)/100,2))*100 -> 9707.5858 | C16: =(3/(1+('CurrentPor-N10Unchanged'!B16+'CurrentPor-N10Unchanged'!F16)/100)+103/POWER(1+('CurrentPor-N10Unchanged'!C16+'CurrentPor-N10Unchanged'!F16)/100,2))*100 -> 9618.5742 | D16: =(3/(1+('CurrentPor-N10Unchanged'!B16+'CurrentPor-N10Unchanged'!G16)/100)+103/POWER(1+('CurrentPor-N10Unchanged'!C16+'CurrentPor-N10Unchanged'!G16)/100,2))*100 -> 9595.4362 | E16: =(3/(1+('CurrentPor-N10Unchanged'!B16+'CurrentPor-N10Unchanged'!H16)/100)+103/POWER(1+('CurrentPor-N10Unchanged'!C16+'CurrentPor-N10Unchanged'!H16)/100,2))*100 -> 9682.0999 | F16: =Portfolio!B$5*'CurrentPor-N10Unchanged'!D16 -> 52143.896 | G16: =Portfolio!B$6*'CurrentPor-N10Unchanged'!E16 -> 3696.2945 | H16: =SUM(B16:G16) -> 94443.886 | I16: =H16-H6 -> -0.62993758
A17: 39281 | B17: =(3/(1+('CurrentPor-N10Unchanged'!B17)/100)+103/POWER(1+('CurrentPor-N10Unchanged'!C17)/100,2))*100 -> 9707.5858 | C17: =(3/(1+('CurrentPor-N10Unchanged'!B17+'CurrentPor-N10Unchanged'!F17)/100)+103/POWER(1+('CurrentPor-N10Unchanged'!C17+'CurrentPor-N10Unchanged'!F17)/100,2))*100 -> 9616.7705 | D17: =(3/(1+('CurrentPor-N10Unchanged'!B17+'CurrentPor-N10Unchanged'!G17)/100)+103/POWER(1+('CurrentPor-N10Unchanged'!C17+'CurrentPor-N10Unchanged'!G17)/100,2))*100 -> 9607.9241 | E17: =(3/(1+('CurrentPor-N10Unchanged'!B17+'CurrentPor-N10Unchanged'!H17)/100)+103/POWER(1+('CurrentPor-N10Unchanged'!C17+'CurrentPor-N10Unchanged'!H17)/100,2))*100 -> 9682.1363 | F17: =Portfolio!B$5*'CurrentPor-N10Unchanged'!D17 -> 52143.896 | G17: =Portfolio!B$6*'CurrentPor-N10Unchanged'!E17 -> 3696.2945 | H17: =SUM(B17:G17) -> 94454.607 | I17: =H17-H7 -> 32.954731
A18: 39282 | B18: =(3/(1+('CurrentPor-N10Unchanged'!B18)/100)+103/POWER(1+('CurrentPor-N10Unchanged'!C18)/100,2))*100 -> 9707.5858 | C18: =(3/(1+('CurrentPor-N10Unchanged'!B18+'CurrentPor-N10Unchanged'!F18)/100)+103/POWER(1+('CurrentPor-N10Unchanged'!C18+'CurrentPor-N10Unchanged'!F18)/100,2))*100 -> 9616.7705 | D18: =(3/(1+('CurrentPor-N10Unchanged'!B18+'CurrentPor-N10Unchanged'!G18)/100)+103/POWER(1+('CurrentPor-N10Unchanged'!C18+'CurrentPor-N10Unchanged'!G18)/100,2))*100 -> 9603.7417 | E18: =(3/(1+('CurrentPor-N10Unchanged'!B18+'CurrentPor-N10Unchanged'!H18)/100)+103/POWER(1+('CurrentPor-N10Unchanged'!C18+'CurrentPor-N10Unchanged'!H18)/100,2))*100 -> 9680.187 | F18: =Portfolio!B$5*'CurrentPor-N10Unchanged'!D18 -> 52143.896 | G18: =Portfolio!B$6*'CurrentPor-N10Unchanged'!E18 -> 3696.2945 | H18: =SUM(B18:G18) -> 94448.475 | I18: =H18-H8 -> 29.267115
A19: 39283 | B19: =(3/(1+('CurrentPor-N10Unchanged'!B19)/100)+103/POWER(1+('CurrentPor-N10Unchanged'!C19)/100,2))*100 -> 9707.5858 | C19: =(3/(1+('CurrentPor-N10Unchanged'!B19+'CurrentPor-N10Unchanged'!F19)/100)+103/POWER(1+('CurrentPor-N10Unchanged'!C19+'CurrentPor-N10Unchanged'!F19)/100,2))*100 -> 9616.7705 | D19: =(3/(1+('CurrentPor-N10Unchanged'!B19+'CurrentPor-N10Unchanged'!G19)/100)+103/POWER(1+('CurrentPor-N10Unchanged'!C19+'CurrentPor-N10Unchanged'!G19)/100,2))*100 -> 9590.1448 | E19: =(3/(1+('CurrentPor-N10Unchanged'!B19+'CurrentPor-N10Unchanged'!H19)/100)+103/POWER(1+('CurrentPor-N10Unchanged'!C19+'CurrentPor-N10Unchanged'!H19)/100,2))*100 -> 9680.9157 | F19: =Portfolio!B$5*'CurrentPor-N10Unchanged'!D19 -> 52143.896 | G19: =Portfolio!B$6*'CurrentPor-N10Unchanged'!E19 -> 3696.2945 | H19: =SUM(B19:G19) -> 94435.607 | I19: =H19-H9 -> 5.9176783
A20: 39286 | B20: =(3/(1+('CurrentPor-N10Unchanged'!B20)/100)+103/POWER(1+('CurrentPor-N10Unchanged'!C20)/100,2))*100 -> 9707.5858 | C20: =(3/(1+('CurrentPor-N10Unchanged'!B20+'CurrentPor-N10Unchanged'!F20)/100)+103/POWER(1+('CurrentPor-N10Unchanged'!C20+'CurrentPor-N10Unchanged'!F20)/100,2))*100 -> 9616.7705 | D20: =(3/(1+('CurrentPor-N10Unchanged'!B20+'CurrentPor-N10Unchanged'!G20)/100)+103/POWER(1+('CurrentPor-N10Unchanged'!C20+'CurrentPor-N10Unchanged'!G20)/100,2))*100 -> 9590.0804 | E20: =(3/(1+('CurrentPor-N10Unchanged'!B20+'CurrentPor-N10Unchanged'!H20)/100)+103/POWER(1+('CurrentPor-N10Unchanged'!C20+'CurrentPor-N10Unchanged'!H20)/100,2))*100 -> 9682.2456 | F20: =Portfolio!B$5*'CurrentPor-N10Unchanged'!D20 -> 52143.896 | G20: =Portfolio!B$6*'CurrentPor-N10Unchanged'!E20 -> 3696.2945 | H20: =SUM(B20:G20) -> 94436.872 | I20: =H20-H10 -> 9.7093652
A21: 39287 | B21: =(3/(1+('CurrentPor-N10Unchanged'!B21)/100)+103/POWER(1+('CurrentPor-N10Unchanged'!C21)/100,2))*100 -> 9707.5858 | C21: =(3/(1+('CurrentPor-N10Unchanged'!B21+'CurrentPor-N10Unchanged'!F21)/100)+103/POWER(1+('CurrentPor-N10Unchanged'!C21+'CurrentPor-N10Unchanged'!F21)/100,2))*100 -> 9614.9674 | D21: =(3/(1+('CurrentPor-N10Unchanged'!B21+'CurrentPor-N10Unchanged'!G21)/100)+103/POWER(1+('CurrentPor-N10Unchanged'!C21+'CurrentPor-N10Unchanged'!G21)/100,2))*100 -> 9601.3477 | E21: =(3/(1+('CurrentPor-N10Unchanged'!B21+'CurrentPor-N10Unchanged'!H21)/100)+103/POWER(1+('CurrentPor-N10Unchanged'!C21+'CurrentPor-N10Unchanged'!H21)/100,2))*100 -> 9681.116 | F21: =Portfolio!B$5*'CurrentPor-N10Unchanged'!D21 -> 52143.896 | G21: =Portfolio!B$6*'CurrentPor-N10Unchanged'!E21 -> 3696.2945 | H21: =SUM(B21:G21) -> 94445.207 | I21: =H21-H11 -> 12.92638
A22: 39288 | B22: =(3/(1+('CurrentPor-N10Unchanged'!B22)/100)+103/POWER(1+('CurrentPor-N10Unchanged'!C22)/100,2))*100 -> 9707.5858 | C22: =(3/(1+('CurrentPor-N10Unchanged'!B22+'CurrentPor-N10Unchanged'!F22)/100)+103/POWER(1+('CurrentPor-N10Unchanged'!C22+'CurrentPor-N10Unchanged'!F22)/100,2))*100 -> 9616.7705 | D22: =(3/(1+('CurrentPor-N10Unchanged'!B22+'CurrentPor-N10Unchanged'!G22)/100)+103/POWER(1+('CurrentPor-N10Unchanged'!C22+'CurrentPor-N10Unchanged'!G22)/100,2))*100 -> 9591.6422 | E22: =(3/(1+('CurrentPor-N10Unchanged'!B22+'CurrentPor-N10Unchanged'!H22)/100)+103/POWER(1+('CurrentPor-N10Unchanged'!C22+'CurrentPor-N10Unchanged'!H22)/100,2))*100 -> 9682.8651 | F22: =Portfolio!B$5*'CurrentPor-N10Unchanged'!D22 -> 52143.896 | G22: =Portfolio!B$6*'CurrentPor-N10Unchanged'!E22 -> 3696.2945 | H22: =SUM(B22:G22) -> 94439.054 | I22: =H22-H12 -> 7.7347786
A23: 39289 | B23: =(3/(1+('CurrentPor-N10Unchanged'!B23)/100)+103/POWER(1+('CurrentPor-N10Unchanged'!C23)/100,2))*100 -> 9707.5858 | C23: =(3/(1+('CurrentPor-N10Unchanged'!B23+'CurrentPor-N10Unchanged'!F23)/100)+103/POWER(1+('CurrentPor-N10Unchanged'!C23+'CurrentPor-N10Unchanged'!F23)/100,2))*100 -> 9622.1831 | D23: =(3/(1+('CurrentPor-N10Unchanged'!B23+'CurrentPor-N10Unchanged'!G23)/100)+103/POWER(1+('CurrentPor-N10Unchanged'!C23+'CurrentPor-N10Unchanged'!G23)/100,2))*100 -> 9612.9614 | E23: =(3/(1+('CurrentPor-N10Unchanged'!B23+'CurrentPor-N10Unchanged'!H23)/100)+103/POWER(1+('CurrentPor-N10Unchanged'!C23+'CurrentPor-N10Unchanged'!H23)/100,2))*100 -> 9684.0133 | F23: =Portfolio!B$5*'CurrentPor-N10Unchanged'!D23 -> 52143.896 | G23: =Portfolio!B$6*'CurrentPor-N10Unchanged'!E23 -> 3696.2945 | H23: =SUM(B23:G23) -> 94466.934 | I23: =H23-H13 -> 36.622631
A24: 39290 | B24: =(3/(1+('CurrentPor-N10Unchanged'!B24)/100)+103/POWER(1+('CurrentPor-N10Unchanged'!C24)/100,2))*100 -> 9707.5858 | C24: =(3/(1+('CurrentPor-N10Unchanged'!B24+'CurrentPor-N10Unchanged'!F24)/100)+103/POWER(1+('CurrentPor-N10Unchanged'!C24+'CurrentPor-N10Unchanged'!F24)/100,2))*100 -> 9622.1831 | D24: =(3/(1+('CurrentPor-N10Unchanged'!B24+'CurrentPor-N10Unchanged'!G24)/100)+103/POWER(1+('CurrentPor-N10Unchanged'!C24+'CurrentPor-N10Unchanged'!G24)/100,2))*100 -> 9604.3101 | E24: =(3/(1+('CurrentPor-N10Unchanged'!B24+'CurrentPor-N10Unchanged'!H24)/100)+103/POWER(1+('CurrentPor-N10Unchanged'!C24+'CurrentPor-N10Unchanged'!H24)/100,2))*100 -> 9683.0474 | F24: =Portfolio!B$5*'CurrentPor-N10Unchanged'!D24 -> 52143.896 | G24: =Portfolio!B$6*'CurrentPor-N10Unchanged'!E24 -> 3696.2945 | H24: =SUM(B24:G24) -> 94457.316 | I24: =H24-H14 -> 3.3748782
... A263: 39625 | B263: =(3/(1+('CurrentPor-N10Unchanged'!B263)/100)+103/POWER(1+('CurrentPor-N10Unchanged'!C263)/100,2))*100 -> 9707.5858 | C263: =(3/(1+('CurrentPor-N10Unchanged'!B263+'CurrentPor-N10Unchanged'!F263)/100)+103/POWER(1+('CurrentPor-N10Unchanged'!C263+'CurrentPor-N10Unchanged'!F263)/100,2))*100 -> 9599.9032 | D263: =(3/(1+('CurrentPor-N10Unchanged'!B263+'CurrentPor-N10Unchanged'!G263)/100)+103/POWER(1+('CurrentPor-N10Unchanged'!C263+'CurrentPor-N10Unchanged'!G263)/100,2))*100 -> 9591.1647 | E263: =(3/(1+('CurrentPor-N10Unchanged'!B263+'CurrentPor-N10Unchanged'!H263)/100)+103/POWER(1+('CurrentPor-N10Unchanged'!C263+'CurrentPor-N10Unchanged'!H263)/100,2))*100 -> 9593.7302 | F263: =Portfolio!B$5*'CurrentPor-N10Unchanged'!D263 -> 52143.896 | G263: =Portfolio!B$6*'CurrentPor-N10Unchanged'!E263 -> 3696.2945 | H263: =SUM(B263:G263) -> 94332.574 | I263: =H263-H253 -> -26.549613

Sheet ES,N10,20 unchanged
B1: n=10 | C1: n=10, 20 | D1: n=10, 40 | E1: n=10, 60 | F1: n=10 | G1: n=10
B2: Treasury Bonds IG valuation | C2: Credit spread: Sovereign Bonds IG valuation | D2: Credit spread: sovereign (high yield, or HY) | E2: Credit Spread:Corporate HY | F2: MSFT | G2: Intel | H2: Portfolio value | I2: 10 day PnL | J2: VaR | K2: ES, Q(pi,3)
A3: 39261 | B3: =(3/(1+('CurrentFact-N10,20Unchanged'!B3)/100)+103/POWER(1+('CurrentFact-N10,20Unchanged'!C3)/100,2))*100 -> 9707.5858 | C3: =(3/(1+('CurrentFact-N10,20Unchanged'!B3+'CurrentFact-N10,20Unchanged'!F3)/100)+103/POWER(1+('CurrentFact-N10,20Unchanged'!C3+'CurrentFact-N10,20Unchanged'!F3)/100,2))*100 -> 9614.9674 | D3: =(3/(1+('CurrentFact-N10,20Unchanged'!B3+'CurrentFact-N10,20Unchanged'!G3)/100)+103/POWER(1+('CurrentFact-N10,20Unchanged'!C3+'CurrentFact-N10,20Unchanged'!G3)/100,2))*100 -> 9601.2396 | E3: =(3/(1+('CurrentFact-N10,20Unchanged'!B3+'CurrentFact-N10,20Unchanged'!H3)/100)+103/POWER(1+('CurrentFact-N10,20Unchanged'!C3+'CurrentFact-N10,20Unchanged'!H3)/100,2))*100 -> 9676.6908 | F3: =Portfolio!B$5*'CurrentFact-N10,20Unchanged'!D3 -> 52143.896 | G3: =Portfolio!B$6*'CurrentFact-N10,20Unchanged'!E3 -> 3696.2945 | H3: =SUM(B3:G3) -> 94440.674 | J3: =_xlfn.PERCENTILE.INC(I13:I263, 0.025) -> -82.56413 | K3: =AVERAGEIF(I13:I263, "<="&J3,I13:I263) -> -102.83547
